Workbook

Sheet Data
A1: Country | B1: Code | C1: POP | D1: GDP_2017USD | E1: INC_2017USD_SSP | F1: INC_2017USD_calc | G1: diff | H1: Elec_Access | I1: Res_Elec_TJ | J1: Res_Elec_kWhCapita
A2: Albania | B2: alb | C2: =VLOOKUP(A2,POP_base!$C$2:$T$201,17,0)*10^6 -> 2883156 | D2: =VLOOKUP(A2,GDP_PPP_base!$C$2:$N$193,11,0)*10^9 -> 35068900000 | E2: =VLOOKUP(A2,INC_PPP_base!$C$2:$N$193,11,0) -> 12166.2 | F2: =D2/C2 -> 12163.372 | G2: =(F2-E2)/E2 -> -0.00023241768 | H2: =VLOOKUP(A2,Elec_Access_base!$A$5:$BH$270,60,0)/100 -> 1 | I2: =11487 -> 11487 | J2: =I2*10^9/3600/C2 -> 1106.7155
A3: Algeria | B3: dza | C3: =VLOOKUP(A3,POP_base!$C$2:$T$201,17,0)*10^6 -> 39146480 | D3: =VLOOKUP(A3,GDP_PPP_base!$C$2:$N$193,11,0)*10^9 -> 456849000000 | E3: =VLOOKUP(A3,INC_PPP_base!$C$2:$N$193,11,0) -> 11553.2 | F3: =D3/C3 -> 11670.245 | G3: =(F3-E3)/E3 -> 0.010130932 | H3: =VLOOKUP(A3,Elec_Access_base!$A$5:$BH$270,60,0)/100 -> 0.994 | I3: =70819 -> 70819 | J3: =I3*10^9/3600/C3 -> 502.52141
A4: Angola | B4: ago | C4: =VLOOKUP(A4,POP_base!$C$2:$T$201,17,0)*10^6 -> 27624320 | D4: =VLOOKUP(A4,GDP_PPP_base!$C$2:$N$193,11,0)*10^9 -> 223908000000 | E4: =VLOOKUP(A4,INC_PPP_base!$C$2:$N$193,11,0) -> 7960.42 | F4: =D4/C4 -> 8105.4665 | G4: =(F4-E4)/E4 -> 0.018220959 | H4: =VLOOKUP(A4,Elec_Access_base!$A$5:$BH$270,60,0)/100 -> 0.42 | I4: =19987 -> 19987 | J4: =I4*10^9/3600/C4 -> 200.98031
A5: Argentina | B5: arg | C5: =VLOOKUP(A5,POP_base!$C$2:$T$201,17,0)*10^6 -> 43042287 | D5: =VLOOKUP(A5,GDP_PPP_base!$C$2:$N$193,11,0)*10^9 -> 867021000000 | E5: =VLOOKUP(A5,INC_PPP_base!$C$2:$N$193,11,0) -> 20043.5 | F5: =D5/C5 -> 20143.47 | G5: =(F5-E5)/E5 -> 0.0049876322 | H5: =VLOOKUP(A5,Elec_Access_base!$A$5:$BH$270,60,0)/100 -> 0.997 | I5: =156099 -> 156099 | J5: =I5*10^9/3600/C5 -> 1007.4008
A6: Armenia | B6: arm | C6: =VLOOKUP(A6,POP_base!$C$2:$T$201,17,0)*10^6 -> 2884958 | D6: =VLOOKUP(A6,GDP_PPP_base!$C$2:$N$193,11,0)*10^9 -> 3.31178e+10 | E6: =VLOOKUP(A6,INC_PPP_base!$C$2:$N$193,11,0) -> 11504.8 | F6: =D6/C6 -> 11479.474 | G6: =(F6-E6)/E6 -> -0.0022013527 | H6: =VLOOKUP(A6,Elec_Access_base!$A$5:$BH$270,60,0)/100 -> 1 | I6: =6757 -> 6757 | J6: =I6*10^9/3600/C6 -> 650.5968
A7: Australia | B7: aus | C7: =VLOOKUP(A7,POP_base!$C$2:$T$201,17,0)*10^6 -> 23641438 | D7: =VLOOKUP(A7,GDP_PPP_base!$C$2:$N$193,11,0)*10^9 -> 1111680000000 | E7: =VLOOKUP(A7,INC_PPP_base!$C$2:$N$193,11,0) -> 46669.7 | F7: =D7/C7 -> 47022.52 | G7: =(F7-E7)/E7 -> 0.0075599452 | H7: =VLOOKUP(A7,Elec_Access_base!$A$5:$BH$270,60,0)/100 -> 1 | I7: =202797 -> 202797 | J7: =I7*10^9/3600/C7 -> 2382.7865
A8: Austria | B8: aut | C8: =VLOOKUP(A8,POP_base!$C$2:$T$201,17,0)*10^6 -> 8584609 | D8: =VLOOKUP(A8,GDP_PPP_base!$C$2:$N$193,11,0)*10^9 -> 431002000000 | E8: =VLOOKUP(A8,INC_PPP_base!$C$2:$N$193,11,0) -> 49870.5 | F8: =D8/C8 -> 50206.364 | G8: =(F8-E8)/E8 -> 0.006734713 | H8: =VLOOKUP(A8,Elec_Access_base!$A$5:$BH$270,60,0)/100 -> 1 | I8: =61975 -> 61975 | J8: =I8*10^9/3600/C8 -> 2005.3654
A9: Bahrain | B9: bhr | C9: =VLOOKUP(A9,POP_base!$C$2:$T$201,17,0)*10^6 -> 1338295 | D9: =VLOOKUP(A9,GDP_PPP_base!$C$2:$N$193,11,0)*10^9 -> 65998700000 | E9: =VLOOKUP(A9,INC_PPP_base!$C$2:$N$193,11,0) -> 48452.1 | F9: =D9/C9 -> 49315.51 | G9: =(F9-E9)/E9 -> 0.01781986 | H9: =VLOOKUP(A9,Elec_Access_base!$A$5:$BH$270,60,0)/100 -> 1 | I9: =27453 -> 27453 | J9: =I9*10^9/3600/C9 -> 5698.1707
A10: Bangladesh | B10: bgd | C10: =VLOOKUP(A10,POP_base!$C$2:$T$201,17,0)*10^6 -> 156916324 | D10: =VLOOKUP(A10,GDP_PPP_base!$C$2:$N$193,11,0)*10^9 -> 730948000000 | E10: =VLOOKUP(A10,INC_PPP_base!$C$2:$N$193,11,0) -> 4631.24 | F10: =D10/C10 -> 4658.2024 | G10: =(F10-E10)/E10 -> 0.0058218574 | H10: =VLOOKUP(A10,Elec_Access_base!$A$5:$BH$270,60,0)/100 -> 0.74 | I10: =60505 -> 60505 | J10: =I10*10^9/3600/C10 -> 107.10769
A11: Belarus | B11: blr | C11: =VLOOKUP(A11,POP_base!$C$2:$T$201,17,0)*10^6 -> 9696501 | D11: =VLOOKUP(A11,GDP_PPP_base!$C$2:$N$193,11,0)*10^9 -> 173734000000 | E11: =VLOOKUP(A11,INC_PPP_base!$C$2:$N$193,11,0) -> 17909.6 | F11: =D11/C11 -> 17917.185 | G11: =(F11-E11)/E11 -> 0.00042350281 | H11: =VLOOKUP(A11,Elec_Access_base!$A$5:$BH$270,60,0)/100 -> 0.974 | I11: =23763 -> 23763 | J11: =I11*10^9/3600/C11 -> 680.74384
A12: Belgium | B12: bel | C12: =VLOOKUP(A12,POP_base!$C$2:$T$201,17,0)*10^6 -> 11214586 | D12: =VLOOKUP(A12,GDP_PPP_base!$C$2:$N$193,11,0)*10^9 -> 520866000000 | E12: =VLOOKUP(A12,INC_PPP_base!$C$2:$N$193,11,0) -> 46306.2 | F12: =D12/C12 -> 46445.406 | G12: =(F12-E12)/E12 -> 0.0030062067 | H12: =VLOOKUP(A12,Elec_Access_base!$A$5:$BH$270,60,0)/100 -> 1 | I12: =65367 -> 65367 | J12: =I12*10^9/3600/C12 -> 1619.0968
A13: Benin | B13: ben | C13: =VLOOKUP(A13,POP_base!$C$2:$T$201,17,0)*10^6 -> 10771657 | D13: =VLOOKUP(A13,GDP_PPP_base!$C$2:$N$193,11,0)*10^9 -> 31156400000 | E13: =VLOOKUP(A13,INC_PPP_base!$C$2:$N$193,11,0) -> 2849.81 | F13: =D13/C13 -> 2892.4426 | G13: =(F13-E13)/E13 -> 0.014959818 | H13: =VLOOKUP(A13,Elec_Access_base!$A$5:$BH$270,60,0)/100 -> 0.296 | I13: =1407 -> 1407 | J13: =I13*10^9/3600/C13 -> 36.283492
A14: Bolivia | B14: bol | C14: =VLOOKUP(A14,POP_base!$C$2:$T$201,17,0)*10^6 -> 11003680 | D14: =VLOOKUP(A14,GDP_PPP_base!$C$2:$N$193,11,0)*10^9 -> 86788900000 | E14: =VLOOKUP(A14,INC_PPP_base!$C$2:$N$193,11,0) -> 7825.8 | F14: =D14/C14 -> 7887.2614 | G14: =(F14-E14)/E14 -> 0.007853683 | H14: =VLOOKUP(A14,Elec_Access_base!$A$5:$BH$270,60,0)/100 -> 0.915 | I14: =10771 -> 10771 | J14: =I14*10^9/3600/C14 -> 271.90399
A15: Bosnia and Herzegovina | B15: bih | C15: =VLOOKUP(A15,POP_base!$C$2:$T$201,17,0)*10^6 -> 3546921 | D15: =VLOOKUP(A15,GDP_PPP_base!$C$2:$N$193,11,0)*10^9 -> 44116800000 | E15: =VLOOKUP(A15,INC_PPP_base!$C$2:$N$193,11,0) -> 12517.8 | F15: =D15/C15 -> 12438.055 | G15: =(F15-E15)/E15 -> -0.0063704941 | H15: =VLOOKUP(A15,Elec_Access_base!$A$5:$BH$270,60,0)/100 -> 0.997 | I15: =17013 -> 17013 | J15: =I15*10^9/3600/C15 -> 1332.3763
A16: Botswana | B16: bwa | C16: =VLOOKUP(A16,POP_base!$C$2:$T$201,17,0)*10^6 -> 2282237 | D16: =VLOOKUP(A16,GDP_PPP_base!$C$2:$N$193,11,0)*10^9 -> 31540800000 | E16: =VLOOKUP(A16,INC_PPP_base!$C$2:$N$193,11,0) -> 13682.6 | F16: =D16/C16 -> 13820.125 | G16: =(F16-E16)/E16 -> 0.010051067 | H16: =VLOOKUP(A16,Elec_Access_base!$A$5:$BH$270,60,0)/100 -> 0.621 | I16: =3387 -> 3387 | J16: =I16*10^9/3600/C16 -> 412.24173
A17: Brazil | B17: bra | C17: =VLOOKUP(A17,POP_base!$C$2:$T$201,17,0)*10^6 -> 204334810 | D17: =VLOOKUP(A17,GDP_PPP_base!$C$2:$N$193,11,0)*10^9 -> 3016140000000 | E17: =VLOOKUP(A17,INC_PPP_base!$C$2:$N$193,11,0) -> 14699.4 | F17: =D17/C17 -> 14760.774 | G17: =(F17-E17)/E17 -> 0.0041752889 | H17: =VLOOKUP(A17,Elec_Access_base!$A$5:$BH$270,60,0)/100 -> 0.997 | I17: =472312 -> 472312 | J17: =I17*10^9/3600/C17 -> 642.07258
A18: Brunei Darussalam | B18: brn | C18: =VLOOKUP(A18,POP_base!$C$2:$T$201,17,0)*10^6 -> 419093 | D18: =VLOOKUP(A18,GDP_PPP_base!$C$2:$N$193,11,0)*10^9 -> 26196700000 | E18: =VLOOKUP(A18,INC_PPP_base!$C$2:$N$193,11,0) -> 62160.1 | F18: =D18/C18 -> 62508.083 | G18: =(F18-E18)/E18 -> 0.005598172 | H18: =VLOOKUP(A18,Elec_Access_base!$A$5:$BH$270,60,0)/100 -> 1 | I18: =4820 -> 4820 | J18: =I18*10^9/3600/C18 -> 3194.7298
A19: Bulgaria | B19: bgr | C19: =VLOOKUP(A19,POP_base!$C$2:$T$201,17,0)*10^6 -> 7341383 | D19: =VLOOKUP(A19,GDP_PPP_base!$C$2:$N$193,11,0)*10^9 -> 143928000000 | E19: =VLOOKUP(A19,INC_PPP_base!$C$2:$N$193,11,0) -> 19691.2 | F19: =D19/C19 -> 19605.025 | G19: =(F19-E19)/E19 -> -0.0043763014 | H19: =VLOOKUP(A19,Elec_Access_base!$A$5:$BH$270,60,0)/100 -> 0.966 | I19: =38318 -> 38318 | J19: =I19*10^9/3600/C19 -> 1449.8479
A20: Cambodia | B20: khm | C20: =VLOOKUP(A20,POP_base!$C$2:$T$201,17,0)*10^6 -> 15315991 | D20: =VLOOKUP(A20,GDP_PPP_base!$C$2:$N$193,11,0)*10^9 -> 55003400000 | E20: =VLOOKUP(A20,INC_PPP_base!$C$2:$N$193,11,0) -> 3567.59 | F20: =D20/C20 -> 3591.24 | G20: =(F20-E20)/E20 -> 0.0066291338 | H20: =VLOOKUP(A20,Elec_Access_base!$A$5:$BH$270,60,0)/100 -> 0.627 | I20: =5486 -> 5486 | J20: =I20*10^9/3600/C20 -> 99.496591
A21: Cameroon | B21: cmr | C21: =VLOOKUP(A21,POP_base!$C$2:$T$201,17,0)*10^6 -> 22662456 | D21: =VLOOKUP(A21,GDP_PPP_base!$C$2:$N$193,11,0)*10^9 -> 83230700000 | E21: =VLOOKUP(A21,INC_PPP_base!$C$2:$N$193,11,0) -> 3616.74 | F21: =D21/C21 -> 3672.6249 | G21: =(F21-E21)/E21 -> 0.01545173 | H21: =VLOOKUP(A21,Elec_Access_base!$A$5:$BH$270,60,0)/100 -> 0.586 | I21: =4690 -> 4690 | J21: =I21*10^9/3600/C21 -> 57.486169
A22: Canada | B22: can | C22: =VLOOKUP(A22,POP_base!$C$2:$T$201,17,0)*10^6 -> 35562312 | D22: =VLOOKUP(A22,GDP_PPP_base!$C$2:$N$193,11,0)*10^9 -> 1594850000000 | E22: =VLOOKUP(A22,INC_PPP_base!$C$2:$N$193,11,0) -> 44633.5 | F22: =D22/C22 -> 44846.634 | G22: =(F22-E22)/E22 -> 0.0047752085 | H22: =VLOOKUP(A22,Elec_Access_base!$A$5:$BH$270,60,0)/100 -> 1 | I22: =613400 -> 613400 | J22: =I22*10^9/3600/C22 -> 4791.277
A23: Chile | B23: chl | C23: =VLOOKUP(A23,POP_base!$C$2:$T$201,17,0)*10^6 -> 17779025 | D23: =VLOOKUP(A23,GDP_PPP_base!$C$2:$N$193,11,0)*10^9 -> 405421000000 | E23: =VLOOKUP(A23,INC_PPP_base!$C$2:$N$193,11,0) -> 22687.1 | F23: =D23/C23 -> 22803.331 | G23: =(F23-E23)/E23 -> 0.0051232398 | H23: =VLOOKUP(A23,Elec_Access_base!$A$5:$BH$270,60,0)/100 -> 0.997 | I23: =42318 -> 42318 | J23: =I23*10^9/3600/C23 -> 661.17236
A24: Colombia | B24: col | C24: =VLOOKUP(A24,POP_base!$C$2:$T$201,17,0)*10^6 -> 46894748 | D24: =VLOOKUP(A24,GDP_PPP_base!$C$2:$N$193,11,0)*10^9 -> 624056000000 | E24: =VLOOKUP(A24,INC_PPP_base!$C$2:$N$193,11,0) -> 13244 | F24: =D24/C24 -> 13307.588 | G24: =(F24-E24)/E24 -> 0.0048012914 | H24: =VLOOKUP(A24,Elec_Access_base!$A$5:$BH$270,60,0)/100 -> 0.982 | I24: =80557 -> 80557 | J24: =I24*10^9/3600/C24 -> 477.17379
A25: Democratic Republic of the Congo | B25: cod | C25: =VLOOKUP(A25,POP_base!$C$2:$T$201,17,0)*10^6 -> 77325521 | D25: =VLOOKUP(A25,GDP_PPP_base!$C$2:$N$193,11,0)*10^9 -> 86126600000 | E25: =VLOOKUP(A25,INC_PPP_base!$C$2:$N$193,11,0) -> 1094.97 | F25: =D25/C25 -> 1113.8186 | G25: =(F25-E25)/E25 -> 0.017213763 | H25: =VLOOKUP(A25,Elec_Access_base!$A$5:$BH$270,60,0)/100 -> 0.166 | I25: =9115 -> 9115 | J25: =I25*10^9/3600/C25 -> 32.743969
A26: Congo | B26: cog | C26: =VLOOKUP(A26,POP_base!$C$2:$T$201,17,0)*10^6 -> 5003857 | D26: =VLOOKUP(A26,GDP_PPP_base!$C$2:$N$193,11,0)*10^9 -> 25738300000 | E26: =VLOOKUP(A26,INC_PPP_base!$C$2:$N$193,11,0) -> 5082.22 | F26: =D26/C26 -> 5143.6922 | G26: =(F26-E26)/E26 -> 0.012095532 | H26: =VLOOKUP(A26,Elec_Access_base!$A$5:$BH$270,60,0)/100 -> 0.443 | I26: =2318 -> 2318 | J26: =I26*10^9/3600/C26 -> 128.67852
A27: Costa Rica | B27: cri | C27: =VLOOKUP(A27,POP_base!$C$2:$T$201,17,0)*10^6 -> 4869993 | D27: =VLOOKUP(A27,GDP_PPP_base!$C$2:$N$193,11,0)*10^9 -> 85241800000 | E27: =VLOOKUP(A27,INC_PPP_base!$C$2:$N$193,11,0) -> 17413.2 | F27: =D27/C27 -> 17503.475 | G27: =(F27-E27)/E27 -> 0.0051842769 | H27: =VLOOKUP(A27,Elec_Access_base!$A$5:$BH$270,60,0)/100 -> 0.994 | I27: =12992 -> 12992 | J27: =I27*10^9/3600/C27 -> 741.04601
A28: Cote d'Ivoire | B28: civ | C28: =VLOOKUP(A28,POP_base!$C$2:$T$201,17,0)*10^6 -> 23291821 | D28: =VLOOKUP(A28,GDP_PPP_base!$C$2:$N$193,11,0)*10^9 -> 104388000000 | E28: =VLOOKUP(A28,INC_PPP_base!$C$2:$N$193,11,0) -> 4423.82 | F28: =D28/C28 -> 4481.7449 | G28: =(F28-E28)/E28 -> 0.013093865 | H28: =VLOOKUP(A28,Elec_Access_base!$A$5:$BH$270,60,0)/100 -> 0.626 | I28: =6854 -> 6854 | J28: =I28*10^9/3600/C28 -> 81.740663
A29: Croatia | B29: hrv | C29: =VLOOKUP(A29,POP_base!$C$2:$T$201,17,0)*10^6 -> 4270955 | D29: =VLOOKUP(A29,GDP_PPP_base!$C$2:$N$193,11,0)*10^9 -> 104702000000 | E29: =VLOOKUP(A29,INC_PPP_base!$C$2:$N$193,11,0) -> 24607.9 | F29: =D29/C29 -> 24514.892 | G29: =(F29-E29)/E29 -> -0.0037796046 | H29: =VLOOKUP(A29,Elec_Access_base!$A$5:$BH$270,60,0)/100 -> 1 | I29: =22327 -> 22327 | J29: =I29*10^9/3600/C29 -> 1452.1212
A30: Cyprus | B30: cyp | C30: =VLOOKUP(A30,POP_base!$C$2:$T$201,17,0)*10^6 -> 1182076 | D30: =VLOOKUP(A30,GDP_PPP_base!$C$2:$N$193,11,0)*10^9 -> 29313800000 | E30: =VLOOKUP(A30,INC_PPP_base!$C$2:$N$193,11,0) -> 24689.8 | F30: =D30/C30 -> 24798.575 | G30: =(F30-E30)/E30 -> 0.0044056538 | H30: =VLOOKUP(A30,Elec_Access_base!$A$5:$BH$270,60,0)/100 -> 1 | I30: =5454 -> 5454 | J30: =I30*10^9/3600/C30 -> 1281.6435
A31: Czechia | B31: cze | C31: =VLOOKUP(A31,POP_base!$C$2:$T$201,17,0)*10^6 -> 10521669 | D31: =VLOOKUP(A31,GDP_PPP_base!$C$2:$N$193,11,0)*10^9 -> 357651000000 | E31: =VLOOKUP(A31,INC_PPP_base!$C$2:$N$193,11,0) -> 33985 | F31: =D31/C31 -> 33991.851 | G31: =(F31-E31)/E31 -> 0.00020157518 | H31: =VLOOKUP(A31,Elec_Access_base!$A$5:$BH$270,60,0)/100 -> 1 | I31: =51775 -> 51775 | J31: =I31*10^9/3600/C31 -> 1366.8881
A32: Denmark | B32: dnk | C32: =VLOOKUP(A32,POP_base!$C$2:$T$201,17,0)*10^6 -> 5664053 | D32: =VLOOKUP(A32,GDP_PPP_base!$C$2:$N$193,11,0)*10^9 -> 278749000000 | E32: =VLOOKUP(A32,INC_PPP_base!$C$2:$N$193,11,0) -> 49094.5 | F32: =D32/C32 -> 49213.699 | G32: =(F32-E32)/E32 -> 0.0024279521 | H32: =VLOOKUP(A32,Elec_Access_base!$A$5:$BH$270,60,0)/100 -> 1 | I32: =36635 -> 36635 | J32: =I32*10^9/3600/C32 -> 1796.662
A33: Dominican Republic | B33: dom | C33: =VLOOKUP(A33,POP_base!$C$2:$T$201,17,0)*10^6 -> 10344326 | D33: =VLOOKUP(A33,GDP_PPP_base!$C$2:$N$193,11,0)*10^9 -> 157602000000 | E33: =VLOOKUP(A33,INC_PPP_base!$C$2:$N$193,11,0) -> 15145.5 | F33: =D33/C33 -> 15235.599 | G33: =(F33-E33)/E33 -> 0.0059488774 | H33: =VLOOKUP(A33,Elec_Access_base!$A$5:$BH$270,60,0)/100 -> 0.986 | I33: =19378 -> 19378 | J33: =I33*10^9/3600/C33 -> 520.36042
A34: Ecuador | B34: ecu | C34: =VLOOKUP(A34,POP_base!$C$2:$T$201,17,0)*10^6 -> 16075497 | D34: =VLOOKUP(A34,GDP_PPP_base!$C$2:$N$193,11,0)*10^9 -> 192865000000 | E34: =VLOOKUP(A34,INC_PPP_base!$C$2:$N$193,11,0) -> 11908.2 | F34: =D34/C34 -> 11997.452 | G34: =(F34-E34)/E34 -> 0.0074949845 | H34: =VLOOKUP(A34,Elec_Access_base!$A$5:$BH$270,60,0)/100 -> 0.988 | I34: =24940 -> 24940 | J34: =I34*10^9/3600/C34 -> 430.95263
A35: Egypt | B35: egy | C35: =VLOOKUP(A35,POP_base!$C$2:$T$201,17,0)*10^6 -> 96675401 | D35: =VLOOKUP(A35,GDP_PPP_base!$C$2:$N$193,11,0)*10^9 -> 1029480000000 | E35: =VLOOKUP(A35,INC_PPP_base!$C$2:$N$193,11,0) -> 10534.6 | F35: =D35/C35 -> 10648.831 | G35: =(F35-E35)/E35 -> 0.010843404 | H35: =VLOOKUP(A35,Elec_Access_base!$A$5:$BH$270,60,0)/100 -> 0.993 | I35: =264099 -> 264099 | J35: =I35*10^9/3600/C35 -> 758.83661
A36: El Salvador | B36: slv | C36: =VLOOKUP(A36,POP_base!$C$2:$T$201,17,0)*10^6 -> 6221248 | D36: =VLOOKUP(A36,GDP_PPP_base!$C$2:$N$193,11,0)*10^9 -> 51516600000 | E36: =VLOOKUP(A36,INC_PPP_base!$C$2:$N$193,11,0) -> 8267.69 | F36: =D36/C36 -> 8280.7501 | G36: =(F36-E36)/E36 -> 0.0015796553 | H36: =VLOOKUP(A36,Elec_Access_base!$A$5:$BH$270,60,0)/100 -> 0.954 | I36: =6573 -> 6573 | J36: =I36*10^9/3600/C36 -> 293.48345
A37: Estonia | B37: est | C37: =VLOOKUP(A37,POP_base!$C$2:$T$201,17,0)*10^6 -> 1313255 | D37: =VLOOKUP(A37,GDP_PPP_base!$C$2:$N$193,11,0)*10^9 -> 38356000000 | E37: =VLOOKUP(A37,INC_PPP_base!$C$2:$N$193,11,0) -> 29175.7 | F37: =D37/C37 -> 29206.818 | G37: =(F37-E37)/E37 -> 0.0010665785 | H37: =VLOOKUP(A37,Elec_Access_base!$A$5:$BH$270,60,0)/100 -> 1 | I37: =6220 -> 6220 | J37: =I37*10^9/3600/C37 -> 1315.6453
A38: Ethiopia | B38: eth | C38: =VLOOKUP(A38,POP_base!$C$2:$T$201,17,0)*10^6 -> 101097184 | D38: =VLOOKUP(A38,GDP_PPP_base!$C$2:$N$193,11,0)*10^9 -> 180711000000 | E38: =VLOOKUP(A38,INC_PPP_base!$C$2:$N$193,11,0) -> 1763.52 | F38: =D38/C38 -> 1787.4979 | G38: =(F38-E38)/E38 -> 0.013596591 | H38: =VLOOKUP(A38,Elec_Access_base!$A$5:$BH$270,60,0)/100 -> 0.29 | I38: =12240 -> 12240 | J38: =I38*10^9/3600/C38 -> 33.631006
A39: Finland | B39: fin | C39: =VLOOKUP(A39,POP_base!$C$2:$T$201,17,0)*10^6 -> 5471699 | D39: =VLOOKUP(A39,GDP_PPP_base!$C$2:$N$193,11,0)*10^9 -> 232865000000 | E39: =VLOOKUP(A39,INC_PPP_base!$C$2:$N$193,11,0) -> 42497.7 | F39: =D39/C39 -> 42558.079 | G39: =(F39-E39)/E39 -> 0.0014207665 | H39: =VLOOKUP(A39,Elec_Access_base!$A$5:$BH$270,60,0)/100 -> 1 | I39: =75304 -> 75304 | J39: =I39*10^9/3600/C39 -> 3822.9036
A40: France | B40: fra | C40: =VLOOKUP(A40,POP_base!$C$2:$T$201,17,0)*10^6 -> 63715216 | D40: =VLOOKUP(A40,GDP_PPP_base!$C$2:$N$193,11,0)*10^9 -> 2719940000000 | E40: =VLOOKUP(A40,INC_PPP_base!$C$2:$N$193,11,0) -> 42625.7 | F40: =D40/C40 -> 42689.018 | G40: =(F40-E40)/E40 -> 0.0014854409 | H40: =VLOOKUP(A40,Elec_Access_base!$A$5:$BH$270,60,0)/100 -> 1 | I40: =566286 -> 566286 | J40: =I40*10^9/3600/C40 -> 2468.8242
...

Sheet Data_Africa
A1: Country | B1: Code | C1: POP | D1: GDP_2017USD | E1: INC_2017USD_SSP | F1: INC_2017USD_calc | G1: diff | H1: Elec_Access | I1: Res_Elec_TJ | J1: Res_Elec_kWhCapita
A2: Nigeria | B2: =VLOOKUP(A2,Data!$A$1:$B$126,2,0) -> nga | C2: =VLOOKUP(A2,POP_base!$C$2:$T$201,17,0)*10^6 -> 181702661 | D2: =VLOOKUP(A2,GDP_PPP_base!$C$2:$N$193,11,0)*10^9 -> 998931000000 | E2: =VLOOKUP(A2,INC_PPP_base!$C$2:$N$193,11,0) -> 5429.1 | F2: =D2/C2 -> 5497.6135 | G2: =(F2-E2)/E2 -> 0.012619677 | H2: =VLOOKUP(A2,Elec_Access_base!$A$5:$BH$270,60,0)/100 -> 0.525 | I2: =VLOOKUP(A2,Data!$A$2:$I$126,9,0) -> 51706 | J2: =I2*10^9/3600/C2 -> 79.0455
A3: Ethiopia | B3: =VLOOKUP(A3,Data!$A$1:$B$126,2,0) -> eth | C3: =VLOOKUP(A3,POP_base!$C$2:$T$201,17,0)*10^6 -> 101097184 | D3: =VLOOKUP(A3,GDP_PPP_base!$C$2:$N$193,11,0)*10^9 -> 180711000000 | E3: =VLOOKUP(A3,INC_PPP_base!$C$2:$N$193,11,0) -> 1763.52 | F3: =D3/C3 -> 1787.4979 | G3: =(F3-E3)/E3 -> 0.013596591 | H3: =VLOOKUP(A3,Elec_Access_base!$A$5:$BH$270,60,0)/100 -> 0.29 | I3: =VLOOKUP(A3,Data!$A$2:$I$126,9,0) -> 12240 | J3: =I3*10^9/3600/C3 -> 33.631006
A4: Egypt | B4: =VLOOKUP(A4,Data!$A$1:$B$126,2,0) -> egy | C4: =VLOOKUP(A4,POP_base!$C$2:$T$201,17,0)*10^6 -> 96675401 | D4: =VLOOKUP(A4,GDP_PPP_base!$C$2:$N$193,11,0)*10^9 -> 1029480000000 | E4: =VLOOKUP(A4,INC_PPP_base!$C$2:$N$193,11,0) -> 10534.6 | F4: =D4/C4 -> 10648.831 | G4: =(F4-E4)/E4 -> 0.010843404 | H4: =VLOOKUP(A4,Elec_Access_base!$A$5:$BH$270,60,0)/100 -> 0.993 | I4: =VLOOKUP(A4,Data!$A$2:$I$126,9,0) -> 264099 | J4: =I4*10^9/3600/C4 -> 758.83661
A5: Democratic Republic of the Congo | B5: =VLOOKUP(A5,Data!$A$1:$B$126,2,0) -> cod | C5: =VLOOKUP(A5,POP_base!$C$2:$T$201,17,0)*10^6 -> 77325521 | D5: =VLOOKUP(A5,GDP_PPP_base!$C$2:$N$193,11,0)*10^9 -> 86126600000 | E5: =VLOOKUP(A5,INC_PPP_base!$C$2:$N$193,11,0) -> 1094.97 | F5: =D5/C5 -> 1113.8186 | G5: =(F5-E5)/E5 -> 0.017213763 | H5: =VLOOKUP(A5,Elec_Access_base!$A$5:$BH$270,60,0)/100 -> 0.166 | I5: =VLOOKUP(A5,Data!$A$2:$I$126,9,0) -> 9115 | J5: =I5*10^9/3600/C5 -> 32.743969
A6: Tanzania | B6: =VLOOKUP(A6,Data!$A$1:$B$126,2,0) -> tza | C6: =VLOOKUP(A6,POP_base!$C$2:$T$201,17,0)*10^6 -> 51608414 | D6: =VLOOKUP(A6,GDP_PPP_base!$C$2:$N$193,11,0)*10^9 -> 117578000000 | E6: =VLOOKUP(A6,INC_PPP_base!$C$2:$N$193,11,0) -> 2237.75 | F6: =D6/C6 -> 2278.2719 | G6: =(F6-E6)/E6 -> 0.018108328 | H6: =VLOOKUP(A6,Elec_Access_base!$A$5:$BH$270,60,0)/100 -> 0.262 | I6: =VLOOKUP(A6,Data!$A$2:$I$126,9,0) -> 8542 | J6: =I6*10^9/3600/C6 -> 45.976568
A7: South Africa | B7: =VLOOKUP(A7,Data!$A$1:$B$126,2,0) -> zaf | C7: =VLOOKUP(A7,POP_base!$C$2:$T$201,17,0)*10^6 -> 55219577 | D7: =VLOOKUP(A7,GDP_PPP_base!$C$2:$N$193,11,0)*10^9 -> 758900000000 | E7: =VLOOKUP(A7,INC_PPP_base!$C$2:$N$193,11,0) -> 13581.7 | F7: =D7/C7 -> 13743.314 | G7: =(F7-E7)/E7 -> 0.011899413 | H7: =VLOOKUP(A7,Elec_Access_base!$A$5:$BH$270,60,0)/100 -> 0.853 | I7: =VLOOKUP(A7,Data!$A$2:$I$126,9,0) -> 145594 | J7: =I7*10^9/3600/C7 -> 732.39927
A8: Kenya | B8: =VLOOKUP(A8,Data!$A$1:$B$126,2,0) -> ken | C8: =VLOOKUP(A8,POP_base!$C$2:$T$201,17,0)*10^6 -> 46345992 | D8: =VLOOKUP(A8,GDP_PPP_base!$C$2:$N$193,11,0)*10^9 -> 195128000000 | E8: =VLOOKUP(A8,INC_PPP_base!$C$2:$N$193,11,0) -> 4164.82 | F8: =D8/C8 -> 4210.2454 | G8: =(F8-E8)/E8 -> 0.010906932 | H8: =VLOOKUP(A8,Elec_Access_base!$A$5:$BH$270,60,0)/100 -> 0.416 | I8: =VLOOKUP(A8,Data!$A$2:$I$126,9,0) -> 9601 | J8: =I8*10^9/3600/C8 -> 57.54423
A9: Sudan | B9: =VLOOKUP(A9,Data!$A$1:$B$126,2,0) -> sdn | C9: =VLOOKUP(A9,POP_base!$C$2:$T$201,17,0)*10^6 -> 37585674 | D9: =VLOOKUP(A9,GDP_PPP_base!$C$2:$N$193,11,0)*10^9 -> 181882000000 | E9: =VLOOKUP(A9,INC_PPP_base!$C$2:$N$193,11,0) -> 4764.9 | F9: =D9/C9 -> 4839.131 | G9: =(F9-E9)/E9 -> 0.01557871 | H9: =VLOOKUP(A9,Elec_Access_base!$A$5:$BH$270,60,0)/100 -> 0.48 | I9: =VLOOKUP(A9,Data!$A$2:$I$126,9,0) -> 21437 | J9: =I9*10^9/3600/C9 -> 158.43064
A10: Uganda | B10: =VLOOKUP(A10,Data!$A$1:$B$126,2,0) -> uga | C10: =VLOOKUP(A10,POP_base!$C$2:$T$201,17,0)*10^6 -> 36893791 | D10: =VLOOKUP(A10,GDP_PPP_base!$C$2:$N$193,11,0)*10^9 -> 83910600000 | E10: =VLOOKUP(A10,INC_PPP_base!$C$2:$N$193,11,0) -> 2238.97 | F10: =D10/C10 -> 2274.3827 | G10: =(F10-E10)/E10 -> 0.015816514 | H10: =VLOOKUP(A10,Elec_Access_base!$A$5:$BH$270,60,0)/100 -> 0.185 | I10: =VLOOKUP(A10,Data!$A$2:$I$126,9,0) -> 2192 | J10: =I10*10^9/3600/C10 -> 16.503831
A11: Algeria | B11: =VLOOKUP(A11,Data!$A$1:$B$126,2,0) -> dza | C11: =VLOOKUP(A11,POP_base!$C$2:$T$201,17,0)*10^6 -> 39146480 | D11: =VLOOKUP(A11,GDP_PPP_base!$C$2:$N$193,11,0)*10^9 -> 456849000000 | E11: =VLOOKUP(A11,INC_PPP_base!$C$2:$N$193,11,0) -> 11553.2 | F11: =D11/C11 -> 11670.245 | G11: =(F11-E11)/E11 -> 0.010130932 | H11: =VLOOKUP(A11,Elec_Access_base!$A$5:$BH$270,60,0)/100 -> 0.994 | I11: =VLOOKUP(A11,Data!$A$2:$I$126,9,0) -> 70819 | J11: =I11*10^9/3600/C11 -> 502.52141
A12: Angola | B12: =VLOOKUP(A12,Data!$A$1:$B$126,2,0) -> ago | C12: =VLOOKUP(A12,POP_base!$C$2:$T$201,17,0)*10^6 -> 27624320 | D12: =VLOOKUP(A12,GDP_PPP_base!$C$2:$N$193,11,0)*10^9 -> 223908000000 | E12: =VLOOKUP(A12,INC_PPP_base!$C$2:$N$193,11,0) -> 7960.42 | F12: =D12/C12 -> 8105.4665 | G12: =(F12-E12)/E12 -> 0.018220959 | H12: =VLOOKUP(A12,Elec_Access_base!$A$5:$BH$270,60,0)/100 -> 0.42 | I12: =VLOOKUP(A12,Data!$A$2:$I$126,9,0) -> 19987 | J12: =I12*10^9/3600/C12 -> 200.98031
A13: Morocco | B13: =VLOOKUP(A13,Data!$A$1:$B$126,2,0) -> mar | C13: =VLOOKUP(A13,POP_base!$C$2:$T$201,17,0)*10^6 -> 34467568 | D13: =VLOOKUP(A13,GDP_PPP_base!$C$2:$N$193,11,0)*10^9 -> 270392000000 | E13: =VLOOKUP(A13,INC_PPP_base!$C$2:$N$193,11,0) -> 7796.67 | F13: =D13/C13 -> 7844.8239 | G13: =(F13-E13)/E13 -> 0.0061762091 | H13: =VLOOKUP(A13,Elec_Access_base!$A$5:$BH$270,60,0)/100 -> 0.973 | I13: =VLOOKUP(A13,Data!$A$2:$I$126,9,0) -> 36543 | J13: =I13*10^9/3600/C13 -> 294.5039
... A38: Eswatini | B38: =VLOOKUP(A38,Data!$A$1:$B$126,2,0) -> swz | C38: =VLOOKUP(A38,POP_base!$C$2:$T$201,17,0)*10^6 -> 1129754 | D38: =VLOOKUP(A38,GDP_PPP_base!$C$2:$N$193,11,0)*10^9 -> 9171850000 | E38: =VLOOKUP(A38,INC_PPP_base!$C$2:$N$193,11,0) -> 8088.51 | F38: =D38/C38 -> 8118.4488 | G38: =(F38-E38)/E38 -> 0.003701398 | H38: =VLOOKUP(A38,Elec_Access_base!$A$5:$BH$270,60,0)/100 -> 0.641 | I38: =VLOOKUP(A38,Data!$A$2:$I$126,9,0) -> 1324 | J38: =I38*10^9/3600/C38 -> 325.53793

Sheet POP_base
A1: Model | B1: Scenario | C1: Region | D1: Variable | E1: Unit | F1: 1950 | G1: 1955 | H1: 1960 | I1: 1965 | J1: 1970 | K1: 1975 | L1: 1980 | M1: 1985 | N1: 1990 | O1: 1995 | P1: 2000 | Q1: 2005 | R1: 2010 | S1: 2015 | T1: 2020
A2: IIASA-WiC POP 2023 | B2: Historical Reference | C2: Aruba | D2: Population | E2: million | F2: 0.038123 | G2: 0.045654 | H2: 0.05386 | I2: 0.058504 | J2: 0.05924 | K2: 0.060375 | L2: 0.062138 | M2: 0.064383 | N2: 0.064895 | O2: 0.075884 | P2: 0.088122 | Q2: 0.093938 | R2: 0.099821 | S2: 0.103937 | T2: 0.106664
A3: IIASA-WiC POP 2023 | B3: Historical Reference | C3: Afghanistan | D3: Population | E3: million | F3: 7.436561 | G3: 7.915832 | H3: 8.541748 | I3: 9.457096 | J3: 10.620384 | K3: 12.016498 | L3: 12.917355 | M3: 10.50657 | N3: 10.845924 | O3: 16.071789 | P3: 19.669913 | Q3: 23.856141 | R3: 27.80317 | S3: 33.36082 | T3: 38.326031
A4: IIASA-WiC POP 2023 | B4: Historical Reference | C4: Angola | D4: Population | E4: million | F4: 4.432912 | G4: 4.895364 | H4: 5.313525 | I4: 5.707744 | J4: 5.9667 | K4: 6.916596 | L4: 8.182314 | M4: 9.791161 | N4: 11.631523 | O4: 13.680908 | P4: 16.126967 | Q4: 19.103826 | R4: 22.925082 | S4: 27.62432 | T4: 32.899002
A5: IIASA-WiC POP 2023 | B5: Historical Reference | C5: Albania | D5: Population | E5: million | F5: 1.234474 | G5: 1.430773 | H5: 1.682657 | I5: 1.97945 | J5: 2.292301 | K5: 2.61791 | L5: 2.915703 | M5: 3.15281 | N5: 3.290062 | O5: 3.28996 | P5: 3.195713 | Q5: 3.047469 | R5: 2.920897 | S5: 2.883156 | T5: 2.87213
A6: IIASA-WiC POP 2023 | B6: Historical Reference | C6: United Arab Emirates | D6: Population | E6: million | F6: 0.072048 | G6: 0.098947 | H6: 0.129741 | I6: 0.169496 | J6: 0.275244 | K6: 0.517455 | L6: 0.961141 | M6: 1.343826 | N6: 1.845986 | O6: 2.381492 | P6: 3.186118 | Q6: 4.083254 | R6: 8.433991 | S6: 8.877288 | T6: 9.247554
A7: IIASA-WiC POP 2023 | B7: Historical Reference | C7: Argentina | D7: Population | E7: million | F7: 16.849682 | G7: 18.5373 | H7: 20.187607 | I7: 21.880234 | J7: 23.652997 | K7: 25.669772 | L7: 27.804417 | M7: 30.058262 | N7: 32.402162 | O7: 34.721109 | P7: 36.864 | Q7: 38.867884 | R7: 40.892778 | S7: 43.042287 | T7: 44.908441
A8: IIASA-WiC POP 2023 | B8: Historical Reference | C8: Armenia | D8: Population | E8: million | F8: 1.366081 | G8: 1.578846 | H8: 1.870776 | I8: 2.202927 | J8: 2.505973 | K8: 2.798622 | L8: 3.119069 | M8: 3.287069 | N8: 3.525783 | O8: 3.333873 | P8: 3.187692 | Q8: 3.056449 | R8: 2.955608 | S8: 2.884958 | T8: 2.812494
A9: IIASA-WiC POP 2023 | B9: Historical Reference | C9: Antigua and Barbuda | D9: Population | E9: million | F9: 0.044948 | G9: 0.04977 | H9: 0.05482 | I9: 0.059162 | J9: 0.064296 | K9: 0.064101 | L9: 0.064782 | M9: 0.065212 | N9: 0.063473 | O9: 0.06771 | P9: 0.074423 | Q9: 0.07938 | R9: 0.085163 | S9: 0.089595 | T9: 0.092375
A10: IIASA-WiC POP 2023 | B10: Historical Reference | C10: Australia | D10: Population | E10: million | F10: 8.0489 | G10: 9.099771 | H10: 10.173755 | I10: 11.240012 | J10: 12.393916 | K10: 13.809241 | L10: 14.604481 | M10: 15.677747 | N10: 16.928886 | O10: 17.897944 | P10: 18.903313 | Q10: 20.04013 | R10: 21.856965 | S10: 23.641438 | T10: 25.544183
A11: IIASA-WiC POP 2023 | B11: Historical Reference | C11: Austria | D11: Population | E11: million | F11: 6.937809 | G11: 6.943932 | H11: 7.029366 | I11: 7.246871 | J11: 7.453368 | K11: 7.590322 | L11: 7.543687 | M11: 7.560286 | N11: 7.645463 | O11: 7.942527 | P11: 8.001197 | Q11: 8.200618 | R11: 8.350976 | S11: 8.584609 | T11: 8.9011
A12: IIASA-WiC POP 2023 | B12: Historical Reference | C12: Azerbaijan | D12: Population | E12: million | F12: 3.126982 | G12: 3.502112 | H12: 4.063658 | I12: 4.770385 | J12: 5.372649 | K12: 5.87609 | L12: 6.339692 | M12: 6.832859 | N12: 7.371985 | O12: 7.857374 | P12: 8.143914 | Q12: 8.604653 | R12: 9.177799 | S12: 9.804533 | T12: 10.273527
A13: IIASA-WiC POP 2023 | B13: Historical Reference | C13: Burundi | D13: Population | E13: million | F13: 2.229322 | G13: 2.470794 | H13: 2.719733 | I13: 3.086551 | J13: 3.45601 | K13: 3.711071 | L13: 4.176526 | M13: 4.903724 | N13: 5.428165 | O13: 5.898312 | P13: 6.243645 | Q13: 7.257392 | R13: 8.955711 | S13: 10.667662 | T13: 12.053895
... A201: IIASA-WiC POP 2023 | B201: Historical Reference | C201: Zimbabwe | D201: Population | E201: million | F201: 2.746396 | G201: 3.21349 | H201: 3.747472 | I201: 4.377599 | J201: 5.124662 | K201: 6.00165 | L201: 6.734798 | M201: 8.544135 | N201: 9.980999 | O201: 10.901511 | P201: 11.791214 | Q201: 12.195578 | R201: 12.753008 | S201: 14.006288 | T201: 15.505219

Sheet GDP_PPP_base
A1: Model | B1: Scenario | C1: Region | D1: Variable | E1: Unit | F1: 1980 | G1: 1985 | H1: 1990 | I1: 1995 | J1: 2000 | K1: 2005 | L1: 2010 | M1: 2015 | N1: 2020
A2: OECD ENV-Growth 2023 | B2: Historical Reference | C2: Aruba | D2: GDP|PPP | E2: billion USD_2017/yr | H2: 2.11677 | I2: 2.88042 | J2: 3.47463 | K2: 3.87497 | L2: 3.53452 | M2: 3.98373 | N2: 3.11606
A3: OECD ENV-Growth 2023 | B3: Historical Reference | C3: Angola | D3: GDP|PPP | E3: billion USD_2017/yr | H3: 68.5243 | I3: 58.6377 | J3: 77.1182 | K3: 120.066 | L3: 179.52 | M3: 223.908 | N3: 201.395
A4: OECD ENV-Growth 2023 | B4: Historical Reference | C4: Albania | D4: GDP|PPP | E4: billion USD_2017/yr | F4: 14.8499 | G4: 16.406 | H4: 16.7455 | I4: 14.6095 | J4: 18.6547 | K4: 24.8144 | L4: 32.0917 | M4: 35.0689 | N4: 38.6186
A5: OECD ENV-Growth 2023 | B5: Historical Reference | C5: United Arab Emirates | D5: GDP|PPP | E5: billion USD_2017/yr | F5: 169.912 | G5: 164.342 | H5: 194.55 | I5: 235.524 | J5: 317.069 | K5: 411.65 | L5: 480.294 | M5: 607.034 | N5: 628.455
A6: OECD ENV-Growth 2023 | B6: Historical Reference | C6: Argentina | D6: GDP|PPP | E6: billion USD_2017/yr | F6: 513.07 | G6: 461.13 | H6: 461.3 | I6: 604.596 | J6: 576.77 | K6: 634.572 | L6: 805.778 | M6: 867.021 | N6: 750.58
A7: OECD ENV-Growth 2023 | B7: Historical Reference | C7: Armenia | D7: GDP|PPP | E7: billion USD_2017/yr | H7: 18.3279 | I7: 9.68713 | J7: 12.2243 | K7: 22.0888 | L7: 26.6884 | M7: 33.1178 | N7: 37.5166
A8: OECD ENV-Growth 2023 | B8: Historical Reference | C8: Antigua and Barbuda | D8: GDP|PPP | E8: billion USD_2017/yr | F8: 0.54986 | G8: 0.712911 | H8: 0.966737 | I8: 1.07312 | J8: 1.39171 | K8: 1.60333 | L8: 1.60275 | M8: 1.73978 | N8: 1.74094
A9: OECD ENV-Growth 2023 | B9: Historical Reference | C9: Australia | D9: GDP|PPP | E9: billion USD_2017/yr | F9: 390.087 | G9: 452.531 | H9: 536.001 | I9: 612.702 | J9: 718.501 | K9: 848.066 | L9: 972.936 | M9: 1111.68 | N9: 1202.79
A10: OECD ENV-Growth 2023 | B10: Historical Reference | C10: Austria | D10: GDP|PPP | E10: billion USD_2017/yr | F10: 229.744 | G10: 247.132 | H10: 286.936 | I10: 320.261 | J10: 350.226 | K10: 382.176 | L10: 407.961 | M10: 431.002 | N10: 435.834
A11: OECD ENV-Growth 2023 | B11: Historical Reference | C11: Azerbaijan | D11: GDP|PPP | E11: billion USD_2017/yr | H11: 54.6529 | I11: 24.0195 | J11: 33.6378 | K11: 59.6581 | L11: 127.424 | M11: 143.331 | N11: 138.624
A12: OECD ENV-Growth 2023 | B12: Historical Reference | C12: Burundi | D12: GDP|PPP | E12: billion USD_2017/yr | F12: 3.72721 | G12: 4.80321 | H12: 5.76222 | I12: 5.11207 | J12: 5.09362 | K12: 5.88198 | L12: 7.3406 | M12: 8.38362 | N12: 8.69567
A13: OECD ENV-Growth 2023 | B13: Historical Reference | C13: Belgium | D13: GDP|PPP | E13: billion USD_2017/yr | F13: 290.045 | G13: 304.001 | H13: 353.911 | I13: 383.011 | J13: 412.034 | K13: 453.638 | L13: 488.271 | M13: 520.866 | N13: 528.495
A14: OECD ENV-Growth 2023 | B14: Historical Reference | C14: Benin | D14: GDP|PPP | E14: billion USD_2017/yr | F14: 9.32584 | G14: 9.92173 | H14: 10.9313 | I14: 13.4313 | J14: 17.0153 | K14: 20.6072 | L14: 24.8812 | M14: 31.1564 | N14: 40.287
A15: OECD ENV-Growth 2023 | B15: Historical Reference | C15: Burkina Faso | D15: GDP|PPP | E15: billion USD_2017/yr | F15: 6.70199 | G15: 7.79455 | H15: 9.01754 | I15: 10.9244 | J15: 15.1311 | K15: 20.6025 | L15: 26.9238 | M15: 35.0508 | N15: 45.2979
A16: OECD ENV-Growth 2023 | B16: Historical Reference | C16: Bangladesh | D16: GDP|PPP | E16: billion USD_2017/yr | F16: 138.127 | G16: 165.767 | H16: 199.079 | I16: 246.793 | J16: 312.734 | K16: 400.688 | L16: 537.977 | M16: 730.948 | N16: 999.535
A17: OECD ENV-Growth 2023 | B17: Historical Reference | C17: Bulgaria | D17: GDP|PPP | E17: billion USD_2017/yr | F17: 113.902 | G17: 137.072 | H17: 139.962 | I17: 95.8215 | J17: 86.0918 | K17: 113.557 | L17: 134.732 | M17: 143.928 | N17: 156.364
A18: OECD ENV-Growth 2023 | B18: Historical Reference | C18: Bahrain | D18: GDP|PPP | E18: billion USD_2017/yr | F18: 15.8672 | G18: 19.1642 | H18: 21.0703 | I18: 26.1304 | J18: 32.8333 | K18: 42.2266 | L18: 55.3404 | M18: 65.9987 | N18: 70.9099
A19: OECD ENV-Growth 2023 | B19: Historical Reference | C19: Bahamas | D19: GDP|PPP | E19: billion USD_2017/yr | F19: 7.1193 | G19: 8.36647 | H19: 9.4091 | I19: 9.36377 | J19: 11.9687 | K19: 12.9925 | L19: 12.8411 | M19: 13.3607 | N19: 10.622
A20: OECD ENV-Growth 2023 | B20: Historical Reference | C20: Bosnia and Herzegovina | D20: GDP|PPP | E20: billion USD_2017/yr | I20: 10.6305 | J20: 27.8832 | K20: 34.491 | L20: 40.7725 | M20: 44.1168 | N20: 48.7193
A21: OECD ENV-Growth 2023 | B21: Historical Reference | C21: Belarus | D21: GDP|PPP | E21: billion USD_2017/yr | H21: 90.636 | I21: 59.2958 | J21: 80.4963 | K21: 115.601 | L21: 164.445 | M21: 173.734 | N21: 180.446
A22: OECD ENV-Growth 2023 | B22: Historical Reference | C22: Belize | D22: GDP|PPP | E22: billion USD_2017/yr | F22: 0.58092 | G22: 0.626782 | H22: 1.16719 | I22: 1.5616 | J22: 2.09207 | K22: 2.7051 | L22: 2.89543 | M22: 3.37851 | N22: 3.04218
A23: OECD ENV-Growth 2023 | B23: Historical Reference | C23: Bolivia | D23: GDP|PPP | E23: billion USD_2017/yr | F23: 31.1143 | G23: 28.2268 | H23: 31.4915 | I23: 38.4942 | J23: 45.5886 | K23: 53.0807 | L23: 66.4498 | M23: 86.7889 | N23: 91.6687
A24: OECD ENV-Growth 2023 | B24: Historical Reference | C24: Brazil | D24: GDP|PPP | E24: billion USD_2017/yr | F24: 1334.93 | G24: 1422.04 | H24: 1561.05 | I24: 1815.94 | J24: 1983.47 | K24: 2292.42 | L24: 2849.54 | M24: 3016.14 | N24: 2935.82
A25: OECD ENV-Growth 2023 | B25: Historical Reference | C25: Barbados | D25: GDP|PPP | E25: billion USD_2017/yr | F25: 3.33356 | G25: 3.27377 | H25: 3.6602 | I25: 3.47938 | J25: 4.11907 | K25: 4.366 | L25: 4.40391 | M25: 4.39273 | N25: 3.87797
A26: OECD ENV-Growth 2023 | B26: Historical Reference | C26: Brunei Darussalam | D26: GDP|PPP | E26: billion USD_2017/yr | G26: 18.3666 | H26: 18.4286 | I26: 21.5237 | J26: 22.9959 | K26: 25.4796 | L26: 26.3305 | M26: 26.1967 | N26: 27.211
A27: OECD ENV-Growth 2023 | B27: Historical Reference | C27: Bhutan | D27: GDP|PPP | E27: billion USD_2017/yr | F27: 0.548435 | G27: 0.812451 | H27: 1.40587 | I27: 1.68378 | J27: 2.28617 | K27: 3.3399 | L27: 5.19084 | M27: 6.9475 | N27: 8.40082
A28: OECD ENV-Growth 2023 | B28: Historical Reference | C28: Botswana | D28: GDP|PPP | E28: billion USD_2017/yr | F28: 4.86069 | G28: 7.74202 | H28: 13.5765 | I28: 16.1109 | J28: 19.5947 | K28: 24.1686 | L28: 26.4665 | M28: 31.5408 | N28: 34.4925
A29: OECD ENV-Growth 2023 | B29: Historical Reference | C29: Central African Republic | D29: GDP|PPP | E29: billion USD_2017/yr | F29: 2.86721 | G29: 3.34604 | H29: 3.83824 | I29: 4.15394 | J29: 4.1603 | K29: 4.38073 | L29: 5.26971 | M29: 3.83133 | N29: 4.52762
A30: OECD ENV-Growth 2023 | B30: Historical Reference | C30: Canada | D30: GDP|PPP | E30: billion USD_2017/yr | F30: 737.974 | G30: 841.377 | H30: 957.085 | I30: 1041.67 | J30: 1192.38 | K30: 1354.21 | L30: 1433.98 | M30: 1594.85 | N30: 1649.89
A31: OECD ENV-Growth 2023 | B31: Historical Reference | C31: Switzerland | D31: GDP|PPP | E31: billion USD_2017/yr | F31: 302.884 | G31: 326.6 | H31: 377.794 | I31: 380.189 | J31: 412.757 | K31: 441.689 | L31: 495.041 | M31: 540.386 | N31: 568.96
A32: OECD ENV-Growth 2023 | B32: Historical Reference | C32: Chile | D32: GDP|PPP | E32: billion USD_2017/yr | F32: 97.0698 | G32: 93.4957 | H32: 123.943 | I32: 187.984 | J32: 220.125 | K32: 276.012 | L32: 334.745 | M32: 405.421 | N32: 410.374
A33: OECD ENV-Growth 2023 | B33: Historical Reference | C33: China | D33: GDP|PPP | E33: billion USD_2017/yr | F33: 666.047 | G33: 1107.46 | H33: 1617.4 | I33: 2881.39 | J33: 4456.79 | K33: 7112.15 | L33: 12153.7 | M33: 17796.8 | N33: 23516.1
A34: OECD ENV-Growth 2023 | B34: Historical Reference | C34: Cote d'Ivoire | D34: GDP|PPP | E34: billion USD_2017/yr | F34: 49.4384 | G34: 50.752 | H34: 54.5038 | I34: 57.4146 | J34: 68.5415 | K34: 68.5426 | L34: 76.4838 | M34: 104.388 | N34: 136.53
A35: OECD ENV-Growth 2023 | B35: Historical Reference | C35: Cameroon | D35: GDP|PPP | E35: billion USD_2017/yr | F35: 29.0234 | G35: 45.3597 | H35: 40.2539 | I35: 36.6355 | J35: 45.6696 | K35: 56.0453 | L35: 65.6235 | M35: 83.2307 | N35: 97.3865
A36: OECD ENV-Growth 2023 | B36: Historical Reference | C36: Democratic Republic of the Congo | D36: GDP|PPP | E36: billion USD_2017/yr | H36: 62.9843 | I36: 45.4303 | J36: 34.8778 | K36: 44.3111 | L36: 58.8781 | M36: 86.1266 | N36: 99.8086
A37: OECD ENV-Growth 2023 | B37: Historical Reference | C37: Congo | D37: GDP|PPP | E37: billion USD_2017/yr | F37: 6.82911 | G37: 7.7001 | H37: 12.041 | I37: 13.4714 | J37: 16.1869 | K37: 17.0355 | L37: 22.4127 | M37: 25.7383 | N37: 21.3772
A38: OECD ENV-Growth 2023 | B38: Historical Reference | C38: Colombia | D38: GDP|PPP | E38: billion USD_2017/yr | F38: 196.509 | G38: 219.811 | H38: 277.367 | I38: 349.784 | J38: 334.256 | K38: 399.28 | L38: 496.451 | M38: 624.056 | N38: 633.845
A39: OECD ENV-Growth 2023 | B39: Historical Reference | C39: Comoros | D39: GDP|PPP | E39: billion USD_2017/yr | F39: 0.936811 | G39: 1.13592 | H39: 1.3266 | I39: 1.38956 | J39: 1.46829 | K39: 1.80066 | L39: 1.98487 | M39: 2.30089 | N39: 2.59785
A40: OECD ENV-Growth 2023 | B40: Historical Reference | C40: Cabo Verde | D40: GDP|PPP | E40: billion USD_2017/yr | F40: 0.595205 | G40: 0.819637 | H40: 0.9922 | I40: 1.27876 | J40: 1.91039 | K40: 2.54831 | L40: 3.43928 | M40: 3.69543 | N40: 3.59291
...

Sheet INC_PPP_base
A1: Model | B1: Scenario | C1: Region | D1: Variable | E1: Unit | F1: 1980 | G1: 1985 | H1: 1990 | I1: 1995 | J1: 2000 | K1: 2005 | L1: 2010 | M1: 2015 | N1: 2020
A2: OECD ENV-Growth 2023 | B2: Historical Reference | C2: Aruba | D2: GDP|PPP [per capita] | E2: USD_2017/yr | H2: 32210.5 | I2: 37381.9 | J2: 38995.2 | K2: 41011.1 | L2: 35223.4 | M2: 38208.8 | N2: 29212.7
A3: OECD ENV-Growth 2023 | B3: Historical Reference | C3: Angola | D3: GDP|PPP [per capita] | E3: USD_2017/yr | H3: 5793.08 | I3: 4214.83 | J3: 4704.03 | K3: 6172.74 | L3: 7683.57 | M3: 7960.42 | N3: 6121.6
A4: OECD ENV-Growth 2023 | B4: Historical Reference | C4: Albania | D4: GDP|PPP [per capita] | E4: USD_2017/yr | F4: 5048.15 | G4: 5172.56 | H4: 5082 | I4: 4448.18 | J4: 5862.55 | K4: 8182.45 | L4: 11015.2 | M4: 12166.2 | N4: 13446
A5: OECD ENV-Growth 2023 | B5: Historical Reference | C5: United Arab Emirates | D5: GDP|PPP [per capita] | E5: USD_2017/yr | F5: 167558 | G5: 119128 | H5: 102387 | I5: 96764.7 | J5: 96805.1 | K5: 96157.5 | L5: 56626.7 | M5: 68076.7 | N5: 67959.1
A6: OECD ENV-Growth 2023 | B6: Historical Reference | C6: Argentina | D6: GDP|PPP [per capita] | E6: USD_2017/yr | F6: 18307.7 | G6: 15225.3 | H6: 14134 | I6: 17300.8 | J6: 15558.6 | K6: 16241.7 | L6: 19605.2 | M6: 20043.5 | N6: 16713.6
A7: OECD ENV-Growth 2023 | B7: Historical Reference | C7: Armenia | D7: GDP|PPP [per capita] | E7: USD_2017/yr | H7: 5153.3 | I7: 2915.36 | J7: 3858.03 | K7: 7248.78 | L7: 9058.31 | M7: 11504.8 | N7: 13339.2
A8: OECD ENV-Growth 2023 | B8: Historical Reference | C8: Antigua and Barbuda | D8: GDP|PPP [per capita] | E8: USD_2017/yr | F8: 8472.95 | G8: 10958.1 | H8: 15263.6 | I8: 15688.9 | J8: 18541.3 | K8: 20073.2 | L8: 18702.5 | M8: 19343.3 | N8: 18846
A9: OECD ENV-Growth 2023 | B9: Historical Reference | C9: Australia | D9: GDP|PPP [per capita] | E9: USD_2017/yr | F9: 26525.1 | G9: 28667.2 | H9: 31440.7 | I9: 34033.4 | J9: 37780.1 | K9: 42042.3 | L9: 44185.9 | M9: 46669.7 | N9: 47086.7
A10: OECD ENV-Growth 2023 | B10: Historical Reference | C10: Austria | D10: GDP|PPP [per capita] | E10: USD_2017/yr | F10: 30439.5 | G10: 32680.3 | H10: 37367.6 | I10: 40298.1 | J10: 43721.2 | K10: 46453.7 | L10: 48782.6 | M10: 49870.5 | N10: 48964
A11: OECD ENV-Growth 2023 | B11: Historical Reference | C11: Azerbaijan | D11: GDP|PPP [per capita] | E11: USD_2017/yr | H11: 7357.84 | I11: 3044.55 | J11: 4107.01 | K11: 6891.92 | L11: 13794.7 | M11: 14531.5 | N11: 13493.3
A12: OECD ENV-Growth 2023 | B12: Historical Reference | C12: Burundi | D12: GDP|PPP [per capita] | E12: USD_2017/yr | F12: 864.214 | G12: 970.733 | H12: 1050.77 | I12: 861.665 | J12: 807.529 | K12: 796.059 | L12: 804.308 | M12: 781.532 | N12: 721.399
A13: OECD ENV-Growth 2023 | B13: Historical Reference | C13: Belgium | D13: GDP|PPP [per capita] | E13: USD_2017/yr | F13: 29509.1 | G13: 30767.7 | H13: 35534.8 | I13: 37939.9 | J13: 40142.2 | K13: 43133.8 | L13: 44886.3 | M13: 46306.2 | N13: 45791.7
A14: OECD ENV-Growth 2023 | B14: Historical Reference | C14: Benin | D14: GDP|PPP [per capita] | E14: USD_2017/yr | F14: 2432.45 | G14: 2244.96 | H14: 2129.43 | I14: 2221.32 | J14: 2431.44 | K14: 2528.67 | L14: 2634.13 | M14: 2849.81 | N14: 3231.54
A15: OECD ENV-Growth 2023 | B15: Historical Reference | C15: Burkina Faso | D15: GDP|PPP [per capita] | E15: USD_2017/yr | F15: 966.684 | G15: 976.86 | H15: 987.535 | I15: 1055.16 | J15: 1273.35 | K15: 1484.74 | L15: 1670.54 | M15: 1872.57 | N15: 2133.48
A16: OECD ENV-Growth 2023 | B16: Historical Reference | C16: Bangladesh | D16: GDP|PPP [per capita] | E16: USD_2017/yr | F16: 1645.75 | G16: 1727.48 | H16: 1857.99 | I16: 2095.14 | J16: 2420.67 | K16: 2843.52 | L16: 3625.4 | M16: 4631.24 | N16: 6005.84
A17: OECD ENV-Growth 2023 | B17: Historical Reference | C17: Bulgaria | D17: GDP|PPP [per capita] | E17: USD_2017/yr | F17: 12683.2 | G17: 15371.9 | H17: 15963.2 | I17: 11302.9 | J17: 10631.6 | K17: 14530.2 | L17: 17745.9 | M17: 19691.2 | N17: 22273.4
A18: OECD ENV-Growth 2023 | B18: Historical Reference | C18: Bahrain | D18: GDP|PPP [per capita] | E18: USD_2017/yr | F18: 43759.8 | G18: 44118.5 | H18: 40721.7 | I18: 42631.8 | J18: 46150.3 | K18: 46818.4 | L18: 45598.6 | M18: 48452.1 | N18: 47462.1
A19: OECD ENV-Growth 2023 | B19: Historical Reference | C19: Bahamas | D19: GDP|PPP [per capita] | E19: USD_2017/yr | F19: 31817.2 | G19: 34018.8 | H19: 34760.7 | I19: 31259.2 | J19: 36824.7 | K19: 37355.8 | L19: 34400.6 | M19: 34022.5 | N19: 26176.8
A20: OECD ENV-Growth 2023 | B20: Historical Reference | C20: Bosnia and Herzegovina | D20: GDP|PPP [per capita] | E20: USD_2017/yr | I20: 2834.41 | J20: 6671.65 | K20: 8424.15 | L20: 10698.4 | M20: 12517.8 | N20: 14582.4
A21: OECD ENV-Growth 2023 | B21: Historical Reference | C21: Belarus | D21: GDP|PPP [per capita] | E21: USD_2017/yr | H21: 8691.16 | I21: 5667.9 | J21: 7848.33 | K21: 11635.5 | L21: 16898.3 | M21: 17909.6 | N21: 18677.7
A22: OECD ENV-Growth 2023 | B22: Historical Reference | C22: Belize | D22: GDP|PPP [per capita] | E22: USD_2017/yr | F22: 4002.53 | G22: 3834.89 | H22: 6392.23 | I22: 7671.54 | J22: 8702.18 | K22: 9648 | L22: 8989.07 | M22: 9388.08 | N22: 7752.25
A23: OECD ENV-Growth 2023 | B23: Historical Reference | C23: Bolivia | D23: GDP|PPP [per capita] | E23: USD_2017/yr | F23: 5424.3 | G23: 4420.36 | H23: 4437.81 | I23: 4909.05 | J23: 5305.53 | K23: 5660.5 | L23: 6499.85 | M23: 7825.8 | N23: 7727.7
A24: OECD ENV-Growth 2023 | B24: Historical Reference | C24: Brazil | D24: GDP|PPP [per capita] | E24: USD_2017/yr | F24: 10916.2 | G24: 10396.3 | H24: 10358.2 | I24: 11105.6 | J24: 11277.8 | K24: 12272.2 | L24: 14512.3 | M24: 14699.4 | N24: 13811.4
A25: OECD ENV-Growth 2023 | B25: Historical Reference | C25: Barbados | D25: GDP|PPP [per capita] | E25: USD_2017/yr | F25: 13146 | G25: 12693.2 | H25: 14139.2 | I25: 13264.5 | J25: 15563.8 | K25: 16201.3 | L25: 16031.1 | M25: 15796.4 | N25: 13828.8
A26: OECD ENV-Growth 2023 | B26: Historical Reference | C26: Brunei Darussalam | D26: GDP|PPP [per capita] | E26: USD_2017/yr | G26: 82686.5 | H26: 70356.8 | I26: 71961.8 | J26: 68864.5 | K26: 69480.2 | L26: 66482 | M26: 62160.1 | N26: 61858.3
A27: OECD ENV-Growth 2023 | B27: Historical Reference | C27: Bhutan | D27: GDP|PPP [per capita] | E27: USD_2017/yr | F27: 1320.7 | G27: 1676.79 | H27: 2517.48 | I27: 3191.77 | J27: 3893.28 | K27: 5035.1 | L27: 7357.5 | M27: 9347.11 | N27: 10910.1
A28: OECD ENV-Growth 2023 | B28: Historical Reference | C28: Botswana | D28: GDP|PPP [per capita] | E28: USD_2017/yr | F28: 5178.78 | G28: 6798.97 | H28: 10120.5 | I28: 10437 | J28: 11346.2 | K28: 12768.6 | L28: 12653.3 | M28: 13682.6 | N28: 13668.3
A29: OECD ENV-Growth 2023 | B29: Historical Reference | C29: Central African Republic | D29: GDP|PPP [per capita] | E29: USD_2017/yr | F29: 1187.11 | G29: 1310.59 | H29: 1366.3 | I29: 1267.72 | J29: 1106.71 | K29: 1040.84 | L29: 1130.82 | M29: 794.99 | N29: 858.802
A30: OECD ENV-Growth 2023 | B30: Historical Reference | C30: Canada | D30: GDP|PPP [per capita] | E30: USD_2017/yr | F30: 30107.3 | G30: 32556.1 | H30: 34605.3 | I30: 35564.7 | J30: 38860.7 | K30: 42035.5 | L30: 42221.4 | M30: 44633.5 | N30: 43696.3
A31: OECD ENV-Growth 2023 | B31: Historical Reference | C31: Switzerland | D31: GDP|PPP [per capita] | E31: USD_2017/yr | F31: 47931.5 | G31: 50480.5 | H31: 56288.9 | I31: 54017.2 | J31: 57470.4 | K31: 59459.1 | L31: 63284.8 | M31: 65250.4 | N31: 66108.7
A32: OECD ENV-Growth 2023 | B32: Historical Reference | C32: Chile | D32: GDP|PPP [per capita] | E32: USD_2017/yr | F32: 8463.05 | G32: 7585 | H32: 9289.1 | I32: 13039.2 | J32: 14338.7 | K32: 17063.8 | L32: 19686.1 | M32: 22687.1 | N32: 21366.2
A33: OECD ENV-Growth 2023 | B33: Historical Reference | C33: China | D33: GDP|PPP [per capita] | E33: USD_2017/yr | F33: 677.999 | G33: 1044.54 | H33: 1401.92 | I33: 2365.39 | J33: 3525.67 | K33: 5450.39 | L33: 9014.81 | M33: 12769.3 | N33: 16514.2
A34: OECD ENV-Growth 2023 | B34: Historical Reference | C34: Cote d'Ivoire | D34: GDP|PPP [per capita] | E34: USD_2017/yr | F34: 5953.71 | G34: 5093.5 | H34: 4576.1 | I34: 4015.09 | J34: 4079.93 | K34: 3613.17 | L34: 3621.39 | M34: 4423.82 | N34: 5156.43
A35: OECD ENV-Growth 2023 | B35: Historical Reference | C35: Cameroon | D35: GDP|PPP [per capita] | E35: USD_2017/yr | F35: 3406.54 | G35: 4626.53 | H35: 3521.62 | I35: 2772.97 | J35: 3026.16 | K35: 3244.27 | L35: 3301.31 | M35: 3616.74 | N35: 3725.98
A36: OECD ENV-Growth 2023 | B36: Historical Reference | C36: Democratic Republic of the Congo | D36: GDP|PPP [per capita] | E36: USD_2017/yr | H36: 1750.17 | I36: 1049.54 | J36: 717.41 | K36: 783.57 | L36: 886.836 | M36: 1094.97 | N36: 1092.81
A37: OECD ENV-Growth 2023 | B37: Historical Reference | C37: Congo | D37: GDP|PPP [per capita] | E37: USD_2017/yr | F37: 3733.27 | G37: 3733.27 | H37: 5047.73 | I37: 4912.43 | J37: 5164.88 | K37: 4638.22 | L37: 5050.31 | M37: 5082.22 | N37: 3793.45
A38: OECD ENV-Growth 2023 | B38: Historical Reference | C38: Colombia | D38: GDP|PPP [per capita] | E38: USD_2017/yr | F38: 7507.18 | G38: 7495.36 | H38: 8507.84 | I38: 9724.29 | J38: 8523.65 | K38: 9456.91 | L38: 11077.5 | M38: 13244 | N38: 12522.4
A39: OECD ENV-Growth 2023 | B39: Historical Reference | C39: Comoros | D39: GDP|PPP [per capita] | E39: USD_2017/yr | F39: 2853.28 | G39: 3023.84 | H39: 3077.11 | I39: 2872.41 | J39: 2735.46 | K39: 3038.13 | L39: 3025.59 | M39: 3150.97 | N39: 3254.12
A40: OECD ENV-Growth 2023 | B40: Historical Reference | C40: Cabo Verde | D40: GDP|PPP [per capita] | E40: USD_2017/yr | F40: 1876.22 | G40: 2411.58 | H40: 2721.57 | I40: 3108.44 | J40: 4168.89 | K40: 5170.78 | L40: 6598.59 | M40: 6692.56 | N40: 6195.38
...

Sheet Elec_Access_base
A1: Data Source | B1: World Development Indicators
A2: Last Updated Date | B2: 45839
A4: Country Name | B4: Country Code | C4: Indicator Name | D4: Indicator Code | E4: 1960 | F4: 1961 | G4: 1962 | H4: 1963 | I4: 1964 | J4: 1965 | K4: 1966 | L4: 1967 | M4: 1968 | N4: 1969 | O4: 1970 | P4: 1971 | Q4: 1972 | R4: 1973 | S4: 1974 | T4: 1975 | U4: 1976 | V4: 1977 | W4: 1978 | X4: 1979 | Y4: 1980 | Z4: 1981 | AA4: 1982 | AB4: 1983 | AC4: 1984 | AD4: 1985 | AE4: 1986 | AF4: 1987 | AG4: 1988 | AH4: 1989 | AI4: 1990 | AJ4: 1991 | AK4: 1992 | AL4: 1993 | AM4: 1994 | AN4: 1995 | AO4: 1996 | AP4: 1997 | AQ4: 1998 | AR4: 1999 | AS4: 2000 | AT4: 2001 | AU4: 2002 | AV4: 2003 | AW4: 2004 | AX4: 2005 | AY4: 2006 | AZ4: 2007 | BA4: 2008 | BB4: 2009 | BC4: 2010 | BD4: 2011 | BE4: 2012 | BF4: 2013 | BG4: 2014 | BH4: 2015 | BI4: 2016 | BJ4: 2017 | BK4: 2018 | BL4: 2019 | BM4: 2020 | BN4: 2021 | BO4: 2022 | BP4: 2023 | BQ4: 2024
A5: Aruba | B5: ABW | C5: Access to electricity (% of population) | D5: EG.ELC.ACCS.ZS | AI5: 100 | AJ5: 99.153656 | AK5: 99.197128 | AL5: 99.239914 | AM5: 100 | AN5: 100 | AO5: 100 | AP5: 100 | AQ5: 100 | AR5: 100 | AS5: 91.7 | AT5: 100 | AU5: 100 | AV5: 100 | AW5: 100 | AX5: 100 | AY5: 100 | AZ5: 100 | BA5: 100 | BB5: 100 | BC5: 93.4 | BD5: 100 | BE5: 100 | BF5: 100 | BG5: 100 | BH5: 100 | BI5: 100 | BJ5: 100 | BK5: 100 | BL5: 100 | BM5: 100 | BN5: 100 | BO5: 99.9 | BP5: 100
A6: Africa Eastern and Southern | B6: AFE | C6: Access to electricity (% of population) | D6: EG.ELC.ACCS.ZS | AS6: 19.917256 | AT6: 19.944277 | AU6: 21.548647 | AV6: 22.493217 | AW6: 23.724455 | AX6: 23.449539 | AY6: 25.172482 | AZ6: 26.795145 | BA6: 25.908845 | BB6: 26.187846 | BC6: 27.414954 | BD6: 28.909756 | BE6: 31.673427 | BF6: 31.723574 | BG6: 31.871956 | BH6: 33.922276 | BI6: 38.859598 | BJ6: 40.223744 | BK6: 43.035073 | BL6: 44.390861 | BM6: 46.282371 | BN6: 48.127211 | BO6: 48.801258 | BP6: 50.66833
A7: Afghanistan | B7: AFG | C7: Access to electricity (% of population) | D7: EG.ELC.ACCS.ZS | AS7: 4.4 | AT7: 9.3 | AU7: 14.1 | AV7: 19 | AW7: 23.8 | AX7: 28.7 | AY7: 33.5 | AZ7: 38.4 | BA7: 42.4 | BB7: 48.3 | BC7: 42.7 | BD7: 43.2 | BE7: 69.1 | BF7: 68 | BG7: 89.5 | BH7: 71.5 | BI7: 97.7 | BJ7: 97.7 | BK7: 93.4 | BL7: 97.7 | BM7: 97.7 | BN7: 97.7 | BO7: 85.3 | BP7: 85.3
A8: Africa Western and Central | B8: AFW | C8: Access to electricity (% of population) | D8: EG.ELC.ACCS.ZS | AL8: 31.653469 | AM8: 32.692208 | AN8: 33.694835 | AO8: 32.697395 | AP8: 32.52392 | AQ8: 33.513504 | AR8: 34.893857 | AS8: 34.246116 | AT8: 35.323267 | AU8: 35.809111 | AV8: 39.960254 | AW8: 37.594502 | AX8: 37.93591 | AY8: 39.952904 | AZ8: 40.864862 | BA8: 41.866015 | BB8: 42.002485 | BC8: 41.95199 | BD8: 46.061967 | BE8: 44.1865 | BF8: 47.194503 | BG8: 47.767361 | BH8: 46.862418 | BI8: 51.045127 | BJ8: 48.900728 | BK8: 51.335829 | BL8: 51.291577 | BM8: 51.856043 | BN8: 54.368599 | BO8: 55.686683 | BP8: 57.069267
A9: Angola | B9: AGO | C9: Access to electricity (% of population) | D9: EG.ELC.ACCS.ZS | AS9: 24.2 | AT9: 20 | AU9: 26.3 | AV9: 27.4 | AW9: 28.4 | AX9: 29.4 | AY9: 30.5 | AZ9: 37.5 | BA9: 38.5 | BB9: 33.8 | BC9: 35 | BD9: 34.6 | BE9: 37.3 | BF9: 38.4 | BG9: 32 | BH9: 42 | BI9: 41.8 | BJ9: 42.9 | BK9: 45.3 | BL9: 45.6 | BM9: 47 | BN9: 48.2 | BO9: 48.5 | BP9: 51.1
A10: Albania | B10: ALB | C10: Access to electricity (% of population) | D10: EG.ELC.ACCS.ZS | AI10: 100 | AJ10: 100 | AK10: 100 | AL10: 100 | AM10: 100 | AN10: 100 | AO10: 100 | AP10: 100 | AQ10: 100 | AR10: 100 | AS10: 99.4 | AT10: 99.4 | AU10: 99.4 | AV10: 99.4 | AW10: 99.4 | AX10: 99.4 | AY10: 99.4 | AZ10: 99.4 | BA10: 100 | BB10: 99.6 | BC10: 99.6 | BD10: 99.7 | BE10: 99.9 | BF10: 99.9 | BG10: 100 | BH10: 100 | BI10: 99.9 | BJ10: 99.9 | BK10: 100 | BL10: 100 | BM10: 100 | BN10: 100 | BO10: 100 | BP10: 100
A11: Andorra | B11: AND | C11: Access to electricity (% of population) | D11: EG.ELC.ACCS.ZS | AI11: 100 | AJ11: 100 | AK11: 100 | AL11: 100 | AM11: 100 | AN11: 100 | AO11: 100 | AP11: 100 | AQ11: 100 | AR11: 100 | AS11: 100 | AT11: 100 | AU11: 100 | AV11: 100 | AW11: 100 | AX11: 100 | AY11: 100 | AZ11: 100 | BA11: 100 | BB11: 100 | BC11: 100 | BD11: 100 | BE11: 100 | BF11: 100 | BG11: 100 | BH11: 100 | BI11: 100 | BJ11: 100 | BK11: 100 | BL11: 100 | BM11: 100 | BN11: 100 | BO11: 100 | BP11: 100
A12: Arab World | B12: ARB | C12: Access to electricity (% of population) | D12: EG.ELC.ACCS.ZS | AP12: 76.611777 | AQ12: 77.541255 | AR12: 78.156404 | AS12: 80.458667 | AT12: 81.354794 | AU12: 81.323622 | AV12: 82.342222 | AW12: 82.279525 | AX12: 83.076767 | AY12: 85.284394 | AZ12: 83.626764 | BA12: 83.275564 | BB12: 84.159729 | BC12: 86.921503 | BD12: 87.172694 | BE12: 86.847867 | BF12: 88.96163 | BG12: 88.406777 | BH12: 88.661643 | BI12: 89.186171 | BJ12: 90.351067 | BK12: 88.689841 | BL12: 89.928996 | BM12: 90.241777 | BN12: 90.434095 | BO12: 90.654518 | BP12: 91.64543
A13: United Arab Emirates | B13: ARE | C13: Access to electricity (% of population) | D13: EG.ELC.ACCS.ZS | AI13: 100 | AJ13: 100 | AK13: 100 | AL13: 100 | AM13: 100 | AN13: 100 | AO13: 100 | AP13: 100 | AQ13: 100 | AR13: 100 | AS13: 100 | AT13: 100 | AU13: 100 | AV13: 100 | AW13: 100 | AX13: 100 | AY13: 100 | AZ13: 100 | BA13: 100 | BB13: 100 | BC13: 100 | BD13: 100 | BE13: 100 | BF13: 100 | BG13: 100 | BH13: 100 | BI13: 100 | BJ13: 100 | BK13: 100 | BL13: 100 | BM13: 100 | BN13: 100 | BO13: 100 | BP13: 100
A14: Argentina | B14: ARG | C14: Access to electricity (% of population) | D14: EG.ELC.ACCS.ZS | AI14: 92.1548 | AJ14: 92.492188 | AK14: 92.829453 | AL14: 93.166046 | AM14: 93.501274 | AN14: 93.834465 | AO14: 94.16494 | AP14: 94.492012 | AQ14: 94.815002 | AR14: 95.133156 | AS14: 95.7 | AT14: 95.5 | AU14: 96.1 | AV14: 96.3 | AW14: 96.5 | AX14: 96.7 | AY14: 97 | AZ14: 97.2 | BA14: 97.5 | BB14: 97.8 | BC14: 98.8 | BD14: 99 | BE14: 99.1 | BF14: 99.3 | BG14: 100 | BH14: 99.7 | BI14: 99.9 | BJ14: 100 | BK14: 100 | BL14: 100 | BM14: 100 | BN14: 100 | BO14: 100 | BP14: 100
A15: Armenia | B15: ARM | C15: Access to electricity (% of population) | D15: EG.ELC.ACCS.ZS | AS15: 98.9 | AT15: 100 | AU15: 98 | AV15: 99.1 | AW15: 99.1 | AX15: 99.8 | AY15: 99.1 | AZ15: 99.2 | BA15: 99.2 | BB15: 99.3 | BC15: 99.8 | BD15: 99.5 | BE15: 99.5 | BF15: 99.4 | BG15: 99.7 | BH15: 100 | BI15: 99.8 | BJ15: 99.7 | BK15: 99.9 | BL15: 100 | BM15: 100 | BN15: 100 | BO15: 100 | BP15: 100
A16: American Samoa | B16: ASM | C16: Access to electricity (% of population) | D16: EG.ELC.ACCS.ZS
A17: Antigua and Barbuda | B17: ATG | C17: Access to electricity (% of population) | D17: EG.ELC.ACCS.ZS | AI17: 95.763046 | AJ17: 95.940651 | AK17: 96.118134 | AL17: 96.294945 | AM17: 96.47039 | AN17: 96.643799 | AO17: 96.814484 | AP17: 96.981773 | AQ17: 97.144981 | AR17: 97.303352 | AS17: 97.7 | AT17: 97.7 | AU17: 100 | AV17: 97.9 | AW17: 97.9 | AX17: 92.2 | AY17: 100 | AZ17: 100 | BA17: 100 | BB17: 98.5 | BC17: 98.7 | BD17: 94.6 | BE17: 100 | BF17: 100 | BG17: 100 | BH17: 100 | BI17: 100 | BJ17: 100 | BK17: 100 | BL17: 100 | BM17: 100 | BN17: 100 | BO17: 100 | BP17: 100
A18: Australia | B18: AUS | C18: Access to electricity (% of population) | D18: EG.ELC.ACCS.ZS | AI18: 100 | AJ18: 100 | AK18: 100 | AL18: 100 | AM18: 100 | AN18: 100 | AO18: 100 | AP18: 100 | AQ18: 100 | AR18: 100 | AS18: 100 | AT18: 100 | AU18: 100 | AV18: 100 | AW18: 100 | AX18: 100 | AY18: 100 | AZ18: 100 | BA18: 100 | BB18: 100 | BC18: 100 | BD18: 100 | BE18: 100 | BF18: 100 | BG18: 100 | BH18: 100 | BI18: 100 | BJ18: 100 | BK18: 100 | BL18: 100 | BM18: 100 | BN18: 100 | BO18: 100 | BP18: 100
A19: Austria | B19: AUT | C19: Access to electricity (% of population) | D19: EG.ELC.ACCS.ZS | AI19: 100 | AJ19: 100 | AK19: 100 | AL19: 100 | AM19: 100 | AN19: 100 | AO19: 100 | AP19: 100 | AQ19: 100 | AR19: 100 | AS19: 100 | AT19: 100 | AU19: 100 | AV19: 100 | AW19: 100 | AX19: 100 | AY19: 100 | AZ19: 100 | BA19: 100 | BB19: 100 | BC19: 100 | BD19: 100 | BE19: 100 | BF19: 100 | BG19: 100 | BH19: 100 | BI19: 100 | BJ19: 100 | BK19: 100 | BL19: 100 | BM19: 100 | BN19: 100 | BO19: 100 | BP19: 100
A20: Azerbaijan | B20: AZE | C20: Access to electricity (% of population) | D20: EG.ELC.ACCS.ZS | AR20: 97 | AS20: 98.9 | AT20: 98.6 | AU20: 100 | AV20: 98.8 | AW20: 99 | AX20: 99.1 | AY20: 99.5 | AZ20: 99.5 | BA20: 99.7 | BB20: 99.9 | BC20: 99.9 | BD20: 99.9 | BE20: 100 | BF20: 100 | BG20: 100 | BH20: 100 | BI20: 100 | BJ20: 100 | BK20: 100 | BL20: 100 | BM20: 100 | BN20: 100 | BO20: 100 | BP20: 100
A21: Burundi | B21: BDI | C21: Access to electricity (% of population) | D21: EG.ELC.ACCS.ZS | AQ21: 3.9 | AR21: 2.0709493 | AS21: 2.5 | AT21: 2.8 | AU21: 3.1 | AV21: 3.4 | AW21: 3.7 | AX21: 3.2 | AY21: 2.7 | AZ21: 4.7 | BA21: 4.8 | BB21: 5.4 | BC21: 5.3 | BD21: 6.2 | BE21: 6.5 | BF21: 6.9 | BG21: 7 | BH21: 7.9 | BI21: 8.5 | BJ21: 9.3 | BK21: 9.5 | BL21: 9.8 | BM21: 9.1 | BN21: 10.2 | BO21: 10.3 | BP21: 11.6
A22: Belgium | B22: BEL | C22: Access to electricity (% of population) | D22: EG.ELC.ACCS.ZS | AI22: 100 | AJ22: 100 | AK22: 100 | AL22: 100 | AM22: 100 | AN22: 100 | AO22: 100 | AP22: 100 | AQ22: 100 | AR22: 100 | AS22: 100 | AT22: 100 | AU22: 100 | AV22: 100 | AW22: 100 | AX22: 100 | AY22: 100 | AZ22: 100 | BA22: 100 | BB22: 100 | BC22: 100 | BD22: 100 | BE22: 100 | BF22: 100 | BG22: 100 | BH22: 100 | BI22: 100 | BJ22: 100 | BK22: 100 | BL22: 100 | BM22: 100 | BN22: 100 | BO22: 100 | BP22: 100
A23: Benin | B23: BEN | C23: Access to electricity (% of population) | D23: EG.ELC.ACCS.ZS | AO23: 14.5 | AP23: 18.589626 | AQ23: 19.578255 | AR23: 20.562042 | AS23: 21.5 | AT23: 21.9 | AU23: 23.4 | AV23: 24.3 | AW23: 25.2 | AX23: 26.1 | AY23: 27.9 | AZ23: 28 | BA23: 29 | BB23: 30 | BC23: 34.2 | BD23: 36.9 | BE23: 38.4 | BF23: 34.7 | BG23: 34.1 | BH23: 29.6 | BI23: 37 | BJ23: 34.5 | BK23: 39 | BL23: 40 | BM23: 41 | BN23: 42 | BO23: 56.5 | BP23: 57
A24: Burkina Faso | B24: BFA | C24: Access to electricity (% of population) | D24: EG.ELC.ACCS.ZS | AL24: 6.1 | AM24: 6.12501 | AN24: 6.6253328 | AO24: 7.1229362 | AP24: 7.6171398 | AQ24: 8.1072645 | AR24: 6.9 | AS24: 9.1 | AT24: 9.5 | AU24: 9.9 | AV24: 11.4 | AW24: 10.7 | AX24: 11.1 | AY24: 11.6 | AZ24: 12 | BA24: 12.5 | BB24: 12.6 | BC24: 13.1 | BD24: 14.8 | BE24: 15.1 | BF24: 15.4 | BG24: 19.2 | BH24: 16.2 | BI24: 16.6 | BJ24: 17 | BK24: 14.4 | BL24: 17.6 | BM24: 18.5 | BN24: 19 | BO24: 19.5 | BP24: 21.7
A25: Bangladesh | B25: BGD | C25: Access to electricity (% of population) | D25: EG.ELC.ACCS.ZS | AJ25: 14.29 | AK25: 9.9054193 | AL25: 12.71788 | AM25: 17.8 | AN25: 18.338045 | AO25: 21.144386 | AP25: 22.4 | AQ25: 26.746193 | AR25: 29.540215 | AS25: 32 | AT25: 35 | AU25: 37.8 | AV25: 40.5 | AW25: 40.6 | AX25: 44.2 | AY25: 50.5 | AZ25: 46.5 | BA25: 54.3 | BB25: 57.1 | BC25: 55.3 | BD25: 59.6 | BE25: 65.5 | BF25: 61.5 | BG25: 62.4 | BH25: 74 | BI25: 75.9 | BJ25: 88 | BK25: 86.9 | BL25: 92.2 | BM25: 96.2 | BN25: 99 | BO25: 99.4 | BP25: 99.5
A26: Bulgaria | B26: BGR | C26: Access to electricity (% of population) | D26: EG.ELC.ACCS.ZS | AI26: 100 | AJ26: 100 | AK26: 100 | AL26: 100 | AM26: 100 | AN26: 100 | AO26: 100 | AP26: 100 | AQ26: 100 | AR26: 100 | AS26: 88.1 | AT26: 88.6 | AU26: 89.1 | AV26: 89.6 | AW26: 90.1 | AX26: 90.6 | AY26: 91.2 | AZ26: 91.7 | BA26: 92.3 | BB26: 92.9 | BC26: 93.5 | BD26: 94.1 | BE26: 94.7 | BF26: 95.3 | BG26: 95.9 | BH26: 96.6 | BI26: 97.3 | BJ26: 98.1 | BK26: 98.7 | BL26: 99.2 | BM26: 99.7 | BN26: 99.8 | BO26: 100 | BP26: 100
A27: Bahrain | B27: BHR | C27: Access to electricity (% of population) | D27: EG.ELC.ACCS.ZS | AI27: 99.941399 | AJ27: 99.967392 | AK27: 99.987183 | AL27: 99.997139 | AM27: 99.999771 | AN27: 100 | AO27: 100 | AP27: 100 | AQ27: 100 | AR27: 100 | AS27: 100 | AT27: 100 | AU27: 100 | AV27: 100 | AW27: 100 | AX27: 100 | AY27: 100 | AZ27: 100 | BA27: 100 | BB27: 100 | BC27: 100 | BD27: 100 | BE27: 100 | BF27: 100 | BG27: 100 | BH27: 100 | BI27: 100 | BJ27: 100 | BK27: 100 | BL27: 100 | BM27: 100 | BN27: 100 | BO27: 100 | BP27: 100
A28: Bahamas, The | B28: BHS | C28: Access to electricity (% of population) | D28: EG.ELC.ACCS.ZS | AI28: 100 | AJ28: 100 | AK28: 100 | AL28: 100 | AM28: 100 | AN28: 100 | AO28: 100 | AP28: 100 | AQ28: 100 | AR28: 100 | AS28: 100 | AT28: 100 | AU28: 100 | AV28: 100 | AW28: 100 | AX28: 100 | AY28: 100 | AZ28: 100 | BA28: 100 | BB28: 100 | BC28: 100 | BD28: 100 | BE28: 100 | BF28: 100 | BG28: 100 | BH28: 100 | BI28: 100 | BJ28: 100 | BK28: 100 | BL28: 100 | BM28: 100 | BN28: 100 | BO28: 100 | BP28: 100
A29: Bosnia and Herzegovina | B29: BIH | C29: Access to electricity (% of population) | D29: EG.ELC.ACCS.ZS | AI29: 100 | AJ29: 100 | AK29: 100 | AL29: 100 | AM29: 100 | AN29: 100 | AO29: 100 | AP29: 100 | AQ29: 100 | AR29: 100 | AS29: 99 | AT29: 99.4 | AU29: 98.5 | AV29: 99 | AW29: 99.1 | AX29: 99.1 | AY29: 99.4 | AZ29: 99.7 | BA29: 99.3 | BB29: 99.4 | BC29: 99.5 | BD29: 99.7 | BE29: 99.7 | BF29: 99.5 | BG29: 99.9 | BH29: 99.7 | BI29: 100 | BJ29: 100 | BK29: 100 | BL29: 100 | BM29: 100 | BN29: 100 | BO29: 100 | BP29: 100
A30: Belarus | B30: BLR | C30: Access to electricity (% of population) | D30: EG.ELC.ACCS.ZS | AI30: 100 | AJ30: 100 | AK30: 100 | AL30: 100 | AM30: 100 | AN30: 100 | AO30: 100 | AP30: 100 | AQ30: 100 | AR30: 100 | AS30: 89 | AT30: 89.5 | AU30: 90 | AV30: 90.5 | AW30: 91 | AX30: 91.5 | AY30: 92.1 | AZ30: 92.6 | BA30: 93.2 | BB30: 93.8 | BC30: 94.4 | BD30: 95 | BE30: 95.6 | BF30: 96.2 | BG30: 96.8 | BH30: 97.4 | BI30: 98 | BJ30: 98.7 | BK30: 99.3 | BL30: 100 | BM30: 100 | BN30: 100 | BO30: 100 | BP30: 100
