Workbook

Sheet Data
A1: Data Source | B1: World Development Indicators
A2: Last Updated Date | B2: 45937
A4: Country Name | B4: Country Code | C4: Indicator Name | D4: Indicator Code | E4: 1960 | F4: 1961 | G4: 1962 | H4: 1963 | I4: 1964 | J4: 1965 | K4: 1966 | L4: 1967 | M4: 1968 | N4: 1969 | O4: 1970 | P4: 1971 | Q4: 1972 | R4: 1973 | S4: 1974 | T4: 1975 | U4: 1976 | V4: 1977 | W4: 1978 | X4: 1979 | Y4: 1980 | Z4: 1981 | AA4: 1982 | AB4: 1983 | AC4: 1984 | AD4: 1985 | AE4: 1986 | AF4: 1987 | AG4: 1988 | AH4: 1989 | AI4: 1990 | AJ4: 1991 | AK4: 1992 | AL4: 1993 | AM4: 1994 | AN4: 1995 | AO4: 1996 | AP4: 1997 | AQ4: 1998 | AR4: 1999 | AS4: 2000 | AT4: 2001 | AU4: 2002 | AV4: 2003 | AW4: 2004 | AX4: 2005 | AY4: 2006 | AZ4: 2007 | BA4: 2008 | BB4: 2009 | BC4: 2010 | BD4: 2011 | BE4: 2012 | BF4: 2013 | BG4: 2014 | BH4: 2015 | BI4: 2016 | BJ4: 2017 | BK4: 2018 | BL4: 2019 | BM4: 2020 | BN4: 2021 | BO4: 2022 | BP4: 2023 | BQ4: 2024
A5: Aruba | B5: ABW | C5: Gini index | D5: SI.POV.GINI
A6: Africa Eastern and Southern | B6: AFE | C6: Gini index | D6: SI.POV.GINI | BS6: =MIN(E5:BQ270) -> 20.2
A7: Afghanistan | B7: AFG | C7: Gini index | D7: SI.POV.GINI
A8: Africa Western and Central | B8: AFW | C8: Gini index | D8: SI.POV.GINI
A9: Angola | B9: AGO | C9: Gini index | D9: SI.POV.GINI | AS9: 51.9 | BA9: 42.7 | BH9: =BA9+((BK9-BA9)/(BK4-BA4))*(BH4-BA4) -> 48.72 | BK9: 51.3
A10: Albania | B10: ALB | C10: Gini index | D10: SI.POV.GINI | AO10: 27 | AU10: 31.7 | AX10: 30.6 | BA10: 30 | BE10: 29 | BG10: 34.6 | BH10: 32.8 | BI10: 33.7 | BJ10: 33.1 | BK10: 30.1 | BL10: 30.1 | BM10: 29.4
A11: Andorra | B11: AND | C11: Gini index | D11: SI.POV.GINI
A12: Arab World | B12: ARB | C12: Gini index | D12: SI.POV.GINI
A13: United Arab Emirates | B13: ARE | C13: Gini index | D13: SI.POV.GINI | BF13: 32.5 | BK13: 26.4
A14: Argentina | B14: ARG | C14: Gini index | D14: SI.POV.GINI | Y14: 40.8 | AE14: 42.8 | AF14: 45.3 | AJ14: 46.8 | AK14: 45.5 | AL14: 44.8 | AM14: 45.9 | AN14: 48.9 | AO14: 49.5 | AP14: 49.1 | AQ14: 50.7 | AR14: 49.8 | AS14: 51 | AT14: 53.3 | AU14: 53.8 | AV14: 51 | AW14: 48.5 | AX14: 47.8 | AY14: 46.4 | AZ14: 46.3 | BA14: 45 | BB14: 43.8 | BC14: 43.7 | BD14: 42.7 | BE14: 41.4 | BF14: 41.1 | BG14: 41.8 | BI14: 42.3 | BJ14: 41.4 | BK14: 41.7 | BL14: 43.3 | BM14: 42.7 | BN14: 42.4 | BO14: 40.7 | BP14: 42.4 | BQ14: 42.4
A15: Armenia | B15: ARM | C15: Gini index | D15: SI.POV.GINI | AO15: 44.4 | AR15: 36.2 | AT15: 35.4 | AU15: 34.8 | AV15: 33 | AW15: 37.5 | AX15: 36 | AY15: 29.7 | AZ15: 31.2 | BA15: 29.2 | BB15: 28 | BC15: 30 | BD15: 29.4 | BE15: 29.6 | BF15: 30.6 | BG15: 31.5 | BH15: 32.4 | BI15: 32.5 | BJ15: 33.6 | BK15: 34.4 | BL15: 30 | BM15: 25.1 | BN15: 27.9 | BO15: 27.9 | BP15: 27.2
A16: American Samoa | B16: ASM | C16: Gini index | D16: SI.POV.GINI
A17: Antigua and Barbuda | B17: ATG | C17: Gini index | D17: SI.POV.GINI
A18: Australia | B18: AUS | C18: Gini index | D18: SI.POV.GINI | Z18: 31.3 | AD18: 32.5 | AH18: 33.2 | AN18: 32.6 | AT18: 33.5 | AV18: 33.5 | AW18: 33.1 | BA18: 35.4 | BC18: 34.7 | BG18: 34.4 | BI18: 33.7 | BK18: 34.3 | BM18: 33.8
A19: Austria | B19: AUT | C19: Gini index | D19: SI.POV.GINI | AM19: 30.8 | AN19: 29.9 | AO19: 29.3 | AP19: 29.1 | AQ19: 31.3 | AR19: 29.7 | AS19: 29 | AV19: 29.5 | AW19: 29.8 | AX19: 28.7 | AY19: 29.6 | AZ19: 30.6 | BA19: 30.4 | BB19: 31.5 | BC19: 30.3 | BD19: 30.8 | BE19: 30.5 | BF19: 30.8 | BG19: 30.5 | BH19: 30.5 | BI19: 30.8 | BJ19: 29.7 | BK19: 30.8 | BL19: 30.2 | BM19: 29.8 | BN19: 30.7 | BO19: 30.9 | BP19: 31.2
A20: Azerbaijan | B20: AZE | C20: Gini index | D20: SI.POV.GINI | AN20: 34.6 | AT20: 36.5 | AU20: 25.3 | AV20: 26.8 | AW20: 26.6 | AX20: 26.6
A21: Burundi | B21: BDI | C21: Gini index | D21: SI.POV.GINI | AK21: 33.3 | AQ21: 42.1 | AY21: 33.4 | BF21: 38.6 | BM21: 37.5
A22: Belgium | B22: BEL | C22: Gini index | D22: SI.POV.GINI | AD22: 25.2 | AG22: 25.7 | AK22: 24.9 | AN22: 28.4 | AP22: 26.8 | AS22: 33.1 | AV22: 28.1 | AW22: 30.5 | AX22: 29.3 | AY22: 28.1 | AZ22: 29.2 | BA22: 28.4 | BB22: 28.6 | BC22: 28.4 | BD22: 28.1 | BE22: 27.5 | BF22: 27.7 | BG22: 28.1 | BH22: 27.7 | BI22: 27.6 | BJ22: 27.4 | BK22: 27.2 | BL22: 27.2 | BM22: 26 | BN22: 26.6 | BO22: 26.4 | BP22: 26.8 | BS22: =[1]Data!$F$12 -> 46445.406
A23: Benin | B23: BEN | C23: Gini index | D23: SI.POV.GINI | AV23: 38.6 | BD23: 43.4 | BH23: 47.6 | BK23: 37.9 | BN23: 34.4
A24: Burkina Faso | B24: BFA | C24: Gini index | D24: SI.POV.GINI | AM24: 48 | AQ24: 49.9 | AV24: 43.3 | BB24: 39.8 | BG24: 35.3 | BK24: 43 | BN24: 37.4
A25: Bangladesh | B25: BGD | C25: Gini index | D25: SI.POV.GINI | AB25: 25.9 | AD25: 26.9 | AG25: 28.8 | AJ25: 27.6 | AN25: 32.9 | AS25: 33.4 | AX25: 33.2 | BC25: 32.1 | BI25: 32.4 | BO25: 30.9
A26: Bulgaria | B26: BGR | C26: Gini index | D26: SI.POV.GINI | AH26: 23.4 | AK26: 30.7 | AM26: 24.3 | AN26: 32.8 | AP26: 26.4 | AT26: 32.7 | AV26: 28.9 | AY26: 35.7 | AZ26: 36.1 | BA26: 33.6 | BB26: 33.8 | BC26: 35.7 | BD26: 34.3 | BE26: 36 | BF26: 36.6 | BG26: 37.4 | BH26: 38.6 | BI26: 40.6 | BJ26: 40.4 | BK26: 41.3 | BL26: 40.3 | BM26: 40.5 | BN26: 39 | BO26: 38.2 | BP26: 39.5
A27: Bahrain | B27: BHR | C27: Gini index | D27: SI.POV.GINI
A28: Bahamas, The | B28: BHS | C28: Gini index | D28: SI.POV.GINI
A29: Bosnia and Herzegovina | B29: BIH | C29: Gini index | D29: SI.POV.GINI | AT29: 30 | AW29: 34 | AZ29: 33.1 | BD29: 33
A30: Belarus | B30: BLR | C30: Gini index | D30: SI.POV.GINI | AL30: 21.6 | AN30: 28.7 | AQ30: 32 | AR30: 31.7 | AS30: 31.2 | AT30: 30.6 | AU30: 30.3 | AV30: 28.8 | AW30: 26.5 | AX30: 27.6 | AY30: 28.3 | AZ30: 29.6 | BA30: 27.8 | BB30: 27.7 | BC30: 28.6 | BD30: 27.2 | BE30: 26.5 | BF30: 26.6 | BG30: 27.2 | BH30: 25.6 | BI30: 25.3 | BJ30: 25.4 | BK30: 25.2 | BL30: 25.3 | BM30: 24.4 | BS30: =[1]Data!$F$11 -> 17917.185
A31: Belize | B31: BLZ | C31: Gini index | D31: SI.POV.GINI | AL31: 60.2 | AM31: 60.9 | AN31: 57.5 | AO31: 56.6 | AP31: 60.4 | AQ31: 54.9 | AR31: 53.2 | BK31: 39.9
A32: Bermuda | B32: BMU | C32: Gini index | D32: SI.POV.GINI
A33: Bolivia | B33: BOL | C33: Gini index | D33: SI.POV.GINI | AI33: 42 | AK33: 49.1 | AP33: 58.1 | AR33: 58 | AS33: 61.6 | AT33: 57.4 | AU33: 59.3 | AW33: 55 | AX33: 58.5 | AY33: 56.7 | AZ33: 54.5 | BA33: 50.8 | BB33: 49.2 | BD33: 46.1 | BE33: 46.6 | BF33: 47.6 | BG33: 47.8 | BH33: 46.7 | BI33: 45.2 | BJ33: 44.6 | BK33: 42.6 | BL33: 41.6 | BM33: 43.6 | BN33: 40.9 | BO33: 41.2 | BP33: 42.1
A34: Brazil | B34: BRA | C34: Gini index | D34: SI.POV.GINI | Z34: 57.9 | AA34: 58.4 | AB34: 58.9 | AC34: 58.3 | AD34: 55.5 | AE34: 58.4 | AF34: 59.6 | AG34: 61.4 | AH34: 63.2 | AI34: 60.5 | AK34: 53.1 | AL34: 60.1 | AN34: 59.5 | AO34: 59.8 | AP34: 59.8 | AQ34: 59.6 | AR34: 59 | AT34: 58.4 | AU34: 58.1 | AV34: 57.6 | AW34: 56.5 | AX34: 56.3 | AY34: 55.6 | AZ34: 54.9 | BA34: 54 | BB34: 53.7 | BD34: 52.9 | BE34: 53.4 | BF34: 52.7 | BG34: 52 | BH34: 51.9 | BI34: 53.4 | BJ34: 53.3 | BK34: 53.9 | BL34: 53.5 | BM34: 48.9 | BN34: 52.9 | BO34: 52 | BP34: 51.6
A35: Barbados | B35: BRB | C35: Gini index | D35: SI.POV.GINI | BI35: 34.1
A36: Brunei Darussalam | B36: BRN | C36: Gini index | D36: SI.POV.GINI
A37: Bhutan | B37: BTN | C37: Gini index | D37: SI.POV.GINI | AV37: 40.9 | AZ37: 38.1 | BE37: 38.8 | BJ37: 37.4 | BO37: 28.5
A38: Botswana | B38: BWA | C38: Gini index | D38: SI.POV.GINI | AD38: 54.2 | AL38: 60.1 | AU38: 61.5 | BB38: 56.9 | BH38: 54.9
A39: Central African Republic | B39: CAF | C39: Gini index | D39: SI.POV.GINI | AK39: 59.7 | BA39: 56.2 | BN39: 43
A40: Canada | B40: CAN | C40: Gini index | D40: SI.POV.GINI | P40: 37.2 | R40: 34.9 | T40: 34.1 | V40: 33.7 | X40: 33.5 | Z40: 33 | AA40: 32.9 | AC40: 33.5 | AD40: 33.2 | AE40: 31.7 | AF40: 31.7 | AG40: 31.2 | AH40: 31 | AI40: 31.4 | AJ40: 31.9 | AK40: 31.6 | AL40: 31.7 | AM40: 31.3 | AN40: 31.5 | AO40: 32.8 | AP40: 33.1 | AQ40: 33.2 | AR40: 33.1 | AS40: 33.4 | AT40: 33.6 | AU40: 33.6 | AV40: 33.8 | AW40: 33.8 | AX40: 33.6 | AY40: 34.1 | AZ40: 33.8 | BA40: 33.9 | BB40: 34 | BC40: 33.6 | BD40: 32.7 | BE40: 33.5 | BF40: 33.8 | BG40: 33.2 | BH40: 33.7 | BI40: 32.7 | BJ40: 33.3 | BK40: 32.5 | BL40: 31.7 | BM40: 29.9 | BN40: 31.1
A41: Central Europe and the Baltics | B41: CEB | C41: Gini index | D41: SI.POV.GINI
...

Sheet Gini_2015
A1: Country Name | B1: Country Code | C1: Gini_2015
A2: Aruba | B2: ABW | C2: =VLOOKUP(A2,Data!$A$5:$BH$270,60,0)/100 -> 0
A3: Africa Eastern and Southern | B3: AFE | C3: =VLOOKUP(A3,Data!$A$5:$BH$270,60,0)/100 -> 0
A4: Afghanistan | B4: AFG | C4: =VLOOKUP(A4,Data!$A$5:$BH$270,60,0)/100 -> 0
A5: Africa Western and Central | B5: AFW | C5: =VLOOKUP(A5,Data!$A$5:$BH$270,60,0)/100 -> 0
A6: Angola | B6: AGO | C6: =VLOOKUP(A6,Data!$A$5:$BH$270,60,0)/100 -> 0.4872
A7: Albania | B7: ALB | C7: =VLOOKUP(A7,Data!$A$5:$BH$270,60,0)/100 -> 0.328
A8: Andorra | B8: AND | C8: =VLOOKUP(A8,Data!$A$5:$BH$270,60,0)/100 -> 0
A9: Arab World | B9: ARB | C9: =VLOOKUP(A9,Data!$A$5:$BH$270,60,0)/100 -> 0
A10: United Arab Emirates | B10: ARE | C10: =VLOOKUP(A10,Data!$A$5:$BH$270,60,0)/100 -> 0
A11: Argentina | B11: ARG | C11: =VLOOKUP(A11,Data!$A$5:$BH$270,60,0)/100 -> 0
A12: Armenia | B12: ARM | C12: =VLOOKUP(A12,Data!$A$5:$BH$270,60,0)/100 -> 0.324
A13: American Samoa | B13: ASM | C13: =VLOOKUP(A13,Data!$A$5:$BH$270,60,0)/100 -> 0
... A267: Zimbabwe | B267: ZWE | C267: =VLOOKUP(A267,Data!$A$5:$BH$270,60,0)/100 -> 0.43933333

Sheet Metadata - Countries
A1: Country Code | B1: Region | C1: IncomeGroup | D1: SpecialNotes | E1: TableName
A2: ABW | B2: Latin America & Caribbean | C2: High income | E2: Aruba
A3: AFE | D3: 26 countries, stretching from the Red Sea in the North to the Cape of Good Hope in the South (https://www.worldbank.org/en/region/afr/eastern-and-southern-africa) | E3: Africa Eastern and Southern
A4: AFG | B4: Middle East & North Africa | C4: Low income | D4: The reporting period for national accounts data is designated as either calendar year basis (CY) or fiscal year basis (FY). For this country, it is fiscal year-based (fiscal year-end: March 20). Also, an estimate (PA.NUS.ATLS) of the exchange rate covers the same period and thus differs from the official exchange rate (CY). In addition, the World Bank systematically assesses the appropriateness of official exchange rates as conversion factors. In this country, multiple or dual exchange rate activity exists and must be accounted for appropriately in underlying statistics. An alternative estimate (“alternative conversion factor” - PA.NUS.ATLS) is thus calculated as a weighted average of the different exchange rates in use in the country. Doing so better reflects economic reality and leads to more accurate cross-country comparisons and country classifications by income level. For this country, this applies to the period 1960-2006. Alternative conversion factors are used in the Atlas methodology and elsewhere in World Development Indicators as single-year conversion factors. | E4: Afghanistan
A5: AFW | D5: 22 countries, stretching from the westernmost point of Africa, across the equator, and partly along the Atlantic Ocean till the Republic of Congo in the South (https://www.worldbank.org/en/region/afr/western-and-central-africa) | E5: Africa Western and Central
A6: AGO | B6: Sub-Saharan Africa | C6: Lower middle income | D6: The World Bank systematically assesses the appropriateness of official exchange rates as conversion factors. In this country, multiple or dual exchange rate activity exists and must be accounted for appropriately in underlying statistics. An alternative estimate (“alternative conversion factor” - PA.NUS.ATLS) is thus calculated as a weighted average of the different exchange rates in use in the country. Doing so better reflects economic reality and leads to more accurate cross-country comparisons and country classifications by income level. For this country, this applies to the period 1994-2024. Alternative conversion factors are used in the Atlas methodology and elsewhere in World Development Indicators as single-year conversion factors. | E6: Angola
A7: ALB | B7: Europe & Central Asia | C7: Upper middle income | E7: Albania
A8: AND | B8: Europe & Central Asia | C8: High income | E8: Andorra
A9: ARB | D9: Arab World aggregate. Arab World is composed of members of the League of Arab States. | E9: Arab World
A10: ARE | B10: Middle East & North Africa | C10: High income | E10: United Arab Emirates
A11: ARG | B11: Latin America & Caribbean | C11: Upper middle income | D11: The World Bank systematically assesses the appropriateness of official exchange rates as conversion factors. In this country, multiple or dual exchange rate activity exists and must be accounted for appropriately in underlying statistics. An alternative estimate (“alternative conversion factor” - PA.NUS.ATLS) is thus calculated as a weighted average of the different exchange rates in use in the country. Doing so better reflects economic reality and leads to more accurate cross-country comparisons and country classifications by income level. For this country, this applies to the period 1971-2018. Alternative conversion factors are used in the Atlas methodology and elsewhere in World Development Indicators as single-year conversion factors. | E11: Argentina
A12: ARM | B12: Europe & Central Asia | C12: Upper middle income | E12: Armenia
A13: ASM | B13: East Asia & Pacific | C13: High income | E13: American Samoa
A14: ATG | B14: Latin America & Caribbean | C14: High income | E14: Antigua and Barbuda
A15: AUS | B15: East Asia & Pacific | C15: High income | D15: The reporting period for national accounts data is designated as either calendar year basis (CY) or fiscal year basis (FY). For this country, it is fiscal year-based (fiscal year-end: June 30). Also, an estimate (PA.NUS.ATLS) of the exchange rate covers the same period and thus differs from the official exchange rate (CY). | E15: Australia
A16: AUT | B16: Europe & Central Asia | C16: High income | D16: A simple multiplier is used to convert the national currencies of EMU members to euros. The following irrevocable euro conversion rate was adopted by the EU Council on January 1, 1999: 1 euro = 13.7603 Austrian schilling. Please note that historical data before 1999 are not actual euros and are not comparable or suitable for aggregation across countries. | E16: Austria
A17: AZE | B17: Europe & Central Asia | C17: Upper middle income | E17: Azerbaijan
A18: BDI | B18: Sub-Saharan Africa | C18: Low income | D18: The World Bank systematically assesses the appropriateness of official exchange rates as conversion factors. In this country, multiple or dual exchange rate activity exists and must be accounted for appropriately in underlying statistics. An alternative estimate (“alternative conversion factor” - PA.NUS.ATLS) is thus calculated as a weighted average of the different exchange rates in use in the country. Doing so better reflects economic reality and leads to more accurate cross-country comparisons and country classifications by income level. For this country, this applies to the period 1983-2024. Alternative conversion factors are used in the Atlas methodology and elsewhere in World Development Indicators as single-year conversion factors. | E18: Burundi
A19: BEL | B19: Europe & Central Asia | C19: High income | D19: A simple multiplier is used to convert the national currencies of EMU members to euros. The following irrevocable euro conversion rate was adopted by the EU Council on January 1, 1999: 1 euro = 40.3399 Belgian franc. Please note that historical data before 1999 are not actual euros and are not comparable or suitable for aggregation across countries. | E19: Belgium
A20: BEN | B20: Sub-Saharan Africa | C20: Lower middle income | E20: Benin
A21: BFA | B21: Sub-Saharan Africa | C21: Low income | E21: Burkina Faso
A22: BGD | B22: South Asia | C22: Lower middle income | D22: The reporting period for national accounts data is designated as either calendar year basis (CY) or fiscal year basis (FY). For this country, it is fiscal year-based (fiscal year-end: June 30). Also, an estimate (PA.NUS.ATLS) of the exchange rate covers the same period and thus differs from the official exchange rate (CY). | E22: Bangladesh
A23: BGR | B23: Europe & Central Asia | C23: High income | E23: Bulgaria
A24: BHR | B24: Middle East & North Africa | C24: High income | E24: Bahrain
A25: BHS | B25: Latin America & Caribbean | C25: High income | E25: Bahamas, The
A26: BIH | B26: Europe & Central Asia | C26: Upper middle income | E26: Bosnia and Herzegovina
A27: BLR | B27: Europe & Central Asia | C27: Upper middle income | D27: Data before 2015 were adjusted to reflect the new denomination effective from July 1, 2016 (BYN), a decrease of 10,000 times (1 BYN = 10,000 BYR) | E27: Belarus
A28: BLZ | B28: Latin America & Caribbean | C28: Upper middle income | E28: Belize
A29: BMU | B29: North America | C29: High income | E29: Bermuda
A30: BOL | B30: Latin America & Caribbean | C30: Lower middle income | E30: Bolivia
A31: BRA | B31: Latin America & Caribbean | C31: Upper middle income | E31: Brazil
A32: BRB | B32: Latin America & Caribbean | C32: High income | E32: Barbados
A33: BRN | B33: East Asia & Pacific | C33: High income | E33: Brunei Darussalam
A34: BTN | B34: South Asia | C34: Lower middle income | E34: Bhutan
A35: BWA | B35: Sub-Saharan Africa | C35: Upper middle income | E35: Botswana
A36: CAF | B36: Sub-Saharan Africa | C36: Low income | E36: Central African Republic
A37: CAN | B37: North America | C37: High income | D37: Fiscal year end: March 31; reporting period for national accounts data: CY. | E37: Canada
A38: CEB | D38: Central Europe and the Baltics aggregate. | E38: Central Europe and the Baltics
A39: CHE | B39: Europe & Central Asia | C39: High income | E39: Switzerland
A40: CHI | B40: Europe & Central Asia | C40: High income | E40: Channel Islands
...

Sheet Metadata - Indicators
A1: INDICATOR_CODE | B1: INDICATOR_NAME | C1: SOURCE_NOTE | D1: SOURCE_ORGANIZATION
A2: SI.POV.GINI | B2: Gini index | C2: Gini index measures the extent to which the distribution of income (or, in some cases, consumption expenditure) among individuals or households within an economy deviates from a perfectly equal distribution. A Lorenz curve plots the cumulative percentages of total income received against the cumulative number of recipients, starting with the poorest individual or household. The Gini index measures the area between the Lorenz curve and a hypothetical line of absolute equality, expressed as a percentage of the maximum area under the line. Thus a Gini index of 0 represents perfect equality, while an index of 100 implies perfect inequality. | D2: World Bank, Poverty and Inequality Platform. Data are based on primary household survey data obtained from government statistical agencies and World Bank country departments. Data for high-income economies are mostly from the Luxembourg Income Study database. For more information and methodology, please see http://pip.worldbank.org., World Bank (WB), uri: http://pip.worldbank.org, note: Data are based on primary household survey data obtained from government statistical agencies and World Bank country departments. Data for high-income economies are mostly from the Luxembourg Income Study database.
