Workbook

Sheet lowest_10
A1: Data Source | B1: World Development Indicators
A2: Last Updated Date | B2: 46007
A4: Country Name | B4: Country Code | C4: Indicator Name | D4: Indicator Code | E4: 1960 | F4: 1961 | G4: 1962 | H4: 1963 | I4: 1964 | J4: 1965 | K4: 1966 | L4: 1967 | M4: 1968 | N4: 1969 | O4: 1970 | P4: 1971 | Q4: 1972 | R4: 1973 | S4: 1974 | T4: 1975 | U4: 1976 | V4: 1977 | W4: 1978 | X4: 1979 | Y4: 1980 | Z4: 1981 | AA4: 1982 | AB4: 1983 | AC4: 1984 | AD4: 1985 | AE4: 1986 | AF4: 1987 | AG4: 1988 | AH4: 1989 | AI4: 1990 | AJ4: 1991 | AK4: 1992 | AL4: 1993 | AM4: 1994 | AN4: 1995 | AO4: 1996 | AP4: 1997 | AQ4: 1998 | AR4: 1999 | AS4: 2000 | AT4: 2001 | AU4: 2002 | AV4: 2003 | AW4: 2004 | AX4: 2005 | AY4: 2006 | AZ4: 2007 | BA4: 2008 | BB4: 2009 | BC4: 2010 | BD4: 2011 | BE4: 2012 | BF4: 2013 | BG4: 2014 | BH4: 2015 | BI4: 2016 | BJ4: 2017 | BK4: 2018 | BL4: 2019 | BM4: 2020 | BN4: 2021 | BO4: 2022 | BP4: 2023 | BQ4: 2024
A5: Aruba | B5: ABW | C5: Income share held by lowest 10% | D5: SI.DST.FRST.10
A6: Africa Eastern and Southern | B6: AFE | C6: Income share held by lowest 10% | D6: SI.DST.FRST.10
A7: Afghanistan | B7: AFG | C7: Income share held by lowest 10% | D7: SI.DST.FRST.10
A8: Africa Western and Central | B8: AFW | C8: Income share held by lowest 10% | D8: SI.DST.FRST.10
A9: Angola | B9: AGO | C9: Income share held by lowest 10% | D9: SI.DST.FRST.10 | AS9: 1 | BA9: 2.1 | BK9: 1.3
A10: Albania | B10: ALB | C10: Income share held by lowest 10% | D10: SI.DST.FRST.10 | AO10: 3.9 | AU10: 3.5 | AX10: 3.5 | BA10: 3.7 | BE10: 3.7 | BG10: 2.9 | BH10: 3.2 | BI10: 3 | BJ10: 3.1 | BK10: 3.2 | BL10: 3.5 | BM10: 3.4
A11: Andorra | B11: AND | C11: Income share held by lowest 10% | D11: SI.DST.FRST.10
A12: Arab World | B12: ARB | C12: Income share held by lowest 10% | D12: SI.DST.FRST.10
A13: United Arab Emirates | B13: ARE | C13: Income share held by lowest 10% | D13: SI.DST.FRST.10 | BF13: 2.3 | BK13: 2.8
A14: Argentina | B14: ARG | C14: Income share held by lowest 10% | D14: SI.DST.FRST.10 | Y14: 2 | AE14: 1.8 | AF14: 1.6 | AJ14: 1.8 | AK14: 1.6 | AL14: 1.5 | AM14: 1.5 | AN14: 1.2 | AO14: 1.1 | AP14: 1.1 | AQ14: 1.1 | AR14: 1.1 | AS14: 1 | AT14: 0.7 | AU14: 0.9 | AV14: 1.1 | AW14: 1.2 | AX14: 1.3 | AY14: 1.3 | AZ14: 1.4 | BA14: 1.4 | BB14: 1.4 | BC14: 1.6 | BD14: 1.7 | BE14: 1.7 | BF14: 1.8 | BG14: 1.8 | BI14: 1.7 | BJ14: 1.8 | BK14: 1.7 | BL14: 1.6 | BM14: 1.7 | BN14: 1.8 | BO14: 2 | BP14: 1.9 | BQ14: 1.9
A15: Armenia | B15: ARM | C15: Income share held by lowest 10% | D15: SI.DST.FRST.10 | AO15: 2.3 | AR15: 3 | AT15: 3.2 | AU15: 3.3 | AV15: 3.7 | AW15: 3.1 | AX15: 3.3 | AY15: 3.7 | AZ15: 3.5 | BA15: 3.9 | BB15: 4 | BC15: 3.9 | BD15: 3.8 | BE15: 3.8 | BF15: 3.6 | BG15: 3.5 | BH15: 3.4 | BI15: 3.3 | BJ15: 3.5 | BK15: 3.3 | BL15: 3.7 | BM15: 4.4 | BN15: 4 | BO15: 3.9 | BP15: 4
A16: American Samoa | B16: ASM | C16: Income share held by lowest 10% | D16: SI.DST.FRST.10
A17: Antigua and Barbuda | B17: ATG | C17: Income share held by lowest 10% | D17: SI.DST.FRST.10
A18: Australia | B18: AUS | C18: Income share held by lowest 10% | D18: SI.DST.FRST.10 | Z18: 2.9 | AD18: 2.7 | AH18: 2.7 | AN18: 2.9 | AT18: 2.8 | AV18: 2.8 | AW18: 3.1 | BA18: 2.8 | BC18: 2.8 | BG18: 2.9 | BI18: 2.9 | BK18: 2.8 | BM18: 2.7
A19: Austria | B19: AUT | C19: Income share held by lowest 10% | D19: SI.DST.FRST.10 | AM19: 3.1 | AN19: 3.3 | AO19: 3.5 | AP19: 3.4 | AQ19: 3.3 | AR19: 3.6 | AS19: 3.5 | AV19: 3.3 | AW19: 3.4 | AX19: 3.5 | AY19: 3.4 | AZ19: 3.1 | BA19: 3 | BB19: 2.8 | BC19: 3.1 | BD19: 2.9 | BE19: 2.8 | BF19: 3.1 | BG19: 3.1 | BH19: 3 | BI19: 2.8 | BJ19: 3 | BK19: 3 | BL19: 2.9 | BM19: 2.9 | BN19: 2.8 | BO19: 2.8 | BP19: 2.8
A20: Azerbaijan | B20: AZE | C20: Income share held by lowest 10% | D20: SI.DST.FRST.10 | AN20: 2.7 | AT20: 3.1 | AU20: 4.8 | AV20: 4.5 | AW20: 4.8 | AX20: 4.8
A21: Burundi | B21: BDI | C21: Income share held by lowest 10% | D21: SI.DST.FRST.10 | AK21: 3.4 | AQ21: 1.9 | AY21: 4 | BF21: 2.8 | BM21: 2.9
A22: Belgium | B22: BEL | C22: Income share held by lowest 10% | D22: SI.DST.FRST.10 | AD22: 4.2 | AG22: 4 | AK22: 3.9 | AN22: 3.4 | AP22: 3.6 | AS22: 3.4 | AV22: 3.3 | AW22: 3.4 | AX22: 3.4 | AY22: 3.4 | AZ22: 3.4 | BA22: 3.4 | BB22: 3.2 | BC22: 3.3 | BD22: 3.3 | BE22: 3.4 | BF22: 3.3 | BG22: 3.4 | BH22: 3.4 | BI22: 3.4 | BJ22: 3.4 | BK22: 3.5 | BL22: 3.6 | BM22: 3.7 | BN22: 3.6 | BO22: 3.8 | BP22: 3.7
A23: Benin | B23: BEN | C23: Income share held by lowest 10% | D23: SI.DST.FRST.10 | AV23: 2.9 | BD23: 2.5 | BH23: 1.1 | BK23: 2.9 | BN23: 3.1
A24: Burkina Faso | B24: BFA | C24: Income share held by lowest 10% | D24: SI.DST.FRST.10 | AM24: 2.3 | AQ24: 2 | AV24: 2.3 | BB24: 2.7 | BG24: 3.6 | BK24: 2.6 | BN24: 3
A25: Bangladesh | B25: BGD | C25: Income share held by lowest 10% | D25: SI.DST.FRST.10 | AB25: 4.1 | AD25: 4.5 | AG25: 4.2 | AJ25: 4.1 | AN25: 3.8 | AS25: 3.7 | AX25: 3.8 | BC25: 3.9 | BI25: 3.7 | BO25: 3.7
A26: Bulgaria | B26: BGR | C26: Income share held by lowest 10% | D26: SI.DST.FRST.10 | AH26: 4.6 | AK26: 3.5 | AM26: 4.4 | AN26: 3 | AP26: 4.5 | AT26: 2.6 | AV26: 3.4 | AY26: 1.6 | AZ26: 2.2 | BA26: 2.4 | BB26: 2.4 | BC26: 2.1 | BD26: 2.1 | BE26: 2 | BF26: 1.8 | BG26: 2 | BH26: 1.5 | BI26: 1.6 | BJ26: 1.9 | BK26: 1.9 | BL26: 1.9 | BM26: 2.2 | BN26: 2 | BO26: 2.1 | BP26: 2.1
A27: Bahrain | B27: BHR | C27: Income share held by lowest 10% | D27: SI.DST.FRST.10
A28: Bahamas, The | B28: BHS | C28: Income share held by lowest 10% | D28: SI.DST.FRST.10
A29: Bosnia and Herzegovina | B29: BIH | C29: Income share held by lowest 10% | D29: SI.DST.FRST.10 | AT29: 3.6 | AW29: 2.9 | AZ29: 3 | BD29: 2.9
A30: Belarus | B30: BLR | C30: Income share held by lowest 10% | D30: SI.DST.FRST.10 | AL30: 4.9 | AN30: 3.5 | AQ30: 3.1 | AR30: 3 | AS30: 3.1 | AT30: 3.3 | AU30: 3.3 | AV30: 3.5 | AW30: 3.8 | AX30: 3.6 | AY30: 3.6 | AZ30: 3.5 | BA30: 3.7 | BB30: 3.7 | BC30: 3.6 | BD30: 3.8 | BE30: 4 | BF30: 4 | BG30: 3.9 | BH30: 4.1 | BI30: 4.2 | BJ30: 4.3 | BK30: 4.3 | BL30: 4.2 | BM30: 4.5
A31: Belize | B31: BLZ | C31: Income share held by lowest 10% | D31: SI.DST.FRST.10 | AL31: 0.9 | AM31: 1 | AN31: 0.8 | AO31: 1 | AP31: 0.7 | AQ31: 1.1 | AR31: 0.9 | BK31: 2.2
A32: Bermuda | B32: BMU | C32: Income share held by lowest 10% | D32: SI.DST.FRST.10
A33: Bolivia | B33: BOL | C33: Income share held by lowest 10% | D33: SI.DST.FRST.10 | AI33: 2.3 | AK33: 1.7 | AP33: 0.5 | AR33: 0.3 | AS33: 0.3 | AT33: 0.5 | AU33: 0.4 | AW33: 0.9 | AX33: 0.5 | AY33: 0.6 | AZ33: 0.8 | BA33: 0.9 | BB33: 0.8 | BD33: 1.1 | BE33: 0.9 | BF33: 1 | BG33: 1.1 | BH33: 1.1 | BI33: 1 | BJ33: 1.1 | BK33: 1.4 | BL33: 1.7 | BM33: 1.5 | BN33: 1.8 | BO33: 1.7 | BP33: 1.8
A34: Brazil | B34: BRA | C34: Income share held by lowest 10% | D34: SI.DST.FRST.10 | Z34: 0.9 | AA34: 0.9 | AB34: 0.9 | AC34: 0.9 | AD34: 1 | AE34: 0.9 | AF34: 0.8 | AG34: 0.7 | AH34: 0.6 | AI34: 0.8 | AK34: 0.9 | AL34: 0.7 | AN34: 0.8 | AO34: 0.7 | AP34: 0.7 | AQ34: 0.8 | AR34: 0.8 | AT34: 0.8 | AU34: 0.9 | AV34: 0.9 | AW34: 0.9 | AX34: 1 | AY34: 1 | AZ34: 1 | BA34: 1 | BB34: 1 | BD34: 1.1 | BE34: 1.1 | BF34: 1.2 | BG34: 1.2 | BH34: 1.2 | BI34: 1.1 | BJ34: 1 | BK34: 1 | BL34: 0.9 | BM34: 1.6 | BN34: 1 | BO34: 1.2 | BP34: 1.3
A35: Barbados | B35: BRB | C35: Income share held by lowest 10% | D35: SI.DST.FRST.10 | BI35: 2.5
A36: Brunei Darussalam | B36: BRN | C36: Income share held by lowest 10% | D36: SI.DST.FRST.10
A37: Bhutan | B37: BTN | C37: Income share held by lowest 10% | D37: SI.DST.FRST.10 | AV37: 2.8 | AZ37: 2.7 | BE37: 2.7 | BJ37: 2.7 | BO37: 3.6
A38: Botswana | B38: BWA | C38: Income share held by lowest 10% | D38: SI.DST.FRST.10 | AD38: 1.4 | AL38: 1.2 | AU38: 1 | BB38: 1.2 | BH38: 1.4
A39: Central African Republic | B39: CAF | C39: Income share held by lowest 10% | D39: SI.DST.FRST.10 | AK39: 1.5 | BA39: 1.2 | BN39: 2.1
A40: Canada | B40: CAN | C40: Income share held by lowest 10% | D40: SI.DST.FRST.10 | P40: 1.8 | R40: 2.1 | T40: 2.3 | V40: 2.3 | X40: 2.3 | Z40: 2.5 | AA40: 2.6 | AC40: 2.4 | AD40: 2.6 | AE40: 2.7 | AF40: 2.8 | AG40: 2.9 | AH40: 2.8 | AI40: 2.6 | AJ40: 2.6 | AK40: 2.8 | AL40: 2.7 | AM40: 2.8 | AN40: 2.8 | AO40: 2.9 | AP40: 2.9 | AQ40: 2.8 | AR40: 2.8 | AS40: 2.8 | AT40: 2.8 | AU40: 2.7 | AV40: 2.7 | AW40: 2.7 | AX40: 2.7 | AY40: 2.8 | AZ40: 2.8 | BA40: 2.7 | BB40: 2.7 | BC40: 2.8 | BD40: 2.9 | BE40: 2.6 | BF40: 2.5 | BG40: 2.7 | BH40: 2.6 | BI40: 2.9 | BJ40: 2.8 | BK40: 2.9 | BL40: 3 | BM40: 3.5 | BN40: 3.3
A41: Central Europe and the Baltics | B41: CEB | C41: Income share held by lowest 10% | D41: SI.DST.FRST.10
...

Sheet lowest_20
A1: Data Source | B1: World Development Indicators
A2: Last Updated Date | B2: 46007
A4: Country Name | B4: Country Code | C4: Indicator Name | D4: Indicator Code | E4: 1960 | F4: 1961 | G4: 1962 | H4: 1963 | I4: 1964 | J4: 1965 | K4: 1966 | L4: 1967 | M4: 1968 | N4: 1969 | O4: 1970 | P4: 1971 | Q4: 1972 | R4: 1973 | S4: 1974 | T4: 1975 | U4: 1976 | V4: 1977 | W4: 1978 | X4: 1979 | Y4: 1980 | Z4: 1981 | AA4: 1982 | AB4: 1983 | AC4: 1984 | AD4: 1985 | AE4: 1986 | AF4: 1987 | AG4: 1988 | AH4: 1989 | AI4: 1990 | AJ4: 1991 | AK4: 1992 | AL4: 1993 | AM4: 1994 | AN4: 1995 | AO4: 1996 | AP4: 1997 | AQ4: 1998 | AR4: 1999 | AS4: 2000 | AT4: 2001 | AU4: 2002 | AV4: 2003 | AW4: 2004 | AX4: 2005 | AY4: 2006 | AZ4: 2007 | BA4: 2008 | BB4: 2009 | BC4: 2010 | BD4: 2011 | BE4: 2012 | BF4: 2013 | BG4: 2014 | BH4: 2015 | BI4: 2016 | BJ4: 2017 | BK4: 2018 | BL4: 2019 | BM4: 2020 | BN4: 2021 | BO4: 2022 | BP4: 2023 | BQ4: 2024
A5: Aruba | B5: ABW | C5: Income share held by lowest 20% | D5: SI.DST.FRST.20
A6: Africa Eastern and Southern | B6: AFE | C6: Income share held by lowest 20% | D6: SI.DST.FRST.20
A7: Afghanistan | B7: AFG | C7: Income share held by lowest 20% | D7: SI.DST.FRST.20
A8: Africa Western and Central | B8: AFW | C8: Income share held by lowest 20% | D8: SI.DST.FRST.20
A9: Angola | B9: AGO | C9: Income share held by lowest 20% | D9: SI.DST.FRST.20 | AS9: 3.2 | BA9: 5.4 | BK9: 3.8
A10: Albania | B10: ALB | C10: Income share held by lowest 20% | D10: SI.DST.FRST.20 | AO10: 9.2 | AU10: 8.4 | AX10: 8.4 | BA10: 8.9 | BE10: 8.9 | BG10: 7 | BH10: 7.7 | BI10: 7.3 | BJ10: 7.6 | BK10: 7.9 | BL10: 8.5 | BM10: 8.4
A11: Andorra | B11: AND | C11: Income share held by lowest 20% | D11: SI.DST.FRST.20
A12: Arab World | B12: ARB | C12: Income share held by lowest 20% | D12: SI.DST.FRST.20
A13: United Arab Emirates | B13: ARE | C13: Income share held by lowest 20% | D13: SI.DST.FRST.20 | BF13: 6.2 | BK13: 8.2
A14: Argentina | B14: ARG | C14: Income share held by lowest 20% | D14: SI.DST.FRST.20 | Y14: 5.3 | AE14: 5.1 | AF14: 4.6 | AJ14: 4.8 | AK14: 4.6 | AL14: 4.5 | AM14: 4.4 | AN14: 3.8 | AO14: 3.5 | AP14: 3.6 | AQ14: 3.4 | AR14: 3.5 | AS14: 3.2 | AT14: 2.6 | AU14: 2.8 | AV14: 3.3 | AW14: 3.6 | AX14: 3.7 | AY14: 3.9 | AZ14: 4.1 | BA14: 4.2 | BB14: 4.3 | BC14: 4.5 | BD14: 4.8 | BE14: 5 | BF14: 5 | BG14: 5 | BI14: 4.9 | BJ14: 5 | BK14: 4.9 | BL14: 4.6 | BM14: 4.7 | BN14: 5 | BO14: 5.4 | BP14: 5.1 | BQ14: 5.1
A15: Armenia | B15: ARM | C15: Income share held by lowest 20% | D15: SI.DST.FRST.20 | AO15: 5.5 | AR15: 7.6 | AT15: 7.7 | AU15: 8 | AV15: 8.7 | AW15: 7.6 | AX15: 8.1 | AY15: 8.9 | AZ15: 8.4 | BA15: 9.1 | BB15: 9.4 | BC15: 9.1 | BD15: 9 | BE15: 9 | BF15: 8.6 | BG15: 8.5 | BH15: 8.2 | BI15: 7.9 | BJ15: 8.4 | BK15: 8.1 | BL15: 8.9 | BM15: 10.2 | BN15: 9.4 | BO15: 9.2 | BP15: 9.5
A16: American Samoa | B16: ASM | C16: Income share held by lowest 20% | D16: SI.DST.FRST.20
A17: Antigua and Barbuda | B17: ATG | C17: Income share held by lowest 20% | D17: SI.DST.FRST.20
A18: Australia | B18: AUS | C18: Income share held by lowest 20% | D18: SI.DST.FRST.20 | Z18: 7.8 | AD18: 7.5 | AH18: 7.4 | AN18: 7.7 | AT18: 7.5 | AV18: 7.5 | AW18: 7.8 | BA18: 7.2 | BC18: 7.3 | BG18: 7.6 | BI18: 7.5 | BK18: 7.4 | BM18: 7.3
A19: Austria | B19: AUT | C19: Income share held by lowest 20% | D19: SI.DST.FRST.20 | AM19: 8.2 | AN19: 8.3 | AO19: 8.6 | AP19: 8.6 | AQ19: 8.3 | AR19: 8.8 | AS19: 8.8 | AV19: 8.5 | AW19: 8.5 | AX19: 8.8 | AY19: 8.6 | AZ19: 8 | BA19: 8 | BB19: 7.7 | BC19: 8 | BD19: 7.8 | BE19: 7.8 | BF19: 8.1 | BG19: 8 | BH19: 7.9 | BI19: 7.7 | BJ19: 8 | BK19: 7.9 | BL19: 7.9 | BM19: 7.9 | BN19: 7.7 | BO19: 7.8 | BP19: 7.7
A20: Azerbaijan | B20: AZE | C20: Income share held by lowest 20% | D20: SI.DST.FRST.20 | AN20: 7.1 | AT20: 7.4 | AU20: 10.9 | AV20: 10.2 | AW20: 10.7 | AX20: 10.8
A21: Burundi | B21: BDI | C21: Income share held by lowest 20% | D21: SI.DST.FRST.20 | AK21: 7.9 | AQ21: 5.3 | AY21: 8.9 | BF21: 6.9 | BM21: 7.1
A22: Belgium | B22: BEL | C22: Income share held by lowest 20% | D22: SI.DST.FRST.20 | AD22: 9.9 | AG22: 9.7 | AK22: 9.7 | AN22: 8.8 | AP22: 9.2 | AS22: 8.5 | AV22: 8.6 | AW22: 8.4 | AX22: 8.7 | AY22: 8.7 | AZ22: 8.6 | BA22: 8.7 | BB22: 8.5 | BC22: 8.6 | BD22: 8.6 | BE22: 8.7 | BF22: 8.6 | BG22: 8.6 | BH22: 8.6 | BI22: 8.6 | BJ22: 8.7 | BK22: 8.9 | BL22: 9 | BM22: 9.4 | BN22: 9.2 | BO22: 9.4 | BP22: 9.1
A23: Benin | B23: BEN | C23: Income share held by lowest 20% | D23: SI.DST.FRST.20 | AV23: 7 | BD23: 6.1 | BH23: 3.3 | BK23: 7 | BN23: 7.6
A24: Burkina Faso | B24: BFA | C24: Income share held by lowest 20% | D24: SI.DST.FRST.20 | AM24: 5.6 | AQ24: 5.2 | AV24: 5.8 | BB24: 6.7 | BG24: 8.3 | BK24: 6.3 | BN24: 7.3
A25: Bangladesh | B25: BGD | C25: Income share held by lowest 20% | D25: SI.DST.FRST.20 | AB25: 9.7 | AD25: 10 | AG25: 9.4 | AJ25: 9.6 | AN25: 8.8 | AS25: 8.6 | AX25: 8.8 | BC25: 8.9 | BI25: 8.6 | BO25: 8.8
A26: Bulgaria | B26: BGR | C26: Income share held by lowest 20% | D26: SI.DST.FRST.20 | AH26: 10.5 | AK26: 8.3 | AM26: 10.2 | AN26: 7.8 | AP26: 10.1 | AT26: 7.1 | AV26: 8.8 | AY26: 5.7 | AZ26: 6.5 | BA26: 6.9 | BB26: 6.8 | BC26: 6.3 | BD26: 6.4 | BE26: 6.2 | BF26: 5.7 | BG26: 6 | BH26: 5.3 | BI26: 5.4 | BJ26: 5.7 | BK26: 5.7 | BL26: 5.7 | BM26: 6.1 | BN26: 6.1 | BO26: 6.2 | BP26: 6
A27: Bahrain | B27: BHR | C27: Income share held by lowest 20% | D27: SI.DST.FRST.20
A28: Bahamas, The | B28: BHS | C28: Income share held by lowest 20% | D28: SI.DST.FRST.20
A29: Bosnia and Herzegovina | B29: BIH | C29: Income share held by lowest 20% | D29: SI.DST.FRST.20 | AT29: 8.8 | AW29: 7.4 | AZ29: 7.5 | BD29: 7.5
A30: Belarus | B30: BLR | C30: Income share held by lowest 20% | D30: SI.DST.FRST.20 | AL30: 11.1 | AN30: 8.5 | AQ30: 7.9 | AR30: 7.6 | AS30: 7.9 | AT30: 8.2 | AU30: 8.3 | AV30: 8.6 | AW30: 9.4 | AX30: 8.9 | AY30: 8.8 | AZ30: 8.6 | BA30: 9 | BB30: 9.1 | BC30: 8.8 | BD30: 9.2 | BE30: 9.5 | BF30: 9.5 | BG30: 9.3 | BH30: 9.7 | BI30: 9.9 | BJ30: 9.9 | BK30: 10.1 | BL30: 10 | BM30: 10.3
A31: Belize | B31: BLZ | C31: Income share held by lowest 20% | D31: SI.DST.FRST.20 | AL31: 3 | AM31: 3.1 | AN31: 2.4 | AO31: 3.4 | AP31: 2.7 | AQ31: 3.3 | AR31: 3.2 | BK31: 5.8
A32: Bermuda | B32: BMU | C32: Income share held by lowest 20% | D32: SI.DST.FRST.20
A33: Bolivia | B33: BOL | C33: Income share held by lowest 20% | D33: SI.DST.FRST.20 | AI33: 5.6 | AK33: 4.6 | AP33: 2 | AR33: 1.3 | AS33: 1.1 | AT33: 1.9 | AU33: 1.7 | AW33: 3.1 | AX33: 2 | AY33: 2.3 | AZ33: 2.9 | BA33: 3.2 | BB33: 3.2 | BD33: 3.8 | BE33: 3.4 | BF33: 3.6 | BG33: 3.8 | BH33: 3.9 | BI33: 3.7 | BJ33: 3.9 | BK33: 4.5 | BL33: 5.1 | BM33: 4.7 | BN33: 5.3 | BO33: 5.1 | BP33: 5.2
A34: Brazil | B34: BRA | C34: Income share held by lowest 20% | D34: SI.DST.FRST.20 | Z34: 2.7 | AA34: 2.6 | AB34: 2.7 | AC34: 2.8 | AD34: 2.9 | AE34: 2.7 | AF34: 2.4 | AG34: 2.2 | AH34: 2 | AI34: 2.3 | AK34: 2.9 | AL34: 2.4 | AN34: 2.5 | AO34: 2.3 | AP34: 2.3 | AQ34: 2.4 | AR34: 2.5 | AT34: 2.5 | AU34: 2.6 | AV34: 2.6 | AW34: 2.9 | AX34: 2.9 | AY34: 3 | AZ34: 3 | BA34: 3.2 | BB34: 3.2 | BD34: 3.3 | BE34: 3.4 | BF34: 3.5 | BG34: 3.6 | BH34: 3.6 | BI34: 3.3 | BJ34: 3.2 | BK34: 3.1 | BL34: 3.1 | BM34: 4.5 | BN34: 3.3 | BO34: 3.6 | BP34: 3.7
A35: Barbados | B35: BRB | C35: Income share held by lowest 20% | D35: SI.DST.FRST.20 | BI35: 6.9
A36: Brunei Darussalam | B36: BRN | C36: Income share held by lowest 20% | D36: SI.DST.FRST.20
A37: Bhutan | B37: BTN | C37: Income share held by lowest 20% | D37: SI.DST.FRST.20 | AV37: 6.5 | AZ37: 6.7 | BE37: 6.7 | BJ37: 6.7 | BO37: 8.8
A38: Botswana | B38: BWA | C38: Income share held by lowest 20% | D38: SI.DST.FRST.20 | AD38: 3.6 | AL38: 3.1 | AU38: 2.7 | BB38: 3.3 | BH38: 3.7
A39: Central African Republic | B39: CAF | C39: Income share held by lowest 20% | D39: SI.DST.FRST.20 | AK39: 3.1 | BA39: 3.4 | BN39: 5.6
A40: Canada | B40: CAN | C40: Income share held by lowest 20% | D40: SI.DST.FRST.20 | P40: 5.7 | R40: 6.4 | T40: 6.7 | V40: 6.7 | X40: 6.8 | Z40: 7.1 | AA40: 7.1 | AC40: 6.9 | AD40: 7.1 | AE40: 7.4 | AF40: 7.5 | AG40: 7.7 | AH40: 7.6 | AI40: 7.4 | AJ40: 7.3 | AK40: 7.5 | AL40: 7.4 | AM40: 7.5 | AN40: 7.5 | AO40: 7.4 | AP40: 7.4 | AQ40: 7.3 | AR40: 7.3 | AS40: 7.2 | AT40: 7.2 | AU40: 7.2 | AV40: 7.1 | AW40: 7.1 | AX40: 7.2 | AY40: 7.2 | AZ40: 7.3 | BA40: 7.2 | BB40: 7.2 | BC40: 7.3 | BD40: 7.5 | BE40: 7 | BF40: 6.8 | BG40: 7.2 | BH40: 7 | BI40: 7.4 | BJ40: 7.3 | BK40: 7.5 | BL40: 7.7 | BM40: 8.6 | BN40: 8.2
A41: Central Europe and the Baltics | B41: CEB | C41: Income share held by lowest 20% | D41: SI.DST.FRST.20
...

Sheet second_20
A1: Data Source | B1: World Development Indicators
A2: Last Updated Date | B2: 46007
A4: Country Name | B4: Country Code | C4: Indicator Name | D4: Indicator Code | E4: 1960 | F4: 1961 | G4: 1962 | H4: 1963 | I4: 1964 | J4: 1965 | K4: 1966 | L4: 1967 | M4: 1968 | N4: 1969 | O4: 1970 | P4: 1971 | Q4: 1972 | R4: 1973 | S4: 1974 | T4: 1975 | U4: 1976 | V4: 1977 | W4: 1978 | X4: 1979 | Y4: 1980 | Z4: 1981 | AA4: 1982 | AB4: 1983 | AC4: 1984 | AD4: 1985 | AE4: 1986 | AF4: 1987 | AG4: 1988 | AH4: 1989 | AI4: 1990 | AJ4: 1991 | AK4: 1992 | AL4: 1993 | AM4: 1994 | AN4: 1995 | AO4: 1996 | AP4: 1997 | AQ4: 1998 | AR4: 1999 | AS4: 2000 | AT4: 2001 | AU4: 2002 | AV4: 2003 | AW4: 2004 | AX4: 2005 | AY4: 2006 | AZ4: 2007 | BA4: 2008 | BB4: 2009 | BC4: 2010 | BD4: 2011 | BE4: 2012 | BF4: 2013 | BG4: 2014 | BH4: 2015 | BI4: 2016 | BJ4: 2017 | BK4: 2018 | BL4: 2019 | BM4: 2020 | BN4: 2021 | BO4: 2022 | BP4: 2023 | BQ4: 2024
A5: Aruba | B5: ABW | C5: Income share held by second 20% | D5: SI.DST.02ND.20
A6: Africa Eastern and Southern | B6: AFE | C6: Income share held by second 20% | D6: SI.DST.02ND.20
A7: Afghanistan | B7: AFG | C7: Income share held by second 20% | D7: SI.DST.02ND.20
A8: Africa Western and Central | B8: AFW | C8: Income share held by second 20% | D8: SI.DST.02ND.20
A9: Angola | B9: AGO | C9: Income share held by second 20% | D9: SI.DST.02ND.20 | AS9: 7.9 | BA9: 9.6 | BK9: 7.7
A10: Albania | B10: ALB | C10: Income share held by second 20% | D10: SI.DST.02ND.20 | AO10: 13.9 | AU10: 12.6 | AX10: 12.9 | BA10: 13.1 | BE10: 13.2 | BG10: 11.5 | BH10: 12.1 | BI10: 11.9 | BJ10: 12 | BK10: 13 | BL10: 13 | BM10: 13.2
A11: Andorra | B11: AND | C11: Income share held by second 20% | D11: SI.DST.02ND.20
A12: Arab World | B12: ARB | C12: Income share held by second 20% | D12: SI.DST.02ND.20
A13: United Arab Emirates | B13: ARE | C13: Income share held by second 20% | D13: SI.DST.02ND.20 | BF13: 12 | BK13: 14.8
A14: Argentina | B14: ARG | C14: Income share held by second 20% | D14: SI.DST.02ND.20 | Y14: 10.2 | AE14: 9.9 | AF14: 9.3 | AJ14: 9.1 | AK14: 9.2 | AL14: 9.3 | AM14: 9 | AN14: 8.4 | AO14: 8.2 | AP14: 8.2 | AQ14: 7.8 | AR14: 8 | AS14: 7.6 | AT14: 7.1 | AU14: 6.9 | AV14: 7.6 | AW14: 8.1 | AX14: 8.3 | AY14: 8.7 | AZ14: 8.6 | BA14: 9.1 | BB14: 9.4 | BC14: 9.4 | BD14: 9.6 | BE14: 9.9 | BF14: 10 | BG14: 9.7 | BI14: 9.7 | BJ14: 10 | BK14: 9.9 | BL14: 9.5 | BM14: 9.4 | BN14: 9.8 | BO14: 10.1 | BP14: 9.6 | BQ14: 9.7
A15: Armenia | B15: ARM | C15: Income share held by second 20% | D15: SI.DST.02ND.20 | AO15: 9.4 | AR15: 11.6 | AT15: 11.9 | AU15: 12 | AV15: 12.4 | AW15: 11.5 | AX15: 11.8 | AY15: 13.1 | AZ15: 12.8 | BA15: 13.1 | BB15: 13.5 | BC15: 13 | BD15: 13.2 | BE15: 13.2 | BF15: 12.9 | BG15: 12.7 | BH15: 12.6 | BI15: 12.1 | BJ15: 12.4 | BK15: 12.2 | BL15: 13.2 | BM15: 14.3 | BN15: 13.8 | BO15: 13.6 | BP15: 14
A16: American Samoa | B16: ASM | C16: Income share held by second 20% | D16: SI.DST.02ND.20
A17: Antigua and Barbuda | B17: ATG | C17: Income share held by second 20% | D17: SI.DST.02ND.20
A18: Australia | B18: AUS | C18: Income share held by second 20% | D18: SI.DST.02ND.20 | Z18: 12.9 | AD18: 12.6 | AH18: 12.4 | AN18: 12.5 | AT18: 12.2 | AV18: 12.2 | AW18: 12.3 | BA18: 11.6 | BC18: 11.8 | BG18: 12.2 | BI18: 12.2 | BK18: 12.2 | BM18: 12.4
A19: Austria | B19: AUT | C19: Income share held by second 20% | D19: SI.DST.02ND.20 | AM19: 13.2 | AN19: 13.4 | AO19: 13.5 | AP19: 13.5 | AQ19: 13 | AR19: 13.1 | AS19: 13.4 | AV19: 13.4 | AW19: 13.2 | AX19: 13.4 | AY19: 13.3 | AZ19: 13.2 | BA19: 13.3 | BB19: 13 | BC19: 13.2 | BD19: 13.1 | BE19: 13.3 | BF19: 13.1 | BG19: 13.2 | BH19: 13.2 | BI19: 13.2 | BJ19: 13.3 | BK19: 13 | BL19: 13.3 | BM19: 13.5 | BN19: 13.3 | BO19: 13.4 | BP19: 13.2
A20: Azerbaijan | B20: AZE | C20: Income share held by second 20% | D20: SI.DST.02ND.20 | AN20: 12 | AT20: 11.5 | AU20: 14.3 | AV20: 13.9 | AW20: 14 | AX20: 13.9
A21: Burundi | B21: BDI | C21: Income share held by second 20% | D21: SI.DST.02ND.20 | AK21: 12.1 | AQ21: 10.3 | AY21: 11.9 | BF21: 11 | BM21: 11.2
A22: Belgium | B22: BEL | C22: Income share held by second 20% | D22: SI.DST.02ND.20 | AD22: 14.4 | AG22: 14.4 | AK22: 14.6 | AN22: 13.9 | AP22: 14.3 | AS22: 12.9 | AV22: 13.9 | AW22: 13.4 | AX22: 13.7 | AY22: 13.9 | AZ22: 13.6 | BA22: 13.9 | BB22: 13.9 | BC22: 13.9 | BD22: 14 | BE22: 14.2 | BF22: 14.1 | BG22: 13.9 | BH22: 14 | BI22: 14.1 | BJ22: 14.2 | BK22: 14.3 | BL22: 14.2 | BM22: 14.5 | BN22: 14.4 | BO22: 14.5 | BP22: 14.4
A23: Benin | B23: BEN | C23: Income share held by second 20% | D23: SI.DST.02ND.20 | AV23: 10.9 | BD23: 9.6 | BH23: 9.6 | BK23: 11 | BN23: 11.9
A24: Burkina Faso | B24: BFA | C24: Income share held by second 20% | D24: SI.DST.02ND.20 | AM24: 8.7 | AQ24: 8.7 | AV24: 9.7 | BB24: 10.7 | BG24: 11.7 | BK24: 9.8 | BN24: 11.2
A25: Bangladesh | B25: BGD | C25: Income share held by second 20% | D25: SI.DST.02ND.20 | AB25: 14.3 | AD25: 13.8 | AG25: 13.4 | AJ25: 13.6 | AN25: 12.5 | AS25: 12.1 | AX25: 12.2 | BC25: 12.5 | BI25: 12.4 | BO25: 12.8
A26: Bulgaria | B26: BGR | C26: Income share held by second 20% | D26: SI.DST.02ND.20 | AH26: 14.7 | AK26: 13 | AM26: 14.7 | AN26: 12.8 | AP26: 13.9 | AT26: 12.8 | AV26: 13.7 | AY26: 12.6 | AZ26: 11.9 | BA26: 12.6 | BB26: 12.5 | BC26: 12.1 | BD26: 12.7 | BE26: 12.2 | BF26: 12.2 | BG26: 11.8 | BH26: 11.6 | BI26: 11 | BJ26: 11 | BK26: 10.8 | BL26: 11 | BM26: 10.9 | BN26: 11 | BO26: 11.7 | BP26: 11.3
A27: Bahrain | B27: BHR | C27: Income share held by second 20% | D27: SI.DST.02ND.20
A28: Bahamas, The | B28: BHS | C28: Income share held by second 20% | D28: SI.DST.02ND.20
A29: Bosnia and Herzegovina | B29: BIH | C29: Income share held by second 20% | D29: SI.DST.02ND.20 | AT29: 13.3 | AW29: 12.1 | AZ29: 12.2 | BD29: 12.3
A30: Belarus | B30: BLR | C30: Income share held by second 20% | D30: SI.DST.02ND.20 | AL30: 15.3 | AN30: 13.5 | AQ30: 12.6 | AR30: 12.6 | AS30: 12.9 | AT30: 13.1 | AU30: 13.1 | AV30: 13.5 | AW30: 14 | AX30: 13.8 | AY30: 13.5 | AZ30: 13.2 | BA30: 13.6 | BB30: 13.8 | BC30: 13.4 | BD30: 13.9 | BE30: 14 | BF30: 14 | BG30: 14 | BH30: 14.3 | BI30: 14.4 | BJ30: 14.3 | BK30: 14.4 | BL30: 14.3 | BM30: 14.5
A31: Belize | B31: BLZ | C31: Income share held by second 20% | D31: SI.DST.02ND.20 | AL31: 6.5 | AM31: 6.5 | AN31: 5.9 | AO31: 7.1 | AP31: 6.4 | AQ31: 7 | AR31: 7.7 | BK31: 10.5
A32: Bermuda | B32: BMU | C32: Income share held by second 20% | D32: SI.DST.02ND.20
A33: Bolivia | B33: BOL | C33: Income share held by second 20% | D33: SI.DST.02ND.20 | AI33: 9.7 | AK33: 8.5 | AP33: 6.4 | AR33: 5.7 | AS33: 5.3 | AT33: 6.5 | AU33: 6.1 | AW33: 7.2 | AX33: 6.1 | AY33: 6.5 | AZ33: 6.8 | BA33: 8 | BB33: 8.5 | BD33: 9.2 | BE33: 9 | BF33: 8.8 | BG33: 8.8 | BH33: 9 | BI33: 9.3 | BJ33: 9.4 | BK33: 10 | BL33: 10.3 | BM33: 9.8 | BN33: 10.4 | BO33: 10.3 | BP33: 10
A34: Brazil | B34: BRA | C34: Income share held by second 20% | D34: SI.DST.02ND.20 | Z34: 6.2 | AA34: 6 | AB34: 5.9 | AC34: 6 | AD34: 6.5 | AE34: 6 | AF34: 5.7 | AG34: 5.3 | AH34: 5 | AI34: 5.5 | AK34: 7.1 | AL34: 5.8 | AN34: 5.8 | AO34: 5.7 | AP34: 5.7 | AQ34: 5.8 | AR34: 5.9 | AT34: 6 | AU34: 6.1 | AV34: 6.2 | AW34: 6.5 | AX34: 6.5 | AY34: 6.7 | AZ34: 6.9 | BA34: 7.1 | BB34: 7.2 | BD34: 7.5 | BE34: 7.4 | BF34: 7.5 | BG34: 7.7 | BH34: 7.7 | BI34: 7.4 | BJ34: 7.4 | BK34: 7.3 | BL34: 7.3 | BM34: 8.7 | BN34: 7.5 | BO34: 7.7 | BP34: 7.8
A35: Barbados | B35: BRB | C35: Income share held by second 20% | D35: SI.DST.02ND.20 | BI35: 12.2
A36: Brunei Darussalam | B36: BRN | C36: Income share held by second 20% | D36: SI.DST.02ND.20
A37: Bhutan | B37: BTN | C37: Income share held by second 20% | D37: SI.DST.02ND.20 | AV37: 10 | AZ37: 10.8 | BE37: 10.8 | BJ37: 10.8 | BO37: 13.5
A38: Botswana | B38: BWA | C38: Income share held by second 20% | D38: SI.DST.02ND.20 | AD38: 6.9 | AL38: 6 | AU38: 5.3 | BB38: 6.6 | BH38: 6.7
A39: Central African Republic | B39: CAF | C39: Income share held by second 20% | D39: SI.DST.02ND.20 | AK39: 4.9 | BA39: 7 | BN39: 9.7
A40: Canada | B40: CAN | C40: Income share held by second 20% | D40: SI.DST.02ND.20 | P40: 11.7 | R40: 12.3 | T40: 12.5 | V40: 12.5 | X40: 12.5 | Z40: 12.6 | AA40: 12.7 | AC40: 12.7 | AD40: 12.7 | AE40: 13.1 | AF40: 13 | AG40: 13.1 | AH40: 13.2 | AI40: 13.1 | AJ40: 13 | AK40: 13 | AL40: 13 | AM40: 13.1 | AN40: 13 | AO40: 12.6 | AP40: 12.5 | AQ40: 12.6 | AR40: 12.6 | AS40: 12.5 | AT40: 12.5 | AU40: 12.4 | AV40: 12.4 | AW40: 12.4 | AX40: 12.4 | AY40: 12.3 | AZ40: 12.4 | BA40: 12.4 | BB40: 12.3 | BC40: 12.5 | BD40: 12.7 | BE40: 12.4 | BF40: 12.4 | BG40: 12.5 | BH40: 12.5 | BI40: 12.6 | BJ40: 12.4 | BK40: 12.7 | BL40: 12.8 | BM40: 13.3 | BN40: 12.9
A41: Central Europe and the Baltics | B41: CEB | C41: Income share held by second 20% | D41: SI.DST.02ND.20
...

Sheet third_20
A1: Data Source | B1: World Development Indicators
A2: Last Updated Date | B2: 46007
A4: Country Name | B4: Country Code | C4: Indicator Name | D4: Indicator Code | E4: 1960 | F4: 1961 | G4: 1962 | H4: 1963 | I4: 1964 | J4: 1965 | K4: 1966 | L4: 1967 | M4: 1968 | N4: 1969 | O4: 1970 | P4: 1971 | Q4: 1972 | R4: 1973 | S4: 1974 | T4: 1975 | U4: 1976 | V4: 1977 | W4: 1978 | X4: 1979 | Y4: 1980 | Z4: 1981 | AA4: 1982 | AB4: 1983 | AC4: 1984 | AD4: 1985 | AE4: 1986 | AF4: 1987 | AG4: 1988 | AH4: 1989 | AI4: 1990 | AJ4: 1991 | AK4: 1992 | AL4: 1993 | AM4: 1994 | AN4: 1995 | AO4: 1996 | AP4: 1997 | AQ4: 1998 | AR4: 1999 | AS4: 2000 | AT4: 2001 | AU4: 2002 | AV4: 2003 | AW4: 2004 | AX4: 2005 | AY4: 2006 | AZ4: 2007 | BA4: 2008 | BB4: 2009 | BC4: 2010 | BD4: 2011 | BE4: 2012 | BF4: 2013 | BG4: 2014 | BH4: 2015 | BI4: 2016 | BJ4: 2017 | BK4: 2018 | BL4: 2019 | BM4: 2020 | BN4: 2021 | BO4: 2022 | BP4: 2023 | BQ4: 2024
A5: Aruba | B5: ABW | C5: Income share held by third 20% | D5: SI.DST.03RD.20
A6: Africa Eastern and Southern | B6: AFE | C6: Income share held by third 20% | D6: SI.DST.03RD.20
A7: Afghanistan | B7: AFG | C7: Income share held by third 20% | D7: SI.DST.03RD.20
A8: Africa Western and Central | B8: AFW | C8: Income share held by third 20% | D8: SI.DST.03RD.20
A9: Angola | B9: AGO | C9: Income share held by third 20% | D9: SI.DST.03RD.20 | AS9: 12.7 | BA9: 14.5 | BK9: 12.6
A10: Albania | B10: ALB | C10: Income share held by third 20% | D10: SI.DST.03RD.20 | AO10: 17.6 | AU10: 16.5 | AX10: 17 | BA10: 16.8 | BE10: 17.3 | BG10: 16.4 | BH10: 16.5 | BI10: 16.4 | BJ10: 16.5 | BK10: 17.5 | BL10: 17 | BM10: 17.3
A11: Andorra | B11: AND | C11: Income share held by third 20% | D11: SI.DST.03RD.20
A12: Arab World | B12: ARB | C12: Income share held by third 20% | D12: SI.DST.03RD.20
A13: United Arab Emirates | B13: ARE | C13: Income share held by third 20% | D13: SI.DST.03RD.20 | BF13: 18 | BK13: 18.9
A14: Argentina | B14: ARG | C14: Income share held by third 20% | D14: SI.DST.03RD.20 | Y14: 15.4 | AE14: 14.6 | AF14: 14.1 | AJ14: 13.3 | AK14: 13.9 | AL14: 14.3 | AM14: 14 | AN14: 13.3 | AO14: 13.1 | AP14: 13.2 | AQ14: 12.7 | AR14: 13.1 | AS14: 12.8 | AT14: 12.3 | AU14: 12.2 | AV14: 12.7 | AW14: 13.6 | AX14: 13.7 | AY14: 14.2 | AZ14: 14.2 | BA14: 14.5 | BB14: 15 | BC14: 14.9 | BD14: 15 | BE14: 15.4 | BF14: 15.5 | BG14: 15.1 | BI14: 15.1 | BJ14: 15.3 | BK14: 15.3 | BL14: 14.9 | BM14: 15 | BN14: 14.9 | BO14: 15.2 | BP14: 14.9 | BQ14: 14.8
A15: Armenia | B15: ARM | C15: Income share held by third 20% | D15: SI.DST.03RD.20 | AO15: 13.9 | AR15: 15.4 | AT15: 15.6 | AU15: 15.6 | AV15: 15.9 | AW15: 15 | AX15: 15.2 | AY15: 17 | AZ15: 16.7 | BA15: 17 | BB15: 17.2 | BC15: 16.8 | BD15: 17 | BE15: 17.1 | BF15: 16.9 | BG15: 16.9 | BH15: 16.7 | BI15: 17 | BJ15: 15.9 | BK15: 15.9 | BL15: 17 | BM15: 17.8 | BN15: 17.3 | BO15: 17.5 | BP15: 17.5
A16: American Samoa | B16: ASM | C16: Income share held by third 20% | D16: SI.DST.03RD.20
A17: Antigua and Barbuda | B17: ATG | C17: Income share held by third 20% | D17: SI.DST.03RD.20
A18: Australia | B18: AUS | C18: Income share held by third 20% | D18: SI.DST.03RD.20 | Z18: 17 | AD18: 16.6 | AH18: 16.7 | AN18: 16.7 | AT18: 16.5 | AV18: 16.5 | AW18: 16.5 | BA18: 15.9 | BC18: 16.1 | BG18: 16.2 | BI18: 16.5 | BK18: 16.4 | BM18: 16.6
A19: Austria | B19: AUT | C19: Income share held by third 20% | D19: SI.DST.03RD.20 | AM19: 17 | AN19: 17.3 | AO19: 17.4 | AP19: 17.6 | AQ19: 16.9 | AR19: 17.3 | AS19: 17.5 | AV19: 17.4 | AW19: 17.2 | AX19: 17.5 | AY19: 17.2 | AZ19: 17.3 | BA19: 17.5 | BB19: 17.4 | BC19: 17.5 | BD19: 17.4 | BE19: 17.5 | BF19: 17.2 | BG19: 17.5 | BH19: 17.7 | BI19: 17.6 | BJ19: 17.8 | BK19: 17.4 | BL19: 17.5 | BM19: 17.8 | BN19: 17.7 | BO19: 17.7 | BP19: 17.5
A20: Azerbaijan | B20: AZE | C20: Income share held by third 20% | D20: SI.DST.03RD.20 | AN20: 16.4 | AT20: 15.3 | AU20: 17.1 | AV20: 17.1 | AW20: 16.7 | AX20: 16.7
A21: Burundi | B21: BDI | C21: Income share held by third 20% | D21: SI.DST.03RD.20 | AK21: 16.3 | AQ21: 15.2 | AY21: 15.3 | BF21: 15 | BM21: 15.3
A22: Belgium | B22: BEL | C22: Income share held by third 20% | D22: SI.DST.03RD.20 | AD22: 18.3 | AG22: 18.2 | AK22: 18.4 | AN22: 17.8 | AP22: 18 | AS22: 16.3 | AV22: 17.9 | AW22: 17.1 | AX22: 17.3 | AY22: 17.7 | AZ22: 17.4 | BA22: 17.6 | BB22: 17.7 | BC22: 17.8 | BD22: 18 | BE22: 18 | BF22: 18 | BG22: 17.8 | BH22: 18.1 | BI22: 18.1 | BJ22: 18.1 | BK22: 18 | BL22: 17.9 | BM22: 18.1 | BN22: 17.9 | BO22: 17.9 | BP22: 18
A23: Benin | B23: BEN | C23: Income share held by third 20% | D23: SI.DST.03RD.20 | AV23: 15 | BD23: 13.4 | BH23: 14.1 | BK23: 15 | BN23: 16.1
A24: Burkina Faso | B24: BFA | C24: Income share held by third 20% | D24: SI.DST.03RD.20 | AM24: 12 | AQ24: 12.1 | AV24: 14 | BB24: 14.7 | BG24: 15 | BK24: 13.6 | BN24: 15.1
A25: Bangladesh | B25: BGD | C25: Income share held by third 20% | D25: SI.DST.03RD.20 | AB25: 17.9 | AD25: 17.2 | AG25: 17 | AJ25: 17.3 | AN25: 15.7 | AS25: 15.6 | AX25: 15.6 | BC25: 16 | BI25: 16.1 | BO25: 16.5
A26: Bulgaria | B26: BGR | C26: Income share held by third 20% | D26: SI.DST.03RD.20 | AH26: 18.3 | AK26: 17.1 | AM26: 18.1 | AN26: 16.5 | AP26: 17.4 | AT26: 17.2 | AV26: 17.3 | AY26: 17.1 | AZ26: 16.3 | BA26: 16.9 | BB26: 17 | BC26: 16.7 | BD26: 17.1 | BE26: 16.6 | BF26: 16.7 | BG26: 16.2 | BH26: 16.2 | BI26: 15.5 | BJ26: 15.4 | BK26: 14.9 | BL26: 15.2 | BM26: 14.9 | BN26: 15.5 | BO26: 15.6 | BP26: 15.4
A27: Bahrain | B27: BHR | C27: Income share held by third 20% | D27: SI.DST.03RD.20
A28: Bahamas, The | B28: BHS | C28: Income share held by third 20% | D28: SI.DST.03RD.20
A29: Bosnia and Herzegovina | B29: BIH | C29: Income share held by third 20% | D29: SI.DST.03RD.20 | AT29: 17 | AW29: 16.3 | AZ29: 16.6 | BD29: 16.7
A30: Belarus | B30: BLR | C30: Income share held by third 20% | D30: SI.DST.03RD.20 | AL30: 18.5 | AN30: 17.7 | AQ30: 16.9 | AR30: 17.2 | AS30: 17.2 | AT30: 17.2 | AU30: 17.3 | AV30: 17.5 | AW30: 17.9 | AX30: 17.8 | AY30: 17.7 | AZ30: 17.3 | BA30: 17.7 | BB30: 17.7 | BC30: 17.5 | BD30: 17.8 | BE30: 17.9 | BF30: 17.8 | BG30: 17.7 | BH30: 17.9 | BI30: 17.9 | BJ30: 17.8 | BK30: 17.8 | BL30: 17.9 | BM30: 18
A31: Belize | B31: BLZ | C31: Income share held by third 20% | D31: SI.DST.03RD.20 | AL31: 10 | AM31: 9.8 | AN31: 11.1 | AO31: 10.7 | AP31: 10.2 | AQ31: 11.3 | AR31: 12 | BK31: 15.2
A32: Bermuda | B32: BMU | C32: Income share held by third 20% | D32: SI.DST.03RD.20
A33: Bolivia | B33: BOL | C33: Income share held by third 20% | D33: SI.DST.03RD.20 | AI33: 14.5 | AK33: 12.5 | AP33: 11.1 | AR33: 11.7 | AS33: 10.7 | AT33: 11.6 | AU33: 11 | AW33: 11.4 | AX33: 10.8 | AY33: 11.3 | AZ33: 11.8 | BA33: 13.1 | BB33: 13.9 | BD33: 14.3 | BE33: 14.5 | BF33: 14 | BG33: 13.8 | BH33: 14.2 | BI33: 14.7 | BJ33: 14.9 | BK33: 15.2 | BL33: 15 | BM33: 14.5 | BN33: 15.3 | BO33: 15.2 | BP33: 14.8
A34: Brazil | B34: BRA | C34: Income share held by third 20% | D34: SI.DST.03RD.20 | Z34: 10.5 | AA34: 10.3 | AB34: 10 | AC34: 10.2 | AD34: 11 | AE34: 10.3 | AF34: 10.1 | AG34: 9.5 | AH34: 8.9 | AI34: 9.7 | AK34: 12.2 | AL34: 10.1 | AN34: 10.1 | AO34: 10 | AP34: 10 | AQ34: 10 | AR34: 10.2 | AT34: 10.5 | AU34: 10.5 | AV34: 10.7 | AW34: 11 | AX34: 11.1 | AY34: 11.2 | AZ34: 11.6 | BA34: 11.8 | BB34: 11.9 | BD34: 12.2 | BE34: 12 | BF34: 12.2 | BG34: 12.3 | BH34: 12.4 | BI34: 12 | BJ34: 12.1 | BK34: 12 | BL34: 12.2 | BM34: 12.9 | BN34: 12.1 | BO34: 12.3 | BP34: 12.5
A35: Barbados | B35: BRB | C35: Income share held by third 20% | D35: SI.DST.03RD.20 | BI35: 16.9
A36: Brunei Darussalam | B36: BRN | C36: Income share held by third 20% | D36: SI.DST.03RD.20
A37: Bhutan | B37: BTN | C37: Income share held by third 20% | D37: SI.DST.03RD.20 | AV37: 14.2 | AZ37: 15.3 | BE37: 15 | BJ37: 15.5 | BO37: 17.6
A38: Botswana | B38: BWA | C38: Income share held by third 20% | D38: SI.DST.03RD.20 | AD38: 11.4 | AL38: 9.9 | AU38: 8.8 | BB38: 10.6 | BH38: 10.7
A39: Central African Republic | B39: CAF | C39: Income share held by third 20% | D39: SI.DST.03RD.20 | AK39: 9.5 | BA39: 11.1 | BN39: 14.1
A40: Canada | B40: CAN | C40: Income share held by third 20% | D40: SI.DST.03RD.20 | P40: 16.4 | R40: 16.8 | T40: 16.9 | V40: 17.1 | X40: 17.1 | Z40: 17 | AA40: 17 | AC40: 17 | AD40: 17 | AE40: 17.4 | AF40: 17.3 | AG40: 17.3 | AH40: 17.5 | AI40: 17.5 | AJ40: 17.3 | AK40: 17.4 | AL40: 17.4 | AM40: 17.4 | AN40: 17.5 | AO40: 17.1 | AP40: 17 | AQ40: 17 | AR40: 17.1 | AS40: 17 | AT40: 16.9 | AU40: 16.9 | AV40: 16.9 | AW40: 16.9 | AX40: 16.9 | AY40: 16.7 | AZ40: 16.7 | BA40: 16.8 | BB40: 16.8 | BC40: 16.8 | BD40: 17 | BE40: 17.2 | BF40: 17.1 | BG40: 17.1 | BH40: 17 | BI40: 17.2 | BJ40: 17.1 | BK40: 17.1 | BL40: 17.2 | BM40: 17.3 | BN40: 17.1
A41: Central Europe and the Baltics | B41: CEB | C41: Income share held by third 20% | D41: SI.DST.03RD.20
...

Sheet fourth_20
A1: Data Source | B1: World Development Indicators
A2: Last Updated Date | B2: 46007
A4: Country Name | B4: Country Code | C4: Indicator Name | D4: Indicator Code | E4: 1960 | F4: 1961 | G4: 1962 | H4: 1963 | I4: 1964 | J4: 1965 | K4: 1966 | L4: 1967 | M4: 1968 | N4: 1969 | O4: 1970 | P4: 1971 | Q4: 1972 | R4: 1973 | S4: 1974 | T4: 1975 | U4: 1976 | V4: 1977 | W4: 1978 | X4: 1979 | Y4: 1980 | Z4: 1981 | AA4: 1982 | AB4: 1983 | AC4: 1984 | AD4: 1985 | AE4: 1986 | AF4: 1987 | AG4: 1988 | AH4: 1989 | AI4: 1990 | AJ4: 1991 | AK4: 1992 | AL4: 1993 | AM4: 1994 | AN4: 1995 | AO4: 1996 | AP4: 1997 | AQ4: 1998 | AR4: 1999 | AS4: 2000 | AT4: 2001 | AU4: 2002 | AV4: 2003 | AW4: 2004 | AX4: 2005 | AY4: 2006 | AZ4: 2007 | BA4: 2008 | BB4: 2009 | BC4: 2010 | BD4: 2011 | BE4: 2012 | BF4: 2013 | BG4: 2014 | BH4: 2015 | BI4: 2016 | BJ4: 2017 | BK4: 2018 | BL4: 2019 | BM4: 2020 | BN4: 2021 | BO4: 2022 | BP4: 2023 | BQ4: 2024
A5: Aruba | B5: ABW | C5: Income share held by fourth 20% | D5: SI.DST.04TH.20
A6: Africa Eastern and Southern | B6: AFE | C6: Income share held by fourth 20% | D6: SI.DST.04TH.20
A7: Afghanistan | B7: AFG | C7: Income share held by fourth 20% | D7: SI.DST.04TH.20
A8: Africa Western and Central | B8: AFW | C8: Income share held by fourth 20% | D8: SI.DST.04TH.20
A9: Angola | B9: AGO | C9: Income share held by fourth 20% | D9: SI.DST.04TH.20 | AS9: 20.2 | BA9: 21.9 | BK9: 20.4
A10: Albania | B10: ALB | C10: Income share held by fourth 20% | D10: SI.DST.04TH.20 | AO10: 23.4 | AU10: 22.2 | AX10: 22.5 | BA10: 22.2 | BE10: 22.8 | BG10: 23.3 | BH10: 23 | BI10: 23.2 | BJ10: 23.3 | BK10: 23.3 | BL10: 22.7 | BM10: 23
A11: Andorra | B11: AND | C11: Income share held by fourth 20% | D11: SI.DST.04TH.20
A12: Arab World | B12: ARB | C12: Income share held by fourth 20% | D12: SI.DST.04TH.20
A13: United Arab Emirates | B13: ARE | C13: Income share held by fourth 20% | D13: SI.DST.04TH.20 | BF13: 25.5 | BK13: 23.3
A14: Argentina | B14: ARG | C14: Income share held by fourth 20% | D14: SI.DST.04TH.20 | Y14: 22.6 | AE14: 21.8 | AF14: 21.5 | AJ14: 20.3 | AK14: 21.5 | AL14: 22 | AM14: 21.6 | AN14: 20.8 | AO14: 21.2 | AP14: 21.3 | AQ14: 21 | AR14: 21.3 | AS14: 21.3 | AT14: 21.1 | AU14: 20.3 | AV14: 21.5 | AW14: 22.1 | AX14: 22.1 | AY14: 22.5 | AZ14: 22.4 | BA14: 22.7 | BB14: 23 | BC14: 22.6 | BD14: 22.7 | BE14: 23.2 | BF14: 23.3 | BG14: 23.1 | BI14: 22.8 | BJ14: 23 | BK14: 23 | BL14: 22.8 | BM14: 23.2 | BN14: 22.5 | BO14: 22.7 | BP14: 22.7 | BQ14: 22.5
A15: Armenia | B15: ARM | C15: Income share held by fourth 20% | D15: SI.DST.04TH.20 | AO15: 20.6 | AR15: 21.2 | AT15: 20.8 | AU15: 20.8 | AV15: 20.8 | AW15: 20.2 | AX15: 20.2 | AY15: 22.1 | AZ15: 22.1 | BA15: 22.4 | BB15: 22.4 | BC15: 21.7 | BD15: 22.2 | BE15: 22 | BF15: 22.2 | BG15: 22 | BH15: 21.8 | BI15: 22.8 | BJ15: 20.9 | BK15: 20.8 | BL15: 21.7 | BM15: 22.2 | BN15: 21.8 | BO15: 22.4 | BP15: 22.1
A16: American Samoa | B16: ASM | C16: Income share held by fourth 20% | D16: SI.DST.04TH.20
A17: Antigua and Barbuda | B17: ATG | C17: Income share held by fourth 20% | D17: SI.DST.04TH.20
A18: Australia | B18: AUS | C18: Income share held by fourth 20% | D18: SI.DST.04TH.20 | Z18: 23.5 | AD18: 23 | AH18: 23.3 | AN18: 23 | AT18: 23.2 | AV18: 23.2 | AW18: 22.9 | BA18: 22.5 | BC18: 22.7 | BG18: 22.2 | BI18: 22.9 | BK18: 22.5 | BM18: 22.7
A19: Austria | B19: AUT | C19: Income share held by fourth 20% | D19: SI.DST.04TH.20 | AM19: 22.9 | AN19: 23 | AO19: 22.8 | AP19: 23.1 | AQ19: 22.4 | AR19: 22.7 | AS19: 22.9 | AV19: 22.7 | AW19: 22.5 | AX19: 22.8 | AY19: 22.6 | AZ19: 22.9 | BA19: 22.6 | BB19: 22.6 | BC19: 22.9 | BD19: 23 | BE19: 23 | BF19: 22.7 | BG19: 22.7 | BH19: 22.9 | BI19: 23 | BJ19: 23.1 | BK19: 23 | BL19: 23.1 | BM19: 23 | BN19: 22.9 | BO19: 22.3 | BP19: 22.5
A20: Azerbaijan | B20: AZE | C20: Income share held by fourth 20% | D20: SI.DST.04TH.20 | AN20: 22.5 | AT20: 21.2 | AU20: 21 | AV20: 21.4 | AW20: 20.8 | AX20: 20.9
A21: Burundi | B21: BDI | C21: Income share held by fourth 20% | D21: SI.DST.04TH.20 | AK21: 22 | AQ21: 21.3 | AY21: 20.9 | BF21: 20.8 | BM21: 21.4
A22: Belgium | B22: BEL | C22: Income share held by fourth 20% | D22: SI.DST.04TH.20 | AD22: 22.9 | AG22: 22.8 | AK22: 23.1 | AN22: 22.6 | AP22: 22.8 | AS22: 20.9 | AV22: 22.7 | AW22: 21.9 | AX22: 22.2 | AY22: 22.7 | AZ22: 22.3 | BA22: 22.7 | BB22: 22.7 | BC22: 22.5 | BD22: 22.7 | BE22: 22.8 | BF22: 23 | BG22: 22.8 | BH22: 22.7 | BI22: 22.7 | BJ22: 22.7 | BK22: 22.4 | BL22: 22.3 | BM22: 22.6 | BN22: 22.4 | BO22: 22.1 | BP22: 22.2
A23: Benin | B23: BEN | C23: Income share held by fourth 20% | D23: SI.DST.04TH.20 | AV23: 20.9 | BD23: 20.2 | BH23: 20.8 | BK23: 21.4 | BN23: 22.1
A24: Burkina Faso | B24: BFA | C24: Income share held by fourth 20% | D24: SI.DST.04TH.20 | AM24: 18.7 | AQ24: 17.5 | AV24: 20.8 | BB24: 20.9 | BG24: 20.6 | BK24: 20 | BN24: 21.1
A25: Bangladesh | B25: BGD | C25: Income share held by fourth 20% | D25: SI.DST.04TH.20 | AB25: 22.3 | AD25: 21.7 | AG25: 21.6 | AJ25: 22 | AN25: 20.6 | AS25: 21 | AX25: 20.9 | BC25: 21.2 | BI25: 21.4 | BO25: 21.8
A26: Bulgaria | B26: BGR | C26: Income share held by fourth 20% | D26: SI.DST.04TH.20 | AH26: 22.5 | AK26: 22.3 | AM26: 22.2 | AN26: 22 | AP26: 21.9 | AT26: 22.8 | AV26: 22.2 | AY26: 22.9 | AZ26: 22.3 | BA26: 22.6 | BB26: 22.8 | BC26: 22.7 | BD26: 22.7 | BE26: 22.4 | BF26: 22.6 | BG26: 22.1 | BH26: 22.6 | BI26: 21.8 | BJ26: 21.3 | BK26: 21 | BL26: 21.4 | BM26: 20.7 | BN26: 21.9 | BO26: 21.4 | BP26: 21.2
A27: Bahrain | B27: BHR | C27: Income share held by fourth 20% | D27: SI.DST.04TH.20
A28: Bahamas, The | B28: BHS | C28: Income share held by fourth 20% | D28: SI.DST.04TH.20
A29: Bosnia and Herzegovina | B29: BIH | C29: Income share held by fourth 20% | D29: SI.DST.04TH.20 | AT29: 22.1 | AW29: 22.4 | AZ29: 23 | BD29: 22.9
A30: Belarus | B30: BLR | C30: Income share held by fourth 20% | D30: SI.DST.04TH.20 | AL30: 22.2 | AN30: 22.9 | AQ30: 22.6 | AR30: 23.2 | AS30: 23 | AT30: 22.7 | AU30: 22.6 | AV30: 22.8 | AW30: 22.9 | AX30: 23 | AY30: 22.9 | AZ30: 22.5 | BA30: 22.9 | BB30: 22.4 | BC30: 22.8 | BD30: 22.8 | BE30: 22.5 | BF30: 22.5 | BG30: 22.4 | BH30: 22.6 | BI30: 22.3 | BJ30: 22.5 | BK30: 22.3 | BL30: 22.4 | BM30: 22.5
A31: Belize | B31: BLZ | C31: Income share held by fourth 20% | D31: SI.DST.04TH.20 | AL31: 16.2 | AM31: 15.2 | AN31: 19.7 | AO31: 17.6 | AP31: 16.6 | AQ31: 19 | AR31: 19.4 | BK31: 22.3
A32: Bermuda | B32: BMU | C32: Income share held by fourth 20% | D32: SI.DST.04TH.20
A33: Bolivia | B33: BOL | C33: Income share held by fourth 20% | D33: SI.DST.04TH.20 | AI33: 22 | AK33: 19.7 | AP33: 18.8 | AR33: 20.8 | AS33: 18.8 | AT33: 19.5 | AU33: 18.9 | AW33: 18.8 | AX33: 19.2 | AY33: 19.8 | AZ33: 19.8 | BA33: 20.9 | BB33: 21.3 | BD33: 22.2 | BE33: 22.5 | BF33: 21.7 | BG33: 21.3 | BH33: 21.8 | BI33: 22.8 | BJ33: 22.9 | BK33: 22.9 | BL33: 22.4 | BM33: 22.1 | BN33: 22.4 | BO33: 22.6 | BP33: 22.3
A34: Brazil | B34: BRA | C34: Income share held by fourth 20% | D34: SI.DST.04TH.20 | Z34: 18.4 | AA34: 18.3 | AB34: 18.1 | AC34: 18.1 | AD34: 19.6 | AE34: 18.2 | AF34: 18.1 | AG34: 17.5 | AH34: 16.8 | AI34: 17.9 | AK34: 20.8 | AL34: 17.5 | AN34: 17.9 | AO34: 18.2 | AP34: 18.1 | AQ34: 17.9 | AR34: 18 | AT34: 18.5 | AU34: 18.3 | AV34: 18.7 | AW34: 18.8 | AX34: 18.7 | AY34: 18.8 | AZ34: 19.2 | BA34: 19.3 | BB34: 19.4 | BD34: 19.5 | BE34: 19.2 | BF34: 19.3 | BG34: 19.5 | BH34: 19.6 | BI34: 19.3 | BJ34: 19.4 | BK34: 19.3 | BL34: 19.5 | BM34: 19.3 | BN34: 19.6 | BO34: 19.5 | BP34: 19.4
A35: Barbados | B35: BRB | C35: Income share held by fourth 20% | D35: SI.DST.04TH.20 | BI35: 22.8
A36: Brunei Darussalam | B36: BRN | C36: Income share held by fourth 20% | D36: SI.DST.04TH.20
A37: Bhutan | B37: BTN | C37: Income share held by fourth 20% | D37: SI.DST.04TH.20 | AV37: 21.3 | AZ37: 22.1 | BE37: 21.4 | BJ37: 22.7 | BO37: 22.8
A38: Botswana | B38: BWA | C38: Income share held by fourth 20% | D38: SI.DST.04TH.20 | AD38: 19.2 | AL38: 16.7 | AU38: 16.8 | BB38: 17.8 | BH38: 19.1
A39: Central African Republic | B39: CAF | C39: Income share held by fourth 20% | D39: SI.DST.04TH.20 | AK39: 18.3 | BA39: 17.7 | BN39: 21.4
A40: Canada | B40: CAN | C40: Income share held by fourth 20% | D40: SI.DST.04TH.20 | P40: 23.2 | R40: 23.3 | T40: 23.4 | V40: 23.6 | X40: 23.6 | Z40: 23.5 | AA40: 23.2 | AC40: 23.2 | AD40: 23.1 | AE40: 23.3 | AF40: 23.2 | AG40: 23.3 | AH40: 23.4 | AI40: 23.4 | AJ40: 23.4 | AK40: 23.3 | AL40: 23.4 | AM40: 23.3 | AN40: 23.3 | AO40: 23 | AP40: 22.8 | AQ40: 22.8 | AR40: 22.9 | AS40: 22.8 | AT40: 22.8 | AU40: 23 | AV40: 22.9 | AW40: 23 | AX40: 22.9 | AY40: 22.8 | AZ40: 22.7 | BA40: 22.8 | BB40: 22.9 | BC40: 22.8 | BD40: 22.9 | BE40: 23.2 | BF40: 23.4 | BG40: 23 | BH40: 23 | BI40: 23 | BJ40: 23 | BK40: 23 | BL40: 23.1 | BM40: 22.7 | BN40: 22.6
A41: Central Europe and the Baltics | B41: CEB | C41: Income share held by fourth 20% | D41: SI.DST.04TH.20
...

Sheet highest_20
A1: Data Source | B1: World Development Indicators
A2: Last Updated Date | B2: 46007
A4: Country Name | B4: Country Code | C4: Indicator Name | D4: Indicator Code | E4: 1960 | F4: 1961 | G4: 1962 | H4: 1963 | I4: 1964 | J4: 1965 | K4: 1966 | L4: 1967 | M4: 1968 | N4: 1969 | O4: 1970 | P4: 1971 | Q4: 1972 | R4: 1973 | S4: 1974 | T4: 1975 | U4: 1976 | V4: 1977 | W4: 1978 | X4: 1979 | Y4: 1980 | Z4: 1981 | AA4: 1982 | AB4: 1983 | AC4: 1984 | AD4: 1985 | AE4: 1986 | AF4: 1987 | AG4: 1988 | AH4: 1989 | AI4: 1990 | AJ4: 1991 | AK4: 1992 | AL4: 1993 | AM4: 1994 | AN4: 1995 | AO4: 1996 | AP4: 1997 | AQ4: 1998 | AR4: 1999 | AS4: 2000 | AT4: 2001 | AU4: 2002 | AV4: 2003 | AW4: 2004 | AX4: 2005 | AY4: 2006 | AZ4: 2007 | BA4: 2008 | BB4: 2009 | BC4: 2010 | BD4: 2011 | BE4: 2012 | BF4: 2013 | BG4: 2014 | BH4: 2015 | BI4: 2016 | BJ4: 2017 | BK4: 2018 | BL4: 2019 | BM4: 2020 | BN4: 2021 | BO4: 2022 | BP4: 2023 | BQ4: 2024
A5: Aruba | B5: ABW | C5: Income share held by highest 20% | D5: SI.DST.05TH.20
A6: Africa Eastern and Southern | B6: AFE | C6: Income share held by highest 20% | D6: SI.DST.05TH.20
A7: Afghanistan | B7: AFG | C7: Income share held by highest 20% | D7: SI.DST.05TH.20
A8: Africa Western and Central | B8: AFW | C8: Income share held by highest 20% | D8: SI.DST.05TH.20
A9: Angola | B9: AGO | C9: Income share held by highest 20% | D9: SI.DST.05TH.20 | AS9: 56.1 | BA9: 48.5 | BK9: 55.6
A10: Albania | B10: ALB | C10: Income share held by highest 20% | D10: SI.DST.05TH.20 | AO10: 36 | AU10: 40.3 | AX10: 39.2 | BA10: 39 | BE10: 37.8 | BG10: 41.7 | BH10: 40.6 | BI10: 41.2 | BJ10: 40.7 | BK10: 38.2 | BL10: 38.8 | BM10: 38
A11: Andorra | B11: AND | C11: Income share held by highest 20% | D11: SI.DST.05TH.20
A12: Arab World | B12: ARB | C12: Income share held by highest 20% | D12: SI.DST.05TH.20
A13: United Arab Emirates | B13: ARE | C13: Income share held by highest 20% | D13: SI.DST.05TH.20 | BF13: 38.2 | BK13: 34.8
A14: Argentina | B14: ARG | C14: Income share held by highest 20% | D14: SI.DST.05TH.20 | Y14: 46.6 | AE14: 48.5 | AF14: 50.6 | AJ14: 52.5 | AK14: 50.8 | AL14: 49.9 | AM14: 50.9 | AN14: 53.8 | AO14: 54 | AP14: 53.6 | AQ14: 55.1 | AR14: 54.1 | AS14: 55.1 | AT14: 57 | AU14: 57.8 | AV14: 55 | AW14: 52.6 | AX14: 52.1 | AY14: 50.7 | AZ14: 50.7 | BA14: 49.5 | BB14: 48.4 | BC14: 48.6 | BD14: 47.9 | BE14: 46.6 | BF14: 46.2 | BG14: 47 | BI14: 47.5 | BJ14: 46.7 | BK14: 46.9 | BL14: 48.3 | BM14: 47.7 | BN14: 47.8 | BO14: 46.6 | BP14: 47.8 | BQ14: 47.9
A15: Armenia | B15: ARM | C15: Income share held by highest 20% | D15: SI.DST.05TH.20 | AO15: 50.6 | AR15: 44.2 | AT15: 43.9 | AU15: 43.5 | AV15: 42.2 | AW15: 45.8 | AX15: 44.7 | AY15: 38.8 | AZ15: 40 | BA15: 38.4 | BB15: 37.5 | BC15: 39.4 | BD15: 38.6 | BE15: 38.7 | BF15: 39.4 | BG15: 40.1 | BH15: 40.7 | BI15: 40.2 | BJ15: 42.4 | BK15: 43 | BL15: 39.2 | BM15: 35.5 | BN15: 37.7 | BO15: 37.3 | BP15: 36.9
A16: American Samoa | B16: ASM | C16: Income share held by highest 20% | D16: SI.DST.05TH.20
A17: Antigua and Barbuda | B17: ATG | C17: Income share held by highest 20% | D17: SI.DST.05TH.20
A18: Australia | B18: AUS | C18: Income share held by highest 20% | D18: SI.DST.05TH.20 | Z18: 38.8 | AD18: 40.2 | AH18: 40.2 | AN18: 40 | AT18: 40.6 | AV18: 40.6 | AW18: 40.6 | BA18: 42.7 | BC18: 42 | BG18: 41.9 | BI18: 40.8 | BK18: 41.5 | BM18: 41
A19: Austria | B19: AUT | C19: Income share held by highest 20% | D19: SI.DST.05TH.20 | AM19: 38.7 | AN19: 37.9 | AO19: 37.7 | AP19: 37.3 | AQ19: 39.4 | AR19: 38 | AS19: 37.4 | AV19: 38 | AW19: 38.5 | AX19: 37.5 | AY19: 38.3 | AZ19: 38.7 | BA19: 38.6 | BB19: 39.3 | BC19: 38.4 | BD19: 38.7 | BE19: 38.4 | BF19: 38.9 | BG19: 38.7 | BH19: 38.4 | BI19: 38.6 | BJ19: 37.8 | BK19: 38.7 | BL19: 38.2 | BM19: 37.8 | BN19: 38.4 | BO19: 38.9 | BP19: 39
A20: Azerbaijan | B20: AZE | C20: Income share held by highest 20% | D20: SI.DST.05TH.20 | AN20: 42 | AT20: 44.5 | AU20: 36.7 | AV20: 37.4 | AW20: 37.8 | AX20: 37.8
A21: Burundi | B21: BDI | C21: Income share held by highest 20% | D21: SI.DST.05TH.20 | AK21: 41.6 | AQ21: 47.8 | AY21: 42.9 | BF21: 46.3 | BM21: 45
A22: Belgium | B22: BEL | C22: Income share held by highest 20% | D22: SI.DST.05TH.20 | AD22: 34.6 | AG22: 35 | AK22: 34.2 | AN22: 37 | AP22: 35.8 | AS22: 41.4 | AV22: 37 | AW22: 39.2 | AX22: 38.2 | AY22: 36.9 | AZ22: 38 | BA22: 37.2 | BB22: 37.2 | BC22: 37.2 | BD22: 36.8 | BE22: 36.4 | BF22: 36.4 | BG22: 36.9 | BH22: 36.5 | BI22: 36.4 | BJ22: 36.3 | BK22: 36.4 | BL22: 36.5 | BM22: 35.5 | BN22: 36 | BO22: 36.1 | BP22: 36.3
A23: Benin | B23: BEN | C23: Income share held by highest 20% | D23: SI.DST.05TH.20 | AV23: 46.2 | BD23: 50.7 | BH23: 52.1 | BK23: 45.5 | BN23: 42.3
A24: Burkina Faso | B24: BFA | C24: Income share held by highest 20% | D24: SI.DST.05TH.20 | AM24: 55 | AQ24: 56.5 | AV24: 49.7 | BB24: 47.1 | BG24: 44.3 | BK24: 50.3 | BN24: 45.3
A25: Bangladesh | B25: BGD | C25: Income share held by highest 20% | D25: SI.DST.05TH.20 | AB25: 35.8 | AD25: 37.2 | AG25: 38.6 | AJ25: 37.4 | AN25: 42.4 | AS25: 42.7 | AX25: 42.5 | BC25: 41.5 | BI25: 41.4 | BO25: 40.1
A26: Bulgaria | B26: BGR | C26: Income share held by highest 20% | D26: SI.DST.05TH.20 | AH26: 34 | AK26: 39.3 | AM26: 34.8 | AN26: 40.9 | AP26: 36.8 | AT26: 40 | AV26: 38 | AY26: 41.7 | AZ26: 43 | BA26: 41 | BB26: 40.9 | BC26: 42.2 | BD26: 41.1 | BE26: 42.7 | BF26: 42.8 | BG26: 43.9 | BH26: 44.3 | BI26: 46.3 | BJ26: 46.6 | BK26: 47.6 | BL26: 46.6 | BM26: 47.4 | BN26: 45.6 | BO26: 45.1 | BP26: 46.2
A27: Bahrain | B27: BHR | C27: Income share held by highest 20% | D27: SI.DST.05TH.20
A28: Bahamas, The | B28: BHS | C28: Income share held by highest 20% | D28: SI.DST.05TH.20
A29: Bosnia and Herzegovina | B29: BIH | C29: Income share held by highest 20% | D29: SI.DST.05TH.20 | AT29: 38.8 | AW29: 41.8 | AZ29: 40.7 | BD29: 40.7
A30: Belarus | B30: BLR | C30: Income share held by highest 20% | D30: SI.DST.05TH.20 | AL30: 32.9 | AN30: 37.4 | AQ30: 40.1 | AR30: 39.4 | AS30: 39.1 | AT30: 38.9 | AU30: 38.8 | AV30: 37.6 | AW30: 35.9 | AX30: 36.5 | AY30: 37.1 | AZ30: 38.4 | BA30: 36.8 | BB30: 37 | BC30: 37.5 | BD30: 36.3 | BE30: 36.1 | BF30: 36.2 | BG30: 36.7 | BH30: 35.4 | BI30: 35.4 | BJ30: 35.5 | BK30: 35.5 | BL30: 35.4 | BM30: 34.8
A31: Belize | B31: BLZ | C31: Income share held by highest 20% | D31: SI.DST.05TH.20 | AL31: 64.3 | AM31: 65.4 | AN31: 60.9 | AO31: 61.3 | AP31: 64.1 | AQ31: 59.3 | AR31: 57.7 | BK31: 46.3
A32: Bermuda | B32: BMU | C32: Income share held by highest 20% | D32: SI.DST.05TH.20
A33: Bolivia | B33: BOL | C33: Income share held by highest 20% | D33: SI.DST.05TH.20 | AI33: 48.2 | AK33: 54.7 | AP33: 61.7 | AR33: 60.5 | AS33: 64.1 | AT33: 60.6 | AU33: 62.3 | AW33: 59.5 | AX33: 61.9 | AY33: 60.1 | AZ33: 58.7 | BA33: 54.8 | BB33: 53.2 | BD33: 50.6 | BE33: 50.6 | BF33: 51.9 | BG33: 52.3 | BH33: 51.1 | BI33: 49.4 | BJ33: 49 | BK33: 47.5 | BL33: 47.3 | BM33: 49 | BN33: 46.7 | BO33: 46.7 | BP33: 47.7
A34: Brazil | B34: BRA | C34: Income share held by highest 20% | D34: SI.DST.05TH.20 | Z34: 62.3 | AA34: 62.7 | AB34: 63.4 | AC34: 62.9 | AD34: 60 | AE34: 62.8 | AF34: 63.7 | AG34: 65.5 | AH34: 67.3 | AI34: 64.6 | AK34: 57.1 | AL34: 64.2 | AN34: 63.8 | AO34: 63.9 | AP34: 63.8 | AQ34: 63.8 | AR34: 63.3 | AT34: 62.5 | AU34: 62.4 | AV34: 61.8 | AW34: 60.8 | AX34: 60.7 | AY34: 60.1 | AZ34: 59.3 | BA34: 58.6 | BB34: 58.2 | BD34: 57.5 | BE34: 58.1 | BF34: 57.5 | BG34: 56.9 | BH34: 56.7 | BI34: 58 | BJ34: 57.8 | BK34: 58.3 | BL34: 57.8 | BM34: 54.7 | BN34: 57.5 | BO34: 56.9 | BP34: 56.6
A35: Barbados | B35: BRB | C35: Income share held by highest 20% | D35: SI.DST.05TH.20 | BI35: 41.2
A36: Brunei Darussalam | B36: BRN | C36: Income share held by highest 20% | D36: SI.DST.05TH.20
A37: Bhutan | B37: BTN | C37: Income share held by highest 20% | D37: SI.DST.05TH.20 | AV37: 47.9 | AZ37: 45.1 | BE37: 46 | BJ37: 44.4 | BO37: 37.3
A38: Botswana | B38: BWA | C38: Income share held by highest 20% | D38: SI.DST.05TH.20 | AD38: 58.9 | AL38: 64.3 | AU38: 66.5 | BB38: 61.7 | BH38: 59.9
A39: Central African Republic | B39: CAF | C39: Income share held by highest 20% | D39: SI.DST.05TH.20 | AK39: 64.3 | BA39: 60.8 | BN39: 49.2
A40: Canada | B40: CAN | C40: Income share held by highest 20% | D40: SI.DST.05TH.20 | P40: 43 | R40: 41.2 | T40: 40.6 | V40: 40.1 | X40: 40 | Z40: 39.8 | AA40: 39.9 | AC40: 40.3 | AD40: 40.1 | AE40: 38.9 | AF40: 39 | AG40: 38.6 | AH40: 38.3 | AI40: 38.5 | AJ40: 39 | AK40: 38.8 | AL40: 38.8 | AM40: 38.6 | AN40: 38.7 | AO40: 39.9 | AP40: 40.3 | AQ40: 40.3 | AR40: 40.1 | AS40: 40.4 | AT40: 40.6 | AU40: 40.5 | AV40: 40.7 | AW40: 40.6 | AX40: 40.5 | AY40: 41 | AZ40: 40.9 | BA40: 40.9 | BB40: 40.8 | BC40: 40.6 | BD40: 39.9 | BE40: 40.2 | BF40: 40.3 | BG40: 40.1 | BH40: 40.5 | BI40: 39.8 | BJ40: 40.3 | BK40: 39.7 | BL40: 39.1 | BM40: 38.1 | BN40: 39.1
A41: Central Europe and the Baltics | B41: CEB | C41: Income share held by highest 20% | D41: SI.DST.05TH.20
...

Sheet highest_10
A1: Data Source | B1: World Development Indicators
A2: Last Updated Date | B2: 46007
A4: Country Name | B4: Country Code | C4: Indicator Name | D4: Indicator Code | E4: 1960 | F4: 1961 | G4: 1962 | H4: 1963 | I4: 1964 | J4: 1965 | K4: 1966 | L4: 1967 | M4: 1968 | N4: 1969 | O4: 1970 | P4: 1971 | Q4: 1972 | R4: 1973 | S4: 1974 | T4: 1975 | U4: 1976 | V4: 1977 | W4: 1978 | X4: 1979 | Y4: 1980 | Z4: 1981 | AA4: 1982 | AB4: 1983 | AC4: 1984 | AD4: 1985 | AE4: 1986 | AF4: 1987 | AG4: 1988 | AH4: 1989 | AI4: 1990 | AJ4: 1991 | AK4: 1992 | AL4: 1993 | AM4: 1994 | AN4: 1995 | AO4: 1996 | AP4: 1997 | AQ4: 1998 | AR4: 1999 | AS4: 2000 | AT4: 2001 | AU4: 2002 | AV4: 2003 | AW4: 2004 | AX4: 2005 | AY4: 2006 | AZ4: 2007 | BA4: 2008 | BB4: 2009 | BC4: 2010 | BD4: 2011 | BE4: 2012 | BF4: 2013 | BG4: 2014 | BH4: 2015 | BI4: 2016 | BJ4: 2017 | BK4: 2018 | BL4: 2019 | BM4: 2020 | BN4: 2021 | BO4: 2022 | BP4: 2023 | BQ4: 2024
A5: Aruba | B5: ABW | C5: Income share held by highest 10% | D5: SI.DST.10TH.10
A6: Africa Eastern and Southern | B6: AFE | C6: Income share held by highest 10% | D6: SI.DST.10TH.10
A7: Afghanistan | B7: AFG | C7: Income share held by highest 10% | D7: SI.DST.10TH.10
A8: Africa Western and Central | B8: AFW | C8: Income share held by highest 10% | D8: SI.DST.10TH.10
A9: Angola | B9: AGO | C9: Income share held by highest 10% | D9: SI.DST.10TH.10 | AS9: 40.2 | BA9: 32.3 | BK9: 39.6
A10: Albania | B10: ALB | C10: Income share held by highest 10% | D10: SI.DST.10TH.10 | AO10: 20.7 | AU10: 25.3 | AX10: 24.3 | BA10: 24.4 | BE10: 22.9 | BG10: 25.5 | BH10: 24.8 | BI10: 25 | BJ10: 24.6 | BK10: 22.7 | BL10: 23.6 | BM10: 22.8
A11: Andorra | B11: AND | C11: Income share held by highest 10% | D11: SI.DST.10TH.10
A12: Arab World | B12: ARB | C12: Income share held by highest 10% | D12: SI.DST.10TH.10
A13: United Arab Emirates | B13: ARE | C13: Income share held by highest 10% | D13: SI.DST.10TH.10 | BF13: 21.4 | BK13: 20.5
A14: Argentina | B14: ARG | C14: Income share held by highest 10% | D14: SI.DST.10TH.10 | Y14: 30.2 | AE14: 32.2 | AF14: 34.2 | AJ14: 36.6 | AK14: 34.3 | AL14: 33.2 | AM14: 34.4 | AN14: 37 | AO14: 36.9 | AP14: 36.4 | AQ14: 38 | AR14: 37 | AS14: 37.7 | AT14: 39.5 | AU14: 40.5 | AV14: 37.7 | AW14: 35.3 | AX14: 35 | AY14: 33.8 | AZ14: 33.7 | BA14: 32.5 | BB14: 31.3 | BC14: 31.8 | BD14: 31 | BE14: 29.8 | BF14: 29.5 | BG14: 30.1 | BI14: 30.7 | BJ14: 30 | BK14: 30.1 | BL14: 31.3 | BM14: 30.6 | BN14: 31.2 | BO14: 29.8 | BP14: 31 | BQ14: 31.2
A15: Armenia | B15: ARM | C15: Income share held by highest 10% | D15: SI.DST.10TH.10 | AO15: 35.2 | AR15: 29.6 | AT15: 29.1 | AU15: 29 | AV15: 28.2 | AW15: 31.7 | AX15: 30.8 | AY15: 24.4 | AZ15: 25.1 | BA15: 23.7 | BB15: 22.9 | BC15: 25 | BD15: 24 | BE15: 24.5 | BF15: 24.7 | BG15: 25.7 | BH15: 26.7 | BI15: 25.3 | BJ15: 28.4 | BK15: 29.2 | BL15: 25.2 | BM15: 21.5 | BN15: 23.6 | BO15: 23 | BP15: 22.9
A16: American Samoa | B16: ASM | C16: Income share held by highest 10% | D16: SI.DST.10TH.10
A17: Antigua and Barbuda | B17: ATG | C17: Income share held by highest 10% | D17: SI.DST.10TH.10
A18: Australia | B18: AUS | C18: Income share held by highest 10% | D18: SI.DST.10TH.10 | Z18: 22.9 | AD18: 24.3 | AH18: 24.2 | AN18: 24.2 | AT18: 24.7 | AV18: 24.7 | AW18: 24.9 | BA18: 27.4 | BC18: 26.5 | BG18: 26.6 | BI18: 25.5 | BK18: 26.2 | BM18: 25.5
A19: Austria | B19: AUT | C19: Income share held by highest 10% | D19: SI.DST.10TH.10 | AM19: 23.6 | AN19: 23 | AO19: 22.8 | AP19: 22.4 | AQ19: 24.6 | AR19: 23.4 | AS19: 22.6 | AV19: 23.5 | AW19: 23.8 | AX19: 22.8 | AY19: 23.7 | AZ19: 23.8 | BA19: 24.1 | BB19: 24.7 | BC19: 23.6 | BD19: 23.7 | BE19: 23.4 | BF19: 24.3 | BG19: 24.1 | BH19: 23.8 | BI19: 23.8 | BJ19: 23 | BK19: 23.9 | BL19: 23.2 | BM19: 23.1 | BN19: 23.8 | BO19: 24.6 | BP19: 24.8
A20: Azerbaijan | B20: AZE | C20: Income share held by highest 10% | D20: SI.DST.10TH.10 | AN20: 26.8 | AT20: 29.5 | AU20: 23.2 | AV20: 23.6 | AW20: 24.4 | AX20: 24.2
A21: Burundi | B21: BDI | C21: Income share held by highest 10% | D21: SI.DST.10TH.10 | AK21: 26.6 | AQ21: 32.5 | AY21: 28 | BF21: 31 | BM21: 29.9
A22: Belgium | B22: BEL | C22: Income share held by highest 10% | D22: SI.DST.10TH.10 | AD22: 20.3 | AG22: 20.7 | AK22: 19.8 | AN22: 22.5 | AP22: 21.2 | AS22: 28 | AV22: 22.2 | AW22: 25.1 | AX22: 23.9 | AY22: 22.4 | AZ22: 23.5 | BA22: 22.7 | BB22: 22.7 | BC22: 22.7 | BD22: 22.3 | BE22: 21.9 | BF22: 21.8 | BG22: 22.4 | BH22: 22.2 | BI22: 22.2 | BJ22: 21.9 | BK22: 22.2 | BL22: 22.3 | BM22: 21.4 | BN22: 21.9 | BO22: 22.2 | BP22: 22.2
A23: Benin | B23: BEN | C23: Income share held by highest 10% | D23: SI.DST.10TH.10 | AV23: 31.1 | BD23: 34.5 | BH23: 37.6 | BK23: 30 | BN23: 27.2
A24: Burkina Faso | B24: BFA | C24: Income share held by highest 10% | D24: SI.DST.10TH.10 | AM24: 39.4 | AQ24: 42.7 | AV24: 33.8 | BB24: 32 | BG24: 29.6 | BK24: 35.3 | BN24: 30.2
A25: Bangladesh | B25: BGD | C25: Income share held by highest 10% | D25: SI.DST.10TH.10 | AB25: 21.9 | AD25: 23.4 | AG25: 24.6 | AJ25: 23.3 | AN25: 28.1 | AS25: 27.9 | AX25: 28 | BC25: 26.9 | BI25: 26.8 | BO25: 25.5
A26: Bulgaria | B26: BGR | C26: Income share held by highest 10% | D26: SI.DST.10TH.10 | AH26: 20 | AK26: 24.7 | AM26: 21 | AN26: 26.3 | AP26: 22.8 | AT26: 24.9 | AV26: 23.6 | AY26: 26.6 | AZ26: 27.9 | BA26: 25.7 | BB26: 25.7 | BC26: 26.9 | BD26: 26 | BE26: 27.4 | BF26: 27.6 | BG26: 28.8 | BH26: 28.7 | BI26: 31.4 | BJ26: 31.9 | BK26: 32.6 | BL26: 31.4 | BM26: 32.6 | BN26: 29.9 | BO26: 30.1 | BP26: 31.1
A27: Bahrain | B27: BHR | C27: Income share held by highest 10% | D27: SI.DST.10TH.10
A28: Bahamas, The | B28: BHS | C28: Income share held by highest 10% | D28: SI.DST.10TH.10
A29: Bosnia and Herzegovina | B29: BIH | C29: Income share held by highest 10% | D29: SI.DST.10TH.10 | AT29: 24.7 | AW29: 26.4 | AZ29: 25.1 | BD29: 25.1
A30: Belarus | B30: BLR | C30: Income share held by highest 10% | D30: SI.DST.10TH.10 | AL30: 19.4 | AN30: 22.6 | AQ30: 24.9 | AR30: 24 | AS30: 24 | AT30: 24 | AU30: 24 | AV30: 22.6 | AW30: 21.3 | AX30: 21.8 | AY30: 22.4 | AZ30: 23.6 | BA30: 22.3 | BB30: 22.6 | BC30: 22.8 | BD30: 21.9 | BE30: 21.8 | BF30: 22.1 | BG30: 22.6 | BH30: 21.2 | BI30: 21.3 | BJ30: 21.3 | BK30: 21.4 | BL30: 21.3 | BM30: 20.7
A31: Belize | B31: BLZ | C31: Income share held by highest 10% | D31: SI.DST.10TH.10 | AL31: 51.1 | AM31: 52.5 | AN31: 44.1 | AO31: 46.5 | AP31: 50.3 | AQ31: 43.7 | AR31: 42.4 | BK31: 30
A32: Bermuda | B32: BMU | C32: Income share held by highest 10% | D32: SI.DST.10TH.10
A33: Bolivia | B33: BOL | C33: Income share held by highest 10% | D33: SI.DST.10TH.10 | AI33: 31.7 | AK33: 39.2 | AP33: 45.4 | AR33: 42.6 | AS33: 47.8 | AT33: 44.1 | AU33: 46.6 | AW33: 43.9 | AX33: 45.3 | AY33: 43.6 | AZ33: 41.8 | BA33: 38.5 | BB33: 36.9 | BD33: 33.7 | BE33: 33.7 | BF33: 35.2 | BG33: 36 | BH33: 34.8 | BI33: 32.4 | BJ33: 32 | BK33: 30.6 | BL33: 30.8 | BM33: 32.6 | BN33: 30.3 | BO33: 30.4 | BP33: 31.3
A34: Brazil | B34: BRA | C34: Income share held by highest 10% | D34: SI.DST.10TH.10 | Z34: 45.9 | AA34: 46.2 | AB34: 46.8 | AC34: 46.5 | AD34: 42.5 | AE34: 46.6 | AF34: 47.4 | AG34: 49.2 | AH34: 51.1 | AI34: 48.1 | AK34: 39.7 | AL34: 48.4 | AN34: 47.5 | AO34: 47.3 | AP34: 47.4 | AQ34: 47.6 | AR34: 47 | AT34: 46.1 | AU34: 46.1 | AV34: 45.4 | AW34: 44.5 | AX34: 44.6 | AY34: 44.1 | AZ34: 43.2 | BA34: 42.5 | BB34: 42.2 | BD34: 41.7 | BE34: 42.4 | BF34: 41.7 | BG34: 41 | BH34: 40.9 | BI34: 42.1 | BJ34: 42 | BK34: 42.5 | BL34: 42 | BM34: 39.5 | BN34: 41.6 | BO34: 41 | BP34: 40.8
